Workbook

Sheet Raw Data Source
A1: Data in "Raw data--monthly" are from the Bureau of Labor Statistics. Series IDs are listed here:
A2: Column | B2: Abbreviation | C2: Name | D2: Dataset | E2: Series ID
A3: C | B3: UE | C3: Unemployed to employed | D3: CPS | E3: LNS17100000
A4: D | B4: UN | C4: Unemployed to NLF | D4: CPS | E4: LNS17900000
A5: E | B5: EU | C5: Employed to Unemployed | D5: CPS | E5: LNS17400000
A6: F | B6: EN | C6: Employed to NLF | D6: CPS | E6: LNS17800000
A7: G | B7: NU | C7: NLF to Unemployed | D7: CPS | E7: LNS17600000
A8: H | B8: NE | C8: NLF to Employed | D8: CPS | E8: LNS17200000
A9: I | B9: N | C9: Civilian Not in the labor force | D9: CPS | E9: LNS15000000
A10: J | B10: E | C10: Civilian Employment | D10: CPS | E10: LNS12000000
A11: K | B11: U | C11: Civilian unemployment | D11: CPS | E11: LNS13000000
A12: L | B12: V | C12: Total Nonfarm Job Openings | D12: JOLTS | E12: JTS00000000JOL
A13: M | B13: L | C13: Civilian Labor Force | D13: CPS | E13: LNS11000000

Sheet Raw data -- monthly
Z1: 3MMA
C2: UE | D2: UN | E2: EU | F2: EN | G2: NU | H2: NE | I2: N | J2: E | K2: U | L2: V | M2: L | P2: U/L | Q2: N/L | R2: V/L | S2: uer | T2: unr | U2: eur | V2: enr | W2: nur | X2: ner | Z2: U/L | AA2: N/L | AB2: V/L | AC2: uer | AD2: unr | AE2: eur | AF2: enr | AG2: nur | AH2: ner | AI2: E | AJ2: N | AK2: U
A3: 32874 | B3: 32874 | C3: ND | D3: ND | F3: ND | G3: ND | H3: ND | I3: 62580 | J3: 119081 | K3: 6752 | M3: =J3+K3 -> 125833 | P3: =K3/M3 -> 0.05365842 | Q3: =I3/M3 -> 0.49732582 | R3: =IF(ISNUMBER(L3),L3/M3,NA()) -> #N/A | S3: =IF(ISNUMBER(C3),C3/$K3,NA()) -> #N/A | T3: =IF(ISNUMBER(D3),D3/$K3,NA()) -> #N/A | U3: =IF(ISNUMBER(E3),E3/$J3,NA()) -> #N/A | V3: =IF(ISNUMBER(F3),F3/$J3,NA()) -> #N/A | W3: =IF(ISNUMBER(G3),G3/$I3,NA()) -> #N/A | X3: =IF(ISNUMBER(H3),H3/$I3,NA()) -> #N/A | Y3: =B3 -> 32874 | Z3: =IF(ISNUMBER(P1),AVERAGE(P1:P3),NA()) -> #N/A | AA3: =IF(ISNUMBER(Q1),AVERAGE(Q1:Q3),NA()) -> #N/A | AB3: =IF(ISNUMBER(R1),AVERAGE(R1:R3),NA()) -> #N/A | AC3: =IF(ISNUMBER(S1),AVERAGE(S1:S3),NA()) -> #N/A | AD3: =IF(ISNUMBER(T1),AVERAGE(T1:T3),NA()) -> #N/A | AE3: =IF(ISNUMBER(U1),AVERAGE(U1:U3),NA()) -> #N/A | AF3: =IF(ISNUMBER(V1),AVERAGE(V1:V3),NA()) -> #N/A | AG3: =IF(ISNUMBER(W1),AVERAGE(W1:W3),NA()) -> #N/A | AH3: =IF(ISNUMBER(X1),AVERAGE(X1:X3),NA()) -> #N/A | AI3: =NA() -> #N/A | AJ3: =NA() -> #N/A | AK3: =NA() -> #N/A
A4: 32905 | B4: 32905 | C4: 2152 | D4: 1360 | E4: 1823 | F4: 3583 | G4: 1573 | H4: 3204 | I4: 62806 | J4: 119059 | K4: 6651 | M4: =J4+K4 -> 125710 | P4: =K4/M4 -> 0.052907485 | Q4: =I4/M4 -> 0.49961021 | R4: =IF(ISNUMBER(L4),L4/M4,NA()) -> #N/A | S4: =IF(ISNUMBER(C4),C4/$K3,NA()) -> 0.31872038 | T4: =IF(ISNUMBER(D4),D4/$K3,NA()) -> 0.2014218 | U4: =IF(ISNUMBER(E4),E4/$J3,NA()) -> 0.015308907 | V4: =IF(ISNUMBER(F4),F4/$J3,NA()) -> 0.030088763 | W4: =IF(ISNUMBER(G4),G4/$I3,NA()) -> 0.025135826 | X4: =IF(ISNUMBER(H4),H4/$I4,NA()) -> 0.051014234 | Y4: =B4 -> 32905 | Z4: =IF(ISNUMBER(P2),AVERAGE(P2:P4),NA()) -> #N/A | AA4: =IF(ISNUMBER(Q2),AVERAGE(Q2:Q4),NA()) -> #N/A | AB4: =IF(ISNUMBER(R2),AVERAGE(R2:R4),NA()) -> #N/A | AC4: =IF(ISNUMBER(S2),AVERAGE(S2:S4),NA()) -> #N/A | AD4: =IF(ISNUMBER(T2),AVERAGE(T2:T4),NA()) -> #N/A | AE4: =IF(ISNUMBER(U2),AVERAGE(U2:U4),NA()) -> #N/A | AF4: =IF(ISNUMBER(V2),AVERAGE(V2:V4),NA()) -> #N/A | AG4: =IF(ISNUMBER(W2),AVERAGE(W2:W4),NA()) -> #N/A | AH4: =IF(ISNUMBER(X2),AVERAGE(X2:X4),NA()) -> #N/A | AI4: =NA() -> #N/A | AJ4: =NA() -> #N/A | AK4: =NA() -> #N/A
A5: 32933 | B5: 32933 | C5: 1964 | D5: 1466 | E5: 1764 | F5: 3367 | G5: 1604 | H5: 3244 | I5: 62829 | J5: 119203 | K5: 6598 | M5: =J5+K5 -> 125801 | P5: =K5/M5 -> 0.052447914 | Q5: =I5/M5 -> 0.49943164 | R5: =IF(ISNUMBER(L5),L5/M5,NA()) -> #N/A | S5: =IF(ISNUMBER(C5),C5/$K4,NA()) -> 0.29529394 | T5: =IF(ISNUMBER(D5),D5/$K4,NA()) -> 0.22041798 | U5: =IF(ISNUMBER(E5),E5/$J4,NA()) -> 0.014816184 | V5: =IF(ISNUMBER(F5),F5/$J4,NA()) -> 0.028280096 | W5: =IF(ISNUMBER(G5),G5/$I4,NA()) -> 0.025538961 | X5: =IF(ISNUMBER(H5),H5/$I5,NA()) -> 0.051632208 | Y5: =B5 -> 32933 | Z5: =IF(ISNUMBER(P3),AVERAGE(P3:P5),NA()) -> 0.053004607 | AA5: =IF(ISNUMBER(Q3),AVERAGE(Q3:Q5),NA()) -> 0.49878923 | AB5: =IF(ISNUMBER(R3),AVERAGE(R3:R5),NA()) -> #N/A | AC5: =IF(ISNUMBER(S3),AVERAGE(S3:S5),NA()) -> #N/A | AD5: =IF(ISNUMBER(T3),AVERAGE(T3:T5),NA()) -> #N/A | AE5: =IF(ISNUMBER(U3),AVERAGE(U3:U5),NA()) -> #N/A | AF5: =IF(ISNUMBER(V3),AVERAGE(V3:V5),NA()) -> #N/A | AG5: =IF(ISNUMBER(W3),AVERAGE(W3:W5),NA()) -> #N/A | AH5: =IF(ISNUMBER(X3),AVERAGE(X3:X5),NA()) -> #N/A | AI5: =NA() -> #N/A | AJ5: =NA() -> #N/A | AK5: =NA() -> #N/A
A6: 32964 | B6: 32964 | C6: 1801 | D6: 1394 | E6: 1873 | F6: 3495 | G6: 1510 | H6: 3148 | I6: 63129 | J6: 118852 | K6: 6797 | M6: =J6+K6 -> 125649 | P6: =K6/M6 -> 0.054095138 | Q6: =I6/M6 -> 0.50242342 | R6: =IF(ISNUMBER(L6),L6/M6,NA()) -> #N/A | S6: =IF(ISNUMBER(C6),C6/$K5,NA()) -> 0.2729615 | T6: =IF(ISNUMBER(D6),D6/$K5,NA()) -> 0.21127614 | U6: =IF(ISNUMBER(E6),E6/$J5,NA()) -> 0.015712692 | V6: =IF(ISNUMBER(F6),F6/$J5,NA()) -> 0.029319732 | W6: =IF(ISNUMBER(G6),G6/$I5,NA()) -> 0.024033488 | X6: =IF(ISNUMBER(H6),H6/$I6,NA()) -> 0.049866147 | Y6: =B6 -> 32964 | Z6: =IF(ISNUMBER(P4),AVERAGE(P4:P6),NA()) -> 0.053150179 | AA6: =IF(ISNUMBER(Q4),AVERAGE(Q4:Q6),NA()) -> 0.50048842 | AB6: =IF(ISNUMBER(R4),AVERAGE(R4:R6),NA()) -> #N/A | AC6: =IF(ISNUMBER(S4),AVERAGE(S4:S6),NA()) -> 0.29565861 | AD6: =IF(ISNUMBER(T4),AVERAGE(T4:T6),NA()) -> 0.21103864 | AE6: =IF(ISNUMBER(U4),AVERAGE(U4:U6),NA()) -> 0.015279261 | AF6: =IF(ISNUMBER(V4),AVERAGE(V4:V6),NA()) -> 0.02922953 | AG6: =IF(ISNUMBER(W4),AVERAGE(W4:W6),NA()) -> 0.024902758 | AH6: =IF(ISNUMBER(X4),AVERAGE(X4:X6),NA()) -> 0.05083753 | AI6: =AVERAGE(J4:J6) -> 119038 | AJ6: =AVERAGE(I4:I6) -> 62921.333 | AK6: =AVERAGE(K4:K6) -> 6682
A7: 32994 | B7: 32994 | C7: 1931 | D7: 1313 | E7: 1676 | F7: 3125 | G7: 1496 | H7: 3119 | I7: 63020 | J7: 119151 | K7: 6742 | M7: =J7+K7 -> 125893 | P7: =K7/M7 -> 0.053553414 | Q7: =I7/M7 -> 0.50058383 | R7: =IF(ISNUMBER(L7),L7/M7,NA()) -> #N/A | S7: =IF(ISNUMBER(C7),C7/$K6,NA()) -> 0.28409592 | T7: =IF(ISNUMBER(D7),D7/$K6,NA()) -> 0.19317346 | U7: =IF(ISNUMBER(E7),E7/$J6,NA()) -> 0.014101572 | V7: =IF(ISNUMBER(F7),F7/$J6,NA()) -> 0.026293205 | W7: =IF(ISNUMBER(G7),G7/$I6,NA()) -> 0.023697508 | X7: =IF(ISNUMBER(H7),H7/$I7,NA()) -> 0.049492225 | Y7: =B7 -> 32994 | Z7: =IF(ISNUMBER(P5),AVERAGE(P5:P7),NA()) -> 0.053365489 | AA7: =IF(ISNUMBER(Q5),AVERAGE(Q5:Q7),NA()) -> 0.50081296 | AB7: =IF(ISNUMBER(R5),AVERAGE(R5:R7),NA()) -> #N/A | AC7: =IF(ISNUMBER(S5),AVERAGE(S5:S7),NA()) -> 0.28411712 | AD7: =IF(ISNUMBER(T5),AVERAGE(T5:T7),NA()) -> 0.2082892 | AE7: =IF(ISNUMBER(U5),AVERAGE(U5:U7),NA()) -> 0.014876816 | AF7: =IF(ISNUMBER(V5),AVERAGE(V5:V7),NA()) -> 0.027964344 | AG7: =IF(ISNUMBER(W5),AVERAGE(W5:W7),NA()) -> 0.024423319 | AH7: =IF(ISNUMBER(X5),AVERAGE(X5:X7),NA()) -> 0.050330193 | AI7: =AVERAGE(J5:J7) -> 119068.67 | AJ7: =AVERAGE(I5:I7) -> 62992.667 | AK7: =AVERAGE(K5:K7) -> 6712.3333
A8: 33025 | B8: 33025 | C8: 1945 | D8: 1393 | E8: 1771 | F8: 3389 | G8: 1381 | H8: 2986 | I8: 63485 | J8: 118983 | K8: 6590 | M8: =J8+K8 -> 125573 | P8: =K8/M8 -> 0.052479434 | Q8: =I8/M8 -> 0.5055625 | R8: =IF(ISNUMBER(L8),L8/M8,NA()) -> #N/A | S8: =IF(ISNUMBER(C8),C8/$K7,NA()) -> 0.28849006 | T8: =IF(ISNUMBER(D8),D8/$K7,NA()) -> 0.20661525 | U8: =IF(ISNUMBER(E8),E8/$J7,NA()) -> 0.014863493 | V8: =IF(ISNUMBER(F8),F8/$J7,NA()) -> 0.0284429 | W8: =IF(ISNUMBER(G8),G8/$I7,NA()) -> 0.021913678 | X8: =IF(ISNUMBER(H8),H8/$I8,NA()) -> 0.047034733 | Y8: =B8 -> 33025 | Z8: =IF(ISNUMBER(P6),AVERAGE(P6:P8),NA()) -> 0.053375996 | AA8: =IF(ISNUMBER(Q6),AVERAGE(Q6:Q8),NA()) -> 0.50285658 | AB8: =IF(ISNUMBER(R6),AVERAGE(R6:R8),NA()) -> #N/A | AC8: =IF(ISNUMBER(S6),AVERAGE(S6:S8),NA()) -> 0.28184916 | AD8: =IF(ISNUMBER(T6),AVERAGE(T6:T8),NA()) -> 0.20368828 | AE8: =IF(ISNUMBER(U6),AVERAGE(U6:U8),NA()) -> 0.014892585 | AF8: =IF(ISNUMBER(V6),AVERAGE(V6:V8),NA()) -> 0.028018612 | AG8: =IF(ISNUMBER(W6),AVERAGE(W6:W8),NA()) -> 0.023214891 | AH8: =IF(ISNUMBER(X6),AVERAGE(X6:X8),NA()) -> 0.048797701 | AI8: =AVERAGE(J6:J8) -> 118995.33 | AJ8: =AVERAGE(I6:I8) -> 63211.333 | AK8: =AVERAGE(K6:K8) -> 6709.6667
A9: 33055 | B9: 33055 | C9: 1818 | D9: 1391 | E9: 1941 | F9: 3297 | G9: 1566 | H9: 3193 | I9: 63456 | J9: 118810 | K9: 6922 | M9: =J9+K9 -> 125732 | P9: =K9/M9 -> 0.055053606 | Q9: =I9/M9 -> 0.50469252 | R9: =IF(ISNUMBER(L9),L9/M9,NA()) -> #N/A | S9: =IF(ISNUMBER(C9),C9/$K8,NA()) -> 0.27587253 | T9: =IF(ISNUMBER(D9),D9/$K8,NA()) -> 0.21107739 | U9: =IF(ISNUMBER(E9),E9/$J8,NA()) -> 0.016313255 | V9: =IF(ISNUMBER(F9),F9/$J8,NA()) -> 0.027709841 | W9: =IF(ISNUMBER(G9),G9/$I8,NA()) -> 0.024667244 | X9: =IF(ISNUMBER(H9),H9/$I9,NA()) -> 0.050318331 | Y9: =B9 -> 33055 | Z9: =IF(ISNUMBER(P7),AVERAGE(P7:P9),NA()) -> 0.053695485 | AA9: =IF(ISNUMBER(Q7),AVERAGE(Q7:Q9),NA()) -> 0.50361295 | AB9: =IF(ISNUMBER(R7),AVERAGE(R7:R9),NA()) -> #N/A | AC9: =IF(ISNUMBER(S7),AVERAGE(S7:S9),NA()) -> 0.28281951 | AD9: =IF(ISNUMBER(T7),AVERAGE(T7:T9),NA()) -> 0.20362203 | AE9: =IF(ISNUMBER(U7),AVERAGE(U7:U9),NA()) -> 0.015092773 | AF9: =IF(ISNUMBER(V7),AVERAGE(V7:V9),NA()) -> 0.027481982 | AG9: =IF(ISNUMBER(W7),AVERAGE(W7:W9),NA()) -> 0.023426144 | AH9: =IF(ISNUMBER(X7),AVERAGE(X7:X9),NA()) -> 0.048948429 | AI9: =AVERAGE(J7:J9) -> 118981.33 | AJ9: =AVERAGE(I7:I9) -> 63320.333 | AK9: =AVERAGE(K7:K9) -> 6751.3333
A10: 33086 | B10: 33086 | C10: 1940 | D10: 1355 | E10: 1877 | F10: 3106 | G10: 1658 | H10: 2961 | I10: 63352 | J10: 118802 | K10: 7188 | M10: =J10+K10 -> 125990 | P10: =K10/M10 -> 0.057052147 | Q10: =I10/M10 -> 0.50283356 | R10: =IF(ISNUMBER(L10),L10/M10,NA()) -> #N/A | S10: =IF(ISNUMBER(C10),C10/$K9,NA()) -> 0.28026582 | T10: =IF(ISNUMBER(D10),D10/$K9,NA()) -> 0.19575267 | U10: =IF(ISNUMBER(E10),E10/$J9,NA()) -> 0.015798333 | V10: =IF(ISNUMBER(F10),F10/$J9,NA()) -> 0.026142581 | W10: =IF(ISNUMBER(G10),G10/$I9,NA()) -> 0.026128341 | X10: =IF(ISNUMBER(H10),H10/$I10,NA()) -> 0.046738856 | Y10: =B10 -> 33086 | Z10: =IF(ISNUMBER(P8),AVERAGE(P8:P10),NA()) -> 0.054861729 | AA10: =IF(ISNUMBER(Q8),AVERAGE(Q8:Q10),NA()) -> 0.50436286 | AB10: =IF(ISNUMBER(R8),AVERAGE(R8:R10),NA()) -> #N/A | AC10: =IF(ISNUMBER(S8),AVERAGE(S8:S10),NA()) -> 0.28154281 | AD10: =IF(ISNUMBER(T8),AVERAGE(T8:T10),NA()) -> 0.20448177 | AE10: =IF(ISNUMBER(U8),AVERAGE(U8:U10),NA()) -> 0.01565836 | AF10: =IF(ISNUMBER(V8),AVERAGE(V8:V10),NA()) -> 0.027431774 | AG10: =IF(ISNUMBER(W8),AVERAGE(W8:W10),NA()) -> 0.024236421 | AH10: =IF(ISNUMBER(X8),AVERAGE(X8:X10),NA()) -> 0.04803064 | AI10: =AVERAGE(J8:J10) -> 118865 | AJ10: =AVERAGE(I8:I10) -> 63431 | AK10: =AVERAGE(K8:K10) -> 6900
A11: 33117 | B11: 33117 | C11: 1764 | D11: 1378 | E11: 1752 | F11: 3356 | G11: 1559 | H11: 2975 | I11: 63636 | J11: 118524 | K11: 7368 | M11: =J11+K11 -> 125892 | P11: =K11/M11 -> 0.058526356 | Q11: =I11/M11 -> 0.50548089 | R11: =IF(ISNUMBER(L11),L11/M11,NA()) -> #N/A | S11: =IF(ISNUMBER(C11),C11/$K10,NA()) -> 0.24540902 | T11: =IF(ISNUMBER(D11),D11/$K10,NA()) -> 0.1917084 | U11: =IF(ISNUMBER(E11),E11/$J10,NA()) -> 0.014747226 | V11: =IF(ISNUMBER(F11),F11/$J10,NA()) -> 0.028248683 | W11: =IF(ISNUMBER(G11),G11/$I10,NA()) -> 0.024608536 | X11: =IF(ISNUMBER(H11),H11/$I11,NA()) -> 0.046750267 | Y11: =B11 -> 33117 | Z11: =IF(ISNUMBER(P9),AVERAGE(P9:P11),NA()) -> 0.05687737 | AA11: =IF(ISNUMBER(Q9),AVERAGE(Q9:Q11),NA()) -> 0.50433566 | AB11: =IF(ISNUMBER(R9),AVERAGE(R9:R11),NA()) -> #N/A | AC11: =IF(ISNUMBER(S9),AVERAGE(S9:S11),NA()) -> 0.26718246 | AD11: =IF(ISNUMBER(T9),AVERAGE(T9:T11),NA()) -> 0.19951282 | AE11: =IF(ISNUMBER(U9),AVERAGE(U9:U11),NA()) -> 0.015619605 | AF11: =IF(ISNUMBER(V9),AVERAGE(V9:V11),NA()) -> 0.027367035 | AG11: =IF(ISNUMBER(W9),AVERAGE(W9:W11),NA()) -> 0.025134707 | AH11: =IF(ISNUMBER(X9),AVERAGE(X9:X11),NA()) -> 0.047935818 | AI11: =AVERAGE(J9:J11) -> 118712 | AJ11: =AVERAGE(I9:I11) -> 63481.333 | AK11: =AVERAGE(K9:K11) -> 7159.3333
A12: 33147 | B12: 33147 | C12: 2029 | D12: 1413 | E12: 1902 | F12: 3236 | G12: 1613 | H12: 3032 | I12: 63715 | J12: 118536 | K12: 7459 | M12: =J12+K12 -> 125995 | P12: =K12/M12 -> 0.059200762 | Q12: =I12/M12 -> 0.50569467 | R12: =IF(ISNUMBER(L12),L12/M12,NA()) -> #N/A | S12: =IF(ISNUMBER(C12),C12/$K11,NA()) -> 0.27538002 | T12: =IF(ISNUMBER(D12),D12/$K11,NA()) -> 0.19177524 | U12: =IF(ISNUMBER(E12),E12/$J11,NA()) -> 0.016047383 | V12: =IF(ISNUMBER(F12),F12/$J11,NA()) -> 0.027302487 | W12: =IF(ISNUMBER(G12),G12/$I11,NA()) -> 0.025347288 | X12: =IF(ISNUMBER(H12),H12/$I12,NA()) -> 0.04758691 | Y12: =B12 -> 33147 | Z12: =IF(ISNUMBER(P10),AVERAGE(P10:P12),NA()) -> 0.058259755 | AA12: =IF(ISNUMBER(Q10),AVERAGE(Q10:Q12),NA()) -> 0.50466971 | AB12: =IF(ISNUMBER(R10),AVERAGE(R10:R12),NA()) -> #N/A | AC12: =IF(ISNUMBER(S10),AVERAGE(S10:S12),NA()) -> 0.26701829 | AD12: =IF(ISNUMBER(T10),AVERAGE(T10:T12),NA()) -> 0.19307877 | AE12: =IF(ISNUMBER(U10),AVERAGE(U10:U12),NA()) -> 0.015530981 | AF12: =IF(ISNUMBER(V10),AVERAGE(V10:V12),NA()) -> 0.02723125 | AG12: =IF(ISNUMBER(W10),AVERAGE(W10:W12),NA()) -> 0.025361388 | AH12: =IF(ISNUMBER(X10),AVERAGE(X10:X12),NA()) -> 0.047025345 | AI12: =AVERAGE(J10:J12) -> 118620.67 | AJ12: =AVERAGE(I10:I12) -> 63567.667 | AK12: =AVERAGE(K10:K12) -> 7338.3333
A13: 33178 | B13: 33178 | C13: 1975 | D13: 1455 | E13: 2034 | F13: 3308 | G13: 1668 | H13: 3092 | I13: 63802 | J13: 118306 | K13: 7764 | M13: =J13+K13 -> 126070 | P13: =K13/M13 -> 0.061584834 | Q13: =I13/M13 -> 0.50608392 | R13: =IF(ISNUMBER(L13),L13/M13,NA()) -> #N/A | S13: =IF(ISNUMBER(C13),C13/$K12,NA()) -> 0.2647808 | T13: =IF(ISNUMBER(D13),D13/$K12,NA()) -> 0.19506636 | U13: =IF(ISNUMBER(E13),E13/$J12,NA()) -> 0.017159344 | V13: =IF(ISNUMBER(F13),F13/$J12,NA()) -> 0.027907134 | W13: =IF(ISNUMBER(G13),G13/$I12,NA()) -> 0.026179079 | X13: =IF(ISNUMBER(H13),H13/$I13,NA()) -> 0.048462431 | Y13: =B13 -> 33178 | Z13: =IF(ISNUMBER(P11),AVERAGE(P11:P13),NA()) -> 0.059770651 | AA13: =IF(ISNUMBER(Q11),AVERAGE(Q11:Q13),NA()) -> 0.50575316 | AB13: =IF(ISNUMBER(R11),AVERAGE(R11:R13),NA()) -> #N/A | AC13: =IF(ISNUMBER(S11),AVERAGE(S11:S13),NA()) -> 0.26185661 | AD13: =IF(ISNUMBER(T11),AVERAGE(T11:T13),NA()) -> 0.19285 | AE13: =IF(ISNUMBER(U11),AVERAGE(U11:U13),NA()) -> 0.015984651 | AF13: =IF(ISNUMBER(V11),AVERAGE(V11:V13),NA()) -> 0.027819435 | AG13: =IF(ISNUMBER(W11),AVERAGE(W11:W13),NA()) -> 0.025378301 | AH13: =IF(ISNUMBER(X11),AVERAGE(X11:X13),NA()) -> 0.047599869 | AI13: =AVERAGE(J11:J13) -> 118455.33 | AJ13: =AVERAGE(I11:I13) -> 63717.667 | AK13: =AVERAGE(K11:K13) -> 7530.3333
A14: 33208 | B14: 33208 | C14: 1963 | D14: 1490 | E14: 1874 | F14: 3185 | G14: 1692 | H14: 2962 | I14: 63875 | J14: 118241 | K14: 7901 | M14: =J14+K14 -> 126142 | P14: =K14/M14 -> 0.06263576 | Q14: =I14/M14 -> 0.50637377 | R14: =IF(ISNUMBER(L14),L14/M14,NA()) -> #N/A | S14: =IF(ISNUMBER(C14),C14/$K13,NA()) -> 0.25283359 | T14: =IF(ISNUMBER(D14),D14/$K13,NA()) -> 0.19191139 | U14: =IF(ISNUMBER(E14),E14/$J13,NA()) -> 0.015840279 | V14: =IF(ISNUMBER(F14),F14/$J13,NA()) -> 0.026921711 | W14: =IF(ISNUMBER(G14),G14/$I13,NA()) -> 0.026519545 | X14: =IF(ISNUMBER(H14),H14/$I14,NA()) -> 0.04637182 | Y14: =B14 -> 33208 | Z14: =IF(ISNUMBER(P12),AVERAGE(P12:P14),NA()) -> 0.061140452 | AA14: =IF(ISNUMBER(Q12),AVERAGE(Q12:Q14),NA()) -> 0.50605079 | AB14: =IF(ISNUMBER(R12),AVERAGE(R12:R14),NA()) -> #N/A | AC14: =IF(ISNUMBER(S12),AVERAGE(S12:S14),NA()) -> 0.26433147 | AD14: =IF(ISNUMBER(T12),AVERAGE(T12:T14),NA()) -> 0.19291766 | AE14: =IF(ISNUMBER(U12),AVERAGE(U12:U14),NA()) -> 0.016349002 | AF14: =IF(ISNUMBER(V12),AVERAGE(V12:V14),NA()) -> 0.027377111 | AG14: =IF(ISNUMBER(W12),AVERAGE(W12:W14),NA()) -> 0.026015304 | AH14: =IF(ISNUMBER(X12),AVERAGE(X12:X14),NA()) -> 0.04747372 | AI14: =AVERAGE(J12:J14) -> 118361 | AJ14: =AVERAGE(I12:I14) -> 63797.333 | AK14: =AVERAGE(K12:K14) -> 7708
A15: 33239 | B15: 33239 | C15: 2016 | D15: 1582 | E15: 1978 | F15: 3237 | G15: 1698 | H15: 2836 | I15: 64208 | J15: 117940 | K15: 8015 | M15: =J15+K15 -> 125955 | P15: =K15/M15 -> 0.063633837 | Q15: =I15/M15 -> 0.50976936 | R15: =IF(ISNUMBER(L15),L15/M15,NA()) -> #N/A | S15: =IF(ISNUMBER(C15),C15/$K14,NA()) -> 0.25515757 | T15: =IF(ISNUMBER(D15),D15/$K14,NA()) -> 0.20022782 | U15: =IF(ISNUMBER(E15),E15/$J14,NA()) -> 0.016728546 | V15: =IF(ISNUMBER(F15),F15/$J14,NA()) -> 0.027376291 | W15: =IF(ISNUMBER(G15),G15/$I14,NA()) -> 0.02658317 | X15: =IF(ISNUMBER(H15),H15/$I15,NA()) -> 0.044168951 | Y15: =B15 -> 33239 | Z15: =IF(ISNUMBER(P13),AVERAGE(P13:P15),NA()) -> 0.062618144 | AA15: =IF(ISNUMBER(Q13),AVERAGE(Q13:Q15),NA()) -> 0.50740902 | AB15: =IF(ISNUMBER(R13),AVERAGE(R13:R15),NA()) -> #N/A | AC15: =IF(ISNUMBER(S13),AVERAGE(S13:S15),NA()) -> 0.25759066 | AD15: =IF(ISNUMBER(T13),AVERAGE(T13:T15),NA()) -> 0.19573519 | AE15: =IF(ISNUMBER(U13),AVERAGE(U13:U15),NA()) -> 0.016576056 | AF15: =IF(ISNUMBER(V13),AVERAGE(V13:V15),NA()) -> 0.027401712 | AG15: =IF(ISNUMBER(W13),AVERAGE(W13:W15),NA()) -> 0.026427265 | AH15: =IF(ISNUMBER(X13),AVERAGE(X13:X15),NA()) -> 0.046334401 | AI15: =AVERAGE(J13:J15) -> 118162.33 | AJ15: =AVERAGE(I13:I15) -> 63961.667 | AK15: =AVERAGE(K13:K15) -> 7893.3333
A16: 33270 | B16: 33270 | C16: 2043 | D16: 1522 | E16: 2084 | F16: 3022 | G16: 1718 | H16: 2857 | I16: 64251 | J16: 117755 | K16: 8265 | M16: =J16+K16 -> 126020 | P16: =K16/M16 -> 0.065584828 | Q16: =I16/M16 -> 0.50984764 | R16: =IF(ISNUMBER(L16),L16/M16,NA()) -> #N/A | S16: =IF(ISNUMBER(C16),C16/$K15,NA()) -> 0.25489707 | T16: =IF(ISNUMBER(D16),D16/$K15,NA()) -> 0.18989395 | U16: =IF(ISNUMBER(E16),E16/$J15,NA()) -> 0.017670002 | V16: =IF(ISNUMBER(F16),F16/$J15,NA()) -> 0.025623198 | W16: =IF(ISNUMBER(G16),G16/$I15,NA()) -> 0.02675679 | X16: =IF(ISNUMBER(H16),H16/$I16,NA()) -> 0.044466234 | Y16: =B16 -> 33270 | Z16: =IF(ISNUMBER(P14),AVERAGE(P14:P16),NA()) -> 0.063951475 | AA16: =IF(ISNUMBER(Q14),AVERAGE(Q14:Q16),NA()) -> 0.50866359 | AB16: =IF(ISNUMBER(R14),AVERAGE(R14:R16),NA()) -> #N/A | AC16: =IF(ISNUMBER(S14),AVERAGE(S14:S16),NA()) -> 0.25429608 | AD16: =IF(ISNUMBER(T14),AVERAGE(T14:T16),NA()) -> 0.19401105 | AE16: =IF(ISNUMBER(U14),AVERAGE(U14:U16),NA()) -> 0.016746275 | AF16: =IF(ISNUMBER(V14),AVERAGE(V14:V16),NA()) -> 0.0266404 | AG16: =IF(ISNUMBER(W14),AVERAGE(W14:W16),NA()) -> 0.026619835 | AH16: =IF(ISNUMBER(X14),AVERAGE(X14:X16),NA()) -> 0.045002335 | AI16: =AVERAGE(J14:J16) -> 117978.67 | AJ16: =AVERAGE(I14:I16) -> 64111.333 | AK16: =AVERAGE(K14:K16) -> 8060.3333
A17: 33298 | B17: 33298 | C17: 2091 | D17: 1510 | E17: 2130 | F17: 3082 | G17: 1774 | H17: 2982 | I17: 64143 | J17: 117652 | K17: 8586 | M17: =J17+K17 -> 126238 | P17: =K17/M17 -> 0.068014386 | Q17: =I17/M17 -> 0.50811166 | R17: =IF(ISNUMBER(L17),L17/M17,NA()) -> #N/A | S17: =IF(ISNUMBER(C17),C17/$K16,NA()) -> 0.25299456 | T17: =IF(ISNUMBER(D17),D17/$K16,NA()) -> 0.18269812 | U17: =IF(ISNUMBER(E17),E17/$J16,NA()) -> 0.018088404 | V17: =IF(ISNUMBER(F17),F17/$J16,NA()) -> 0.026172986 | W17: =IF(ISNUMBER(G17),G17/$I16,NA()) -> 0.027610465 | X17: =IF(ISNUMBER(H17),H17/$I17,NA()) -> 0.046489874 | Y17: =B17 -> 33298 | Z17: =IF(ISNUMBER(P15),AVERAGE(P15:P17),NA()) -> 0.06574435 | AA17: =IF(ISNUMBER(Q15),AVERAGE(Q15:Q17),NA()) -> 0.50924289 | AB17: =IF(ISNUMBER(R15),AVERAGE(R15:R17),NA()) -> #N/A | AC17: =IF(ISNUMBER(S15),AVERAGE(S15:S17),NA()) -> 0.25434973 | AD17: =IF(ISNUMBER(T15),AVERAGE(T15:T17),NA()) -> 0.19093996 | AE17: =IF(ISNUMBER(U15),AVERAGE(U15:U17),NA()) -> 0.017495651 | AF17: =IF(ISNUMBER(V15),AVERAGE(V15:V17),NA()) -> 0.026390825 | AG17: =IF(ISNUMBER(W15),AVERAGE(W15:W17),NA()) -> 0.026983475 | AH17: =IF(ISNUMBER(X15),AVERAGE(X15:X17),NA()) -> 0.045041686 | AI17: =AVERAGE(J15:J17) -> 117782.33 | AJ17: =AVERAGE(I15:I17) -> 64200.667 | AK17: =AVERAGE(K15:K17) -> 8288.6667
... A133: 36831 | B133: 36831 | C133: 1709 | D133: 1244 | E133: 1444 | F133: 3894 | G133: 1596 | H133: 3831 | I133: 70578 | J133: 137322 | K133: 5639 | M133: =J133+K133 -> 142961 | P133: =K133/M133 -> 0.039444324 | Q133: =I133/M133 -> 0.49368709 | R133: =IF(ISNUMBER(L133),L133/M133,NA()) -> #N/A | S133: =IF(ISNUMBER(C133),C133/$K132,NA()) -> 0.30881821 | T133: =IF(ISNUMBER(D133),D133/$K132,NA()) -> 0.22479219 | U133: =IF(ISNUMBER(E133),E133/$J132,NA()) -> 0.01053338 | V133: =IF(ISNUMBER(F133),F133/$J132,NA()) -> 0.028405112 | W133: =IF(ISNUMBER(G133),G133/$I132,NA()) -> 0.022547787 | X133: =IF(ISNUMBER(H133),H133/$I133,NA()) -> 0.054280371 | Y133: =B133 -> 36831 | Z133: =IF(ISNUMBER(P131),AVERAGE(P131:P133),NA()) -> 0.039238297 | AA133: =IF(ISNUMBER(Q131),AVERAGE(Q131:Q133),NA()) -> 0.49522559 | AB133: =IF(ISNUMBER(R131),AVERAGE(R131:R133),NA()) -> #N/A | AC133: =IF(ISNUMBER(S131),AVERAGE(S131:S133),NA()) -> 0.32142595 | AD133: =IF(ISNUMBER(T131),AVERAGE(T131:T133),NA()) -> 0.23562319 | AE133: =IF(ISNUMBER(U131),AVERAGE(U131:U133),NA()) -> 0.011290383 | AF133: =IF(ISNUMBER(V131),AVERAGE(V131:V133),NA()) -> 0.028550413 | AG133: =IF(ISNUMBER(W131),AVERAGE(W131:W133),NA()) -> 0.021548898 | AH133: =IF(ISNUMBER(X131),AVERAGE(X131:X133),NA()) -> 0.053287285 | AI133: =AVERAGE(J131:J133) -> 137101 | AJ133: =AVERAGE(I131:I133) -> 70668.667 | AK133: =AVERAGE(K131:K133) -> 5599.3333
A134: 36861 | B134: 36861 | C134: 1699 | D134: 1293 | E134: 1472 | F134: 3748 | G134: 1487 | H134: 3768 | I134: 70488 | J134: 137614 | K134: 5634 | L134: 5191 | M134: =J134+K134 -> 143248 | P134: =K134/M134 -> 0.039330392 | Q134: =I134/M134 -> 0.4920697 | R134: =IF(ISNUMBER(L134),L134/M134,NA()) -> 0.036237853 | S134: =IF(ISNUMBER(C134),C134/$K133,NA()) -> 0.30129456 | T134: =IF(ISNUMBER(D134),D134/$K133,NA()) -> 0.22929597 | U134: =IF(ISNUMBER(E134),E134/$J133,NA()) -> 0.010719331 | V134: =IF(ISNUMBER(F134),F134/$J133,NA()) -> 0.027293515 | W134: =IF(ISNUMBER(G134),G134/$I133,NA()) -> 0.021068888 | X134: =IF(ISNUMBER(H134),H134/$I134,NA()) -> 0.053455907 | Y134: =B134 -> 36861 | Z134: =IF(ISNUMBER(P132),AVERAGE(P132:P134),NA()) -> 0.039192195 | AA134: =IF(ISNUMBER(Q132),AVERAGE(Q132:Q134),NA()) -> 0.49401823 | AB134: =IF(ISNUMBER(R132),AVERAGE(R132:R134),NA()) -> #N/A | AC134: =IF(ISNUMBER(S132),AVERAGE(S132:S134),NA()) -> 0.31507463 | AD134: =IF(ISNUMBER(T132),AVERAGE(T132:T134),NA()) -> 0.22679976 | AE134: =IF(ISNUMBER(U132),AVERAGE(U132:U134),NA()) -> 0.010856039 | AF134: =IF(ISNUMBER(V132),AVERAGE(V132:V134),NA()) -> 0.028133292 | AG134: =IF(ISNUMBER(W132),AVERAGE(W132:W134),NA()) -> 0.021607097 | AH134: =IF(ISNUMBER(X132),AVERAGE(X132:X134),NA()) -> 0.053293856 | AI134: =AVERAGE(J132:J134) -> 137341.33 | AJ134: =AVERAGE(I132:I134) -> 70616.333 | AK134: =AVERAGE(K132:K134) -> 5602.3333
A135: 36892 | B135: 36892 | C135: 1784 | D135: 1258 | E135: 1758 | F135: 3894 | G135: 1660 | H135: 3972 | I135: 70088 | J135: 137778 | K135: 6023 | L135: 5186 | M135: =J135+K135 -> 143801 | P135: =K135/M135 -> 0.041884271 | Q135: =I135/M135 -> 0.48739578 | R135: =IF(ISNUMBER(L135),L135/M135,NA()) -> 0.036063727 | S135: =IF(ISNUMBER(C135),C135/$K134,NA()) -> 0.31664892 | T135: =IF(ISNUMBER(D135),D135/$K134,NA()) -> 0.22328718 | U135: =IF(ISNUMBER(E135),E135/$J134,NA()) -> 0.012774863 | V135: =IF(ISNUMBER(F135),F135/$J134,NA()) -> 0.02829654 | W135: =IF(ISNUMBER(G135),G135/$I134,NA()) -> 0.023550108 | X135: =IF(ISNUMBER(H135),H135/$I135,NA()) -> 0.056671613 | Y135: =B135 -> 36892 | Z135: =IF(ISNUMBER(P133),AVERAGE(P133:P135),NA()) -> 0.040219662 | AA135: =IF(ISNUMBER(Q133),AVERAGE(Q133:Q135),NA()) -> 0.49105085 | AB135: =IF(ISNUMBER(R133),AVERAGE(R133:R135),NA()) -> #N/A | AC135: =IF(ISNUMBER(S133),AVERAGE(S133:S135),NA()) -> 0.30892056 | AD135: =IF(ISNUMBER(T133),AVERAGE(T133:T135),NA()) -> 0.22579178 | AE135: =IF(ISNUMBER(U133),AVERAGE(U133:U135),NA()) -> 0.011342525 | AF135: =IF(ISNUMBER(V133),AVERAGE(V133:V135),NA()) -> 0.027998389 | AG135: =IF(ISNUMBER(W133),AVERAGE(W133:W135),NA()) -> 0.022388928 | AH135: =IF(ISNUMBER(X133),AVERAGE(X133:X135),NA()) -> 0.05480263 | AI135: =AVERAGE(J133:J135) -> 137571.33 | AJ135: =AVERAGE(I133:I135) -> 70384.667 | AK135: =AVERAGE(K133:K135) -> 5765.3333
A136: 36923 | B136: 36923 | C136: 1831 | D136: 1436 | E136: 1729 | F136: 4170 | G136: 1573 | H136: 3843 | I136: 70409 | J136: 137612 | K136: 6089 | L136: 4702 | M136: =J136+K136 -> 143701 | P136: =K136/M136 -> 0.042372704 | Q136: =I136/M136 -> 0.48996875 | R136: =IF(ISNUMBER(L136),L136/M136,NA()) -> 0.032720719 | S136: =IF(ISNUMBER(C136),C136/$K135,NA()) -> 0.30400133 | T136: =IF(ISNUMBER(D136),D136/$K135,NA()) -> 0.23841939 | U136: =IF(ISNUMBER(E136),E136/$J135,NA()) -> 0.012549173 | V136: =IF(ISNUMBER(F136),F136/$J135,NA()) -> 0.03026608 | W136: =IF(ISNUMBER(G136),G136/$I135,NA()) -> 0.022443214 | X136: =IF(ISNUMBER(H136),H136/$I136,NA()) -> 0.05458109 | Y136: =B136 -> 36923 | Z136: =IF(ISNUMBER(P134),AVERAGE(P134:P136),NA()) -> 0.041195789 | AA136: =IF(ISNUMBER(Q134),AVERAGE(Q134:Q136),NA()) -> 0.48981141 | AB136: =IF(ISNUMBER(R134),AVERAGE(R134:R136),NA()) -> 0.035007433 | AC136: =IF(ISNUMBER(S134),AVERAGE(S134:S136),NA()) -> 0.30731493 | AD136: =IF(ISNUMBER(T134),AVERAGE(T134:T136),NA()) -> 0.23033418 | AE136: =IF(ISNUMBER(U134),AVERAGE(U134:U136),NA()) -> 0.012014456 | AF136: =IF(ISNUMBER(V134),AVERAGE(V134:V136),NA()) -> 0.028618711 | AG136: =IF(ISNUMBER(W134),AVERAGE(W134:W136),NA()) -> 0.02235407 | AH136: =IF(ISNUMBER(X134),AVERAGE(X134:X136),NA()) -> 0.05490287 | AI136: =AVERAGE(J134:J136) -> 137668 | AJ136: =AVERAGE(I134:I136) -> 70328.333 | AK136: =AVERAGE(K134:K136) -> 5915.3333
A137: 36951 | B137: 36951 | C137: 1892 | D137: 1478 | E137: 1782 | F137: 3836 | G137: 1626 | H137: 3840 | I137: 70381 | J137: 137783 | K137: 6141 | L137: 4774 | M137: =J137+K137 -> 143924 | P137: =K137/M137 -> 0.042668353 | Q137: =I137/M137 -> 0.48901504 | R137: =IF(ISNUMBER(L137),L137/M137,NA()) -> 0.033170284 | S137: =IF(ISNUMBER(C137),C137/$K136,NA()) -> 0.31072426 | T137: =IF(ISNUMBER(D137),D137/$K136,NA()) -> 0.2427328 | U137: =IF(ISNUMBER(E137),E137/$J136,NA()) -> 0.012949452 | V137: =IF(ISNUMBER(F137),F137/$J136,NA()) -> 0.027875476 | W137: =IF(ISNUMBER(G137),G137/$I136,NA()) -> 0.023093639 | X137: =IF(ISNUMBER(H137),H137/$I137,NA()) -> 0.05456018 | Y137: =B137 -> 36951 | Z137: =IF(ISNUMBER(P135),AVERAGE(P135:P137),NA()) -> 0.042308443 | AA137: =IF(ISNUMBER(Q135),AVERAGE(Q135:Q137),NA()) -> 0.48879319 | AB137: =IF(ISNUMBER(R135),AVERAGE(R135:R137),NA()) -> 0.03398491 | AC137: =IF(ISNUMBER(S135),AVERAGE(S135:S137),NA()) -> 0.31045817 | AD137: =IF(ISNUMBER(T135),AVERAGE(T135:T137),NA()) -> 0.23481312 | AE137: =IF(ISNUMBER(U135),AVERAGE(U135:U137),NA()) -> 0.012757829 | AF137: =IF(ISNUMBER(V135),AVERAGE(V135:V137),NA()) -> 0.028812699 | AG137: =IF(ISNUMBER(W135),AVERAGE(W135:W137),NA()) -> 0.023028987 | AH137: =IF(ISNUMBER(X135),AVERAGE(X135:X137),NA()) -> 0.055270961 | AI137: =AVERAGE(J135:J137) -> 137724.33 | AJ137: =AVERAGE(I135:I137) -> 70292.667 | AK137: =AVERAGE(K135:K137) -> 6084.3333
A138: 36982 | B138: 36982 | C138: 1859 | D138: 1536 | E138: 1827 | F138: 4193 | G138: 1672 | H138: 3594 | I138: 70956 | J138: 137299 | K138: 6271 | L138: 4653 | M138: =J138+K138 -> 143570 | P138: =K138/M138 -> 0.043679042 | Q138: =I138/M138 -> 0.49422581 | R138: =IF(ISNUMBER(L138),L138/M138,NA()) -> 0.032409278 | S138: =IF(ISNUMBER(C138),C138/$K137,NA()) -> 0.30271943 | T138: =IF(ISNUMBER(D138),D138/$K137,NA()) -> 0.25012213 | U138: =IF(ISNUMBER(E138),E138/$J137,NA()) -> 0.013259981 | V138: =IF(ISNUMBER(F138),F138/$J137,NA()) -> 0.030431911 | W138: =IF(ISNUMBER(G138),G138/$I137,NA()) -> 0.023756412 | X138: =IF(ISNUMBER(H138),H138/$I138,NA()) -> 0.050651108 | Y138: =B138 -> 36982 | Z138: =IF(ISNUMBER(P136),AVERAGE(P136:P138),NA()) -> 0.0429067 | AA138: =IF(ISNUMBER(Q136),AVERAGE(Q136:Q138),NA()) -> 0.49106987 | AB138: =IF(ISNUMBER(R136),AVERAGE(R136:R138),NA()) -> 0.03276676 | AC138: =IF(ISNUMBER(S136),AVERAGE(S136:S138),NA()) -> 0.305815 | AD138: =IF(ISNUMBER(T136),AVERAGE(T136:T138),NA()) -> 0.24375811 | AE138: =IF(ISNUMBER(U136),AVERAGE(U136:U138),NA()) -> 0.012919536 | AF138: =IF(ISNUMBER(V136),AVERAGE(V136:V138),NA()) -> 0.029524489 | AG138: =IF(ISNUMBER(W136),AVERAGE(W136:W138),NA()) -> 0.023097755 | AH138: =IF(ISNUMBER(X136),AVERAGE(X136:X138),NA()) -> 0.053264126 | AI138: =AVERAGE(J136:J138) -> 137564.67 | AJ138: =AVERAGE(I136:I138) -> 70582 | AK138: =AVERAGE(K136:K138) -> 6167
A139: 37012 | B139: 37012 | C139: 2034 | D139: 1462 | E139: 1810 | F139: 4163 | G139: 1618 | H139: 3677 | I139: 71414 | J139: 137092 | K139: 6226 | L139: 4452 | M139: =J139+K139 -> 143318 | P139: =K139/M139 -> 0.043441857 | Q139: =I139/M139 -> 0.49829051 | R139: =IF(ISNUMBER(L139),L139/M139,NA()) -> 0.031063788 | S139: =IF(ISNUMBER(C139),C139/$K138,NA()) -> 0.32435018 | T139: =IF(ISNUMBER(D139),D139/$K138,NA()) -> 0.23313666 | U139: =IF(ISNUMBER(E139),E139/$J138,NA()) -> 0.013182907 | V139: =IF(ISNUMBER(F139),F139/$J138,NA()) -> 0.030320687 | W139: =IF(ISNUMBER(G139),G139/$I138,NA()) -> 0.022802864 | X139: =IF(ISNUMBER(H139),H139/$I139,NA()) -> 0.051488504 | Y139: =B139 -> 37012 | Z139: =IF(ISNUMBER(P137),AVERAGE(P137:P139),NA()) -> 0.043263084 | AA139: =IF(ISNUMBER(Q137),AVERAGE(Q137:Q139),NA()) -> 0.49384379 | AB139: =IF(ISNUMBER(R137),AVERAGE(R137:R139),NA()) -> 0.03221445 | AC139: =IF(ISNUMBER(S137),AVERAGE(S137:S139),NA()) -> 0.31259796 | AD139: =IF(ISNUMBER(T137),AVERAGE(T137:T139),NA()) -> 0.2419972 | AE139: =IF(ISNUMBER(U137),AVERAGE(U137:U139),NA()) -> 0.01313078 | AF139: =IF(ISNUMBER(V137),AVERAGE(V137:V139),NA()) -> 0.029542691 | AG139: =IF(ISNUMBER(W137),AVERAGE(W137:W139),NA()) -> 0.023217638 | AH139: =IF(ISNUMBER(X137),AVERAGE(X137:X139),NA()) -> 0.052233264 | AI139: =AVERAGE(J137:J139) -> 137391.33 | AJ139: =AVERAGE(I137:I139) -> 70917 | AK139: =AVERAGE(K137:K139) -> 6212.6667
A140: 37043 | B140: 37043 | C140: 1910 | D140: 1437 | E140: 1877 | F140: 3958 | G140: 1689 | H140: 3655 | I140: 71593 | J140: 136873 | K140: 6484 | L140: 4337 | M140: =J140+K140 -> 143357 | P140: =K140/M140 -> 0.045229741 | Q140: =I140/M140 -> 0.49940359 | R140: =IF(ISNUMBER(L140),L140/M140,NA()) -> 0.030253144 | S140: =IF(ISNUMBER(C140),C140/$K139,NA()) -> 0.30677803 | T140: =IF(ISNUMBER(D140),D140/$K139,NA()) -> 0.2308063 | U140: =IF(ISNUMBER(E140),E140/$J139,NA()) -> 0.013691536 | V140: =IF(ISNUMBER(F140),F140/$J139,NA()) -> 0.028871123 | W140: =IF(ISNUMBER(G140),G140/$I139,NA()) -> 0.023650825 | X140: =IF(ISNUMBER(H140),H140/$I140,NA()) -> 0.051052477 | Y140: =B140 -> 37043 | Z140: =IF(ISNUMBER(P138),AVERAGE(P138:P140),NA()) -> 0.04411688 | AA140: =IF(ISNUMBER(Q138),AVERAGE(Q138:Q140),NA()) -> 0.49730664 | AB140: =IF(ISNUMBER(R138),AVERAGE(R138:R140),NA()) -> 0.03124207 | AC140: =IF(ISNUMBER(S138),AVERAGE(S138:S140),NA()) -> 0.31128255 | AD140: =IF(ISNUMBER(T138),AVERAGE(T138:T140),NA()) -> 0.2380217 | AE140: =IF(ISNUMBER(U138),AVERAGE(U138:U140),NA()) -> 0.013378141 | AF140: =IF(ISNUMBER(V138),AVERAGE(V138:V140),NA()) -> 0.029874574 | AG140: =IF(ISNUMBER(W138),AVERAGE(W138:W140),NA()) -> 0.023403367 | AH140: =IF(ISNUMBER(X138),AVERAGE(X138:X140),NA()) -> 0.05106403 | AI140: =AVERAGE(J138:J140) -> 137088 | AJ140: =AVERAGE(I138:I140) -> 71321 | AK140: =AVERAGE(K138:K140) -> 6327
A141: 37073 | B141: 37073 | C141: 1956 | D141: 1456 | E141: 1833 | F141: 4028 | G141: 1661 | H141: 4003 | I141: 71526 | J141: 137071 | K141: 6583 | L141: 4231 | M141: =J141+K141 -> 143654 | P141: =K141/M141 -> 0.045825386 | Q141: =I141/M141 -> 0.49790469 | R141: =IF(ISNUMBER(L141),L141/M141,NA()) -> 0.029452713 | S141: =IF(ISNUMBER(C141),C141/$K140,NA()) -> 0.30166564 | T141: =IF(ISNUMBER(D141),D141/$K140,NA()) -> 0.22455275 | U141: =IF(ISNUMBER(E141),E141/$J140,NA()) -> 0.013391977 | V141: =IF(ISNUMBER(F141),F141/$J140,NA()) -> 0.029428741 | W141: =IF(ISNUMBER(G141),G141/$I140,NA()) -> 0.023200592 | X141: =IF(ISNUMBER(H141),H141/$I141,NA()) -> 0.055965663 | Y141: =B141 -> 37073 | Z141: =IF(ISNUMBER(P139),AVERAGE(P139:P141),NA()) -> 0.044832328 | AA141: =IF(ISNUMBER(Q139),AVERAGE(Q139:Q141),NA()) -> 0.49853293 | AB141: =IF(ISNUMBER(R139),AVERAGE(R139:R141),NA()) -> 0.030256548 | AC141: =IF(ISNUMBER(S139),AVERAGE(S139:S141),NA()) -> 0.31093128 | AD141: =IF(ISNUMBER(T139),AVERAGE(T139:T141),NA()) -> 0.22949857 | AE141: =IF(ISNUMBER(U139),AVERAGE(U139:U141),NA()) -> 0.01342214 | AF141: =IF(ISNUMBER(V139),AVERAGE(V139:V141),NA()) -> 0.029540184 | AG141: =IF(ISNUMBER(W139),AVERAGE(W139:W141),NA()) -> 0.023218094 | AH141: =IF(ISNUMBER(X139),AVERAGE(X139:X141),NA()) -> 0.052835548 | AI141: =AVERAGE(J139:J141) -> 137012 | AJ141: =AVERAGE(I139:I141) -> 71511 | AK141: =AVERAGE(K139:K141) -> 6431
A142: 37104 | B142: 37104 | C142: 1914 | D142: 1454 | E142: 1946 | F142: 4523 | G142: 1861 | H142: 3663 | I142: 72136 | J142: 136241 | K142: 7042 | L142: 4139 | M142: =J142+K142 -> 143283 | P142: =K142/M142 -> 0.049147491 | Q142: =I142/M142 -> 0.50345121 | R142: =IF(ISNUMBER(L142),L142/M142,NA()) -> 0.028886888 | S142: =IF(ISNUMBER(C142),C142/$K141,NA()) -> 0.2907489 | T142: =IF(ISNUMBER(D142),D142/$K141,NA()) -> 0.22087194 | U142: =IF(ISNUMBER(E142),E142/$J141,NA()) -> 0.014197022 | V142: =IF(ISNUMBER(F142),F142/$J141,NA()) -> 0.032997498 | W142: =IF(ISNUMBER(G142),G142/$I141,NA()) -> 0.026018511 | X142: =IF(ISNUMBER(H142),H142/$I142,NA()) -> 0.050779084 | Y142: =B142 -> 37104 | Z142: =IF(ISNUMBER(P140),AVERAGE(P140:P142),NA()) -> 0.046734206 | AA142: =IF(ISNUMBER(Q140),AVERAGE(Q140:Q142),NA()) -> 0.50025316 | AB142: =IF(ISNUMBER(R140),AVERAGE(R140:R142),NA()) -> 0.029530915 | AC142: =IF(ISNUMBER(S140),AVERAGE(S140:S142),NA()) -> 0.29973085 | AD142: =IF(ISNUMBER(T140),AVERAGE(T140:T142),NA()) -> 0.22541033 | AE142: =IF(ISNUMBER(U140),AVERAGE(U140:U142),NA()) -> 0.013760178 | AF142: =IF(ISNUMBER(V140),AVERAGE(V140:V142),NA()) -> 0.030432454 | AG142: =IF(ISNUMBER(W140),AVERAGE(W140:W142),NA()) -> 0.024289976 | AH142: =IF(ISNUMBER(X140),AVERAGE(X140:X142),NA()) -> 0.052599075 | AI142: =AVERAGE(J140:J142) -> 136728.33 | AJ142: =AVERAGE(I140:I142) -> 71751.667 | AK142: =AVERAGE(K140:K142) -> 6703
A143: 37135 | B143: 37135 | C143: 2045 | D143: 1550 | E143: 1823 | F143: 3839 | G143: 1856 | H143: 4124 | I143: 71676 | J143: 136846 | K143: 7142 | L143: 4006 | M143: =J143+K143 -> 143988 | P143: =K143/M143 -> 0.049601356 | Q143: =I143/M143 -> 0.49779148 | R143: =IF(ISNUMBER(L143),L143/M143,NA()) -> 0.027821763 | S143: =IF(ISNUMBER(C143),C143/$K142,NA()) -> 0.29040045 | T143: =IF(ISNUMBER(D143),D143/$K142,NA()) -> 0.22010792 | U143: =IF(ISNUMBER(E143),E143/$J142,NA()) -> 0.0133807 | V143: =IF(ISNUMBER(F143),F143/$J142,NA()) -> 0.028178008 | W143: =IF(ISNUMBER(G143),G143/$I142,NA()) -> 0.025729178 | X143: =IF(ISNUMBER(H143),H143/$I143,NA()) -> 0.057536693 | Y143: =B143 -> 37135 | Z143: =IF(ISNUMBER(P141),AVERAGE(P141:P143),NA()) -> 0.048191411 | AA143: =IF(ISNUMBER(Q141),AVERAGE(Q141:Q143),NA()) -> 0.49971579 | AB143: =IF(ISNUMBER(R141),AVERAGE(R141:R143),NA()) -> 0.028720455 | AC143: =IF(ISNUMBER(S141),AVERAGE(S141:S143),NA()) -> 0.29427166 | AD143: =IF(ISNUMBER(T141),AVERAGE(T141:T143),NA()) -> 0.2218442 | AE143: =IF(ISNUMBER(U141),AVERAGE(U141:U143),NA()) -> 0.013656566 | AF143: =IF(ISNUMBER(V141),AVERAGE(V141:V143),NA()) -> 0.030201415 | AG143: =IF(ISNUMBER(W141),AVERAGE(W141:W143),NA()) -> 0.02498276 | AH143: =IF(ISNUMBER(X141),AVERAGE(X141:X143),NA()) -> 0.05476048 | AI143: =AVERAGE(J141:J143) -> 136719.33 | AJ143: =AVERAGE(I141:I143) -> 71779.333 | AK143: =AVERAGE(K141:K143) -> 6922.3333
A144: 37165 | B144: 37165 | C144: 1933 | D144: 1562 | E144: 2025 | F144: 3890 | G144: 1989 | H144: 3416 | I144: 71817 | J144: 136392 | K144: 7694 | L144: 3583 | M144: =J144+K144 -> 144086 | P144: =K144/M144 -> 0.053398665 | Q144: =I144/M144 -> 0.49843149 | R144: =IF(ISNUMBER(L144),L144/M144,NA()) -> 0.024867093 | S144: =IF(ISNUMBER(C144),C144/$K143,NA()) -> 0.27065248 | T144: =IF(ISNUMBER(D144),D144/$K143,NA()) -> 0.21870624 | U144: =IF(ISNUMBER(E144),E144/$J143,NA()) -> 0.014797656 | V144: =IF(ISNUMBER(F144),F144/$J143,NA()) -> 0.028426114 | W144: =IF(ISNUMBER(G144),G144/$I143,NA()) -> 0.027749874 | X144: =IF(ISNUMBER(H144),H144/$I144,NA()) -> 0.04756534 | Y144: =B144 -> 37165 | Z144: =IF(ISNUMBER(P142),AVERAGE(P142:P144),NA()) -> 0.050715837 | AA144: =IF(ISNUMBER(Q142),AVERAGE(Q142:Q144),NA()) -> 0.4998914 | AB144: =IF(ISNUMBER(R142),AVERAGE(R142:R144),NA()) -> 0.027191915 | AC144: =IF(ISNUMBER(S142),AVERAGE(S142:S144),NA()) -> 0.28393394 | AD144: =IF(ISNUMBER(T142),AVERAGE(T142:T144),NA()) -> 0.21989537 | AE144: =IF(ISNUMBER(U142),AVERAGE(U142:U144),NA()) -> 0.014125126 | AF144: =IF(ISNUMBER(V142),AVERAGE(V142:V144),NA()) -> 0.029867207 | AG144: =IF(ISNUMBER(W142),AVERAGE(W142:W144),NA()) -> 0.026499188 | AH144: =IF(ISNUMBER(X142),AVERAGE(X142:X144),NA()) -> 0.051960372 | AI144: =AVERAGE(J142:J144) -> 136493 | AJ144: =AVERAGE(I142:I144) -> 71876.333 | AK144: =AVERAGE(K142:K144) -> 7292.6667
A145: 37196 | B145: 37196 | C145: 2121 | D145: 1624 | E145: 2109 | F145: 3719 | G145: 1917 | H145: 3528 | I145: 71877 | J145: 136238 | K145: 8003 | L145: 3538 | M145: =J145+K145 -> 144241 | P145: =K145/M145 -> 0.055483531 | Q145: =I145/M145 -> 0.49831185 | R145: =IF(ISNUMBER(L145),L145/M145,NA()) -> 0.024528393 | S145: =IF(ISNUMBER(C145),C145/$K144,NA()) -> 0.27566935 | T145: =IF(ISNUMBER(D145),D145/$K144,NA()) -> 0.21107356 | U145: =IF(ISNUMBER(E145),E145/$J144,NA()) -> 0.015462784 | V145: =IF(ISNUMBER(F145),F145/$J144,NA()) -> 0.027266995 | W145: =IF(ISNUMBER(G145),G145/$I144,NA()) -> 0.026692844 | X145: =IF(ISNUMBER(H145),H145/$I145,NA()) -> 0.049083852 | Y145: =B145 -> 37196 | Z145: =IF(ISNUMBER(P143),AVERAGE(P143:P145),NA()) -> 0.05282785 | AA145: =IF(ISNUMBER(Q143),AVERAGE(Q143:Q145),NA()) -> 0.49817828 | AB145: =IF(ISNUMBER(R143),AVERAGE(R143:R145),NA()) -> 0.025739083 | AC145: =IF(ISNUMBER(S143),AVERAGE(S143:S145),NA()) -> 0.27890743 | AD145: =IF(ISNUMBER(T143),AVERAGE(T143:T145),NA()) -> 0.21662924 | AE145: =IF(ISNUMBER(U143),AVERAGE(U143:U145),NA()) -> 0.014547047 | AF145: =IF(ISNUMBER(V143),AVERAGE(V143:V145),NA()) -> 0.027957039 | AG145: =IF(ISNUMBER(W143),AVERAGE(W143:W145),NA()) -> 0.026723966 | AH145: =IF(ISNUMBER(X143),AVERAGE(X143:X145),NA()) -> 0.051395295 | AI145: =AVERAGE(J143:J145) -> 136492 | AJ145: =AVERAGE(I143:I145) -> 71790 | AK145: =AVERAGE(K143:K145) -> 7613
... A284: 41426 | B284: 41426 | C284: 2330 | D284: 2481 | E284: 2114 | F284: 4003 | G284: 2686 | H284: 3907 | I284: 89717 | J284: 144058 | K284: 11777 | L284: 3869 | M284: =J284+K284 -> 155835 | P284: =K284/M284 -> 0.075573523 | Q284: =I284/M284 -> 0.57571791 | R284: =IF(ISNUMBER(L284),L284/M284,NA()) -> 0.024827542 | S284: =IF(ISNUMBER(C284),C284/$K283,NA()) -> 0.19812925 | T284: =IF(ISNUMBER(D284),D284/$K283,NA()) -> 0.21096939 | U284: =IF(ISNUMBER(E284),E284/$J283,NA()) -> 0.014690962 | V284: =IF(ISNUMBER(F284),F284/$J283,NA()) -> 0.027818316 | W284: =IF(ISNUMBER(G284),G284/$I283,NA()) -> 0.02994259 | X284: =IF(ISNUMBER(H284),H284/$I284,NA()) -> 0.043548046 | Y284: =B284 -> 41426 | Z284: =IF(ISNUMBER(P282),AVERAGE(P282:P284),NA()) -> 0.075409267 | AA284: =IF(ISNUMBER(Q282),AVERAGE(Q282:Q284),NA()) -> 0.57712083 | AB284: =IF(ISNUMBER(R282),AVERAGE(R282:R284),NA()) -> 0.024801994 | AC284: =IF(ISNUMBER(S282),AVERAGE(S282:S284),NA()) -> 0.19455682 | AD284: =IF(ISNUMBER(T282),AVERAGE(T282:T284),NA()) -> 0.20948737 | AE284: =IF(ISNUMBER(U282),AVERAGE(U282:U284),NA()) -> 0.014120959 | AF284: =IF(ISNUMBER(V282),AVERAGE(V282:V284),NA()) -> 0.027321045 | AG284: =IF(ISNUMBER(W282),AVERAGE(W282:W284),NA()) -> 0.029999041 | AH284: =IF(ISNUMBER(X282),AVERAGE(X282:X284),NA()) -> 0.043157706 | AI284: =AVERAGE(J282:J284) -> 143845 | AJ284: =AVERAGE(I282:I284) -> 89786.333 | AK284: =AVERAGE(K282:K284) -> 11732
A285: 41456 | B285: 41456 | C285: 2337 | D285: 2619 | E285: 1957 | F285: 3854 | G285: 2719 | H285: 3774 | I285: 89958 | J285: 144285 | K285: 11514 | M285: =J285+K285 -> 155799 | P285: =K285/M285 -> 0.073902913 | Q285: =I285/M285 -> 0.5773978 | R285: =IF(ISNUMBER(L285),L285/M285,NA()) -> #N/A | S285: =IF(ISNUMBER(C285),C285/$K284,NA()) -> 0.19843763 | T285: =IF(ISNUMBER(D285),D285/$K284,NA()) -> 0.22238261 | U285: =IF(ISNUMBER(E285),E285/$J284,NA()) -> 0.013584806 | V285: =IF(ISNUMBER(F285),F285/$J284,NA()) -> 0.026753113 | W285: =IF(ISNUMBER(G285),G285/$I284,NA()) -> 0.030306408 | X285: =IF(ISNUMBER(H285),H285/$I285,NA()) -> 0.041952911 | Y285: =B285 -> 41456 | Z285: =IF(ISNUMBER(P283),AVERAGE(P283:P285),NA()) -> 0.075008894 | AA285: =IF(ISNUMBER(Q283),AVERAGE(Q283:Q285),NA()) -> 0.57647039 | AB285: =IF(ISNUMBER(R283),AVERAGE(R283:R285),NA()) -> #N/A | AC285: =IF(ISNUMBER(S283),AVERAGE(S283:S285),NA()) -> 0.19654554 | AD285: =IF(ISNUMBER(T283),AVERAGE(T283:T285),NA()) -> 0.21352463 | AE285: =IF(ISNUMBER(U283),AVERAGE(U283:U285),NA()) -> 0.013977918 | AF285: =IF(ISNUMBER(V283),AVERAGE(V283:V285),NA()) -> 0.027070605 | AG285: =IF(ISNUMBER(W283),AVERAGE(W283:W285),NA()) -> 0.030375389 | AH285: =IF(ISNUMBER(X283),AVERAGE(X283:X285),NA()) -> 0.042642972 | AI285: =AVERAGE(J283:J285) -> 144080.33 | AJ285: =AVERAGE(I283:I285) -> 89793.333 | AK285: =AVERAGE(K283:K285) -> 11683.667
A286: 41487 | B286: 41487 | C286: 2243 | D286: 2658 | E286: 2007 | F286: 4068 | G286: 2652 | H286: 3711 | I286: 90473 | J286: 144170 | K286: 11316 | M286: =J286+K286 -> 155486 | P286: =K286/M286 -> 0.072778257 | Q286: =I286/M286 -> 0.58187232 | R286: =IF(ISNUMBER(L286),L286/M286,NA()) -> #N/A | S286: =IF(ISNUMBER(C286),C286/$K285,NA()) -> 0.19480632 | T286: =IF(ISNUMBER(D286),D286/$K285,NA()) -> 0.2308494 | U286: =IF(ISNUMBER(E286),E286/$J285,NA()) -> 0.01390997 | V286: =IF(ISNUMBER(F286),F286/$J285,NA()) -> 0.028194199 | W286: =IF(ISNUMBER(G286),G286/$I285,NA()) -> 0.029480424 | X286: =IF(ISNUMBER(H286),H286/$I286,NA()) -> 0.041017762 | Y286: =B286 -> 41487 | Z286: =IF(ISNUMBER(P284),AVERAGE(P284:P286),NA()) -> 0.074084898 | AA286: =IF(ISNUMBER(Q284),AVERAGE(Q284:Q286),NA()) -> 0.57832934 | AB286: =IF(ISNUMBER(R284),AVERAGE(R284:R286),NA()) -> #N/A | AC286: =IF(ISNUMBER(S284),AVERAGE(S284:S286),NA()) -> 0.1971244 | AD286: =IF(ISNUMBER(T284),AVERAGE(T284:T286),NA()) -> 0.22140047 | AE286: =IF(ISNUMBER(U284),AVERAGE(U284:U286),NA()) -> 0.014061913 | AF286: =IF(ISNUMBER(V284),AVERAGE(V284:V286),NA()) -> 0.027588543 | AG286: =IF(ISNUMBER(W284),AVERAGE(W284:W286),NA()) -> 0.029909807 | AH286: =IF(ISNUMBER(X284),AVERAGE(X284:X286),NA()) -> 0.042172906 | AI286: =AVERAGE(J284:J286) -> 144171 | AJ286: =AVERAGE(I284:I286) -> 90049.333 | AK286: =AVERAGE(K284:K286) -> 11535.667

Sheet Raw data -- quarterly
A1: 1 | B1: 2 | C1: 3 | D1: 4 | E1: 5 | F1: 6 | G1: 7 | H1: 8 | I1: 9 | J1: 10
A2: Quarter | B2: U/L | C2: N/L | D2: V/L | E2: uer | F2: unr | G2: eur | H2: enr | I2: nur | J2: ner
A3: =DATE(1990,3,1) -> 32933 | B3: =VLOOKUP($A3,'Raw data -- monthly'!$Y$3:$AH$286,'Raw data -- quarterly'!B$1,FALSE) -> 0.053004607 | C3: =VLOOKUP($A3,'Raw data -- monthly'!$Y$3:$AH$286,'Raw data -- quarterly'!C$1,FALSE) -> 0.49878923 | D3: =VLOOKUP($A3,'Raw data -- monthly'!$Y$3:$AH$286,'Raw data -- quarterly'!D$1,FALSE) -> #N/A | E3: =VLOOKUP($A3,'Raw data -- monthly'!$Y$3:$AH$286,'Raw data -- quarterly'!E$1,FALSE) -> #N/A | F3: =VLOOKUP($A3,'Raw data -- monthly'!$Y$3:$AH$286,'Raw data -- quarterly'!F$1,FALSE) -> #N/A | G3: =VLOOKUP($A3,'Raw data -- monthly'!$Y$3:$AH$286,'Raw data -- quarterly'!G$1,FALSE) -> #N/A | H3: =VLOOKUP($A3,'Raw data -- monthly'!$Y$3:$AH$286,'Raw data -- quarterly'!H$1,FALSE) -> #N/A | I3: =VLOOKUP($A3,'Raw data -- monthly'!$Y$3:$AH$286,'Raw data -- quarterly'!I$1,FALSE) -> #N/A | J3: =VLOOKUP($A3,'Raw data -- monthly'!$Y$3:$AH$286,'Raw data -- quarterly'!J$1,FALSE) -> #N/A
A4: =DATE(YEAR(A3),MONTH(A3)+3,1) -> 33025 | B4: =VLOOKUP($A4,'Raw data -- monthly'!$Y$3:$AH$286,'Raw data -- quarterly'!B$1,FALSE) -> 0.053375996 | C4: =VLOOKUP($A4,'Raw data -- monthly'!$Y$3:$AH$286,'Raw data -- quarterly'!C$1,FALSE) -> 0.50285658 | D4: =VLOOKUP($A4,'Raw data -- monthly'!$Y$3:$AH$286,'Raw data -- quarterly'!D$1,FALSE) -> #N/A | E4: =VLOOKUP($A4,'Raw data -- monthly'!$Y$3:$AH$286,'Raw data -- quarterly'!E$1,FALSE) -> 0.28184916 | F4: =VLOOKUP($A4,'Raw data -- monthly'!$Y$3:$AH$286,'Raw data -- quarterly'!F$1,FALSE) -> 0.20368828 | G4: =VLOOKUP($A4,'Raw data -- monthly'!$Y$3:$AH$286,'Raw data -- quarterly'!G$1,FALSE) -> 0.014892585 | H4: =VLOOKUP($A4,'Raw data -- monthly'!$Y$3:$AH$286,'Raw data -- quarterly'!H$1,FALSE) -> 0.028018612 | I4: =VLOOKUP($A4,'Raw data -- monthly'!$Y$3:$AH$286,'Raw data -- quarterly'!I$1,FALSE) -> 0.023214891 | J4: =VLOOKUP($A4,'Raw data -- monthly'!$Y$3:$AH$286,'Raw data -- quarterly'!J$1,FALSE) -> 0.048797701
A5: =DATE(YEAR(A4),MONTH(A4)+3,1) -> 33117 | B5: =VLOOKUP($A5,'Raw data -- monthly'!$Y$3:$AH$286,'Raw data -- quarterly'!B$1,FALSE) -> 0.05687737 | C5: =VLOOKUP($A5,'Raw data -- monthly'!$Y$3:$AH$286,'Raw data -- quarterly'!C$1,FALSE) -> 0.50433566 | D5: =VLOOKUP($A5,'Raw data -- monthly'!$Y$3:$AH$286,'Raw data -- quarterly'!D$1,FALSE) -> #N/A | E5: =VLOOKUP($A5,'Raw data -- monthly'!$Y$3:$AH$286,'Raw data -- quarterly'!E$1,FALSE) -> 0.26718246 | F5: =VLOOKUP($A5,'Raw data -- monthly'!$Y$3:$AH$286,'Raw data -- quarterly'!F$1,FALSE) -> 0.19951282 | G5: =VLOOKUP($A5,'Raw data -- monthly'!$Y$3:$AH$286,'Raw data -- quarterly'!G$1,FALSE) -> 0.015619605 | H5: =VLOOKUP($A5,'Raw data -- monthly'!$Y$3:$AH$286,'Raw data -- quarterly'!H$1,FALSE) -> 0.027367035 | I5: =VLOOKUP($A5,'Raw data -- monthly'!$Y$3:$AH$286,'Raw data -- quarterly'!I$1,FALSE) -> 0.025134707 | J5: =VLOOKUP($A5,'Raw data -- monthly'!$Y$3:$AH$286,'Raw data -- quarterly'!J$1,FALSE) -> 0.047935818
A6: =DATE(YEAR(A5),MONTH(A5)+3,1) -> 33208 | B6: =VLOOKUP($A6,'Raw data -- monthly'!$Y$3:$AH$286,'Raw data -- quarterly'!B$1,FALSE) -> 0.061140452 | C6: =VLOOKUP($A6,'Raw data -- monthly'!$Y$3:$AH$286,'Raw data -- quarterly'!C$1,FALSE) -> 0.50605079 | D6: =VLOOKUP($A6,'Raw data -- monthly'!$Y$3:$AH$286,'Raw data -- quarterly'!D$1,FALSE) -> #N/A | E6: =VLOOKUP($A6,'Raw data -- monthly'!$Y$3:$AH$286,'Raw data -- quarterly'!E$1,FALSE) -> 0.26433147 | F6: =VLOOKUP($A6,'Raw data -- monthly'!$Y$3:$AH$286,'Raw data -- quarterly'!F$1,FALSE) -> 0.19291766 | G6: =VLOOKUP($A6,'Raw data -- monthly'!$Y$3:$AH$286,'Raw data -- quarterly'!G$1,FALSE) -> 0.016349002 | H6: =VLOOKUP($A6,'Raw data -- monthly'!$Y$3:$AH$286,'Raw data -- quarterly'!H$1,FALSE) -> 0.027377111 | I6: =VLOOKUP($A6,'Raw data -- monthly'!$Y$3:$AH$286,'Raw data -- quarterly'!I$1,FALSE) -> 0.026015304 | J6: =VLOOKUP($A6,'Raw data -- monthly'!$Y$3:$AH$286,'Raw data -- quarterly'!J$1,FALSE) -> 0.04747372
A7: =DATE(YEAR(A6),MONTH(A6)+3,1) -> 33298 | B7: =VLOOKUP($A7,'Raw data -- monthly'!$Y$3:$AH$286,'Raw data -- quarterly'!B$1,FALSE) -> 0.06574435 | C7: =VLOOKUP($A7,'Raw data -- monthly'!$Y$3:$AH$286,'Raw data -- quarterly'!C$1,FALSE) -> 0.50924289 | D7: =VLOOKUP($A7,'Raw data -- monthly'!$Y$3:$AH$286,'Raw data -- quarterly'!D$1,FALSE) -> #N/A | E7: =VLOOKUP($A7,'Raw data -- monthly'!$Y$3:$AH$286,'Raw data -- quarterly'!E$1,FALSE) -> 0.25434973 | F7: =VLOOKUP($A7,'Raw data -- monthly'!$Y$3:$AH$286,'Raw data -- quarterly'!F$1,FALSE) -> 0.19093996 | G7: =VLOOKUP($A7,'Raw data -- monthly'!$Y$3:$AH$286,'Raw data -- quarterly'!G$1,FALSE) -> 0.017495651 | H7: =VLOOKUP($A7,'Raw data -- monthly'!$Y$3:$AH$286,'Raw data -- quarterly'!H$1,FALSE) -> 0.026390825 | I7: =VLOOKUP($A7,'Raw data -- monthly'!$Y$3:$AH$286,'Raw data -- quarterly'!I$1,FALSE) -> 0.026983475 | J7: =VLOOKUP($A7,'Raw data -- monthly'!$Y$3:$AH$286,'Raw data -- quarterly'!J$1,FALSE) -> 0.045041686
A8: =DATE(YEAR(A7),MONTH(A7)+3,1) -> 33390 | B8: =VLOOKUP($A8,'Raw data -- monthly'!$Y$3:$AH$286,'Raw data -- quarterly'!B$1,FALSE) -> 0.068242054 | C8: =VLOOKUP($A8,'Raw data -- monthly'!$Y$3:$AH$286,'Raw data -- quarterly'!C$1,FALSE) -> 0.50893159 | D8: =VLOOKUP($A8,'Raw data -- monthly'!$Y$3:$AH$286,'Raw data -- quarterly'!D$1,FALSE) -> #N/A | E8: =VLOOKUP($A8,'Raw data -- monthly'!$Y$3:$AH$286,'Raw data -- quarterly'!E$1,FALSE) -> 0.25295888 | F8: =VLOOKUP($A8,'Raw data -- monthly'!$Y$3:$AH$286,'Raw data -- quarterly'!F$1,FALSE) -> 0.18318264 | G8: =VLOOKUP($A8,'Raw data -- monthly'!$Y$3:$AH$286,'Raw data -- quarterly'!G$1,FALSE) -> 0.016821954 | H8: =VLOOKUP($A8,'Raw data -- monthly'!$Y$3:$AH$286,'Raw data -- quarterly'!H$1,FALSE) -> 0.026849627 | I8: =VLOOKUP($A8,'Raw data -- monthly'!$Y$3:$AH$286,'Raw data -- quarterly'!I$1,FALSE) -> 0.027664493 | J8: =VLOOKUP($A8,'Raw data -- monthly'!$Y$3:$AH$286,'Raw data -- quarterly'!J$1,FALSE) -> 0.045107043
A9: =DATE(YEAR(A8),MONTH(A8)+3,1) -> 33482 | B9: =VLOOKUP($A9,'Raw data -- monthly'!$Y$3:$AH$286,'Raw data -- quarterly'!B$1,FALSE) -> 0.068540875 | C9: =VLOOKUP($A9,'Raw data -- monthly'!$Y$3:$AH$286,'Raw data -- quarterly'!C$1,FALSE) -> 0.51302076 | D9: =VLOOKUP($A9,'Raw data -- monthly'!$Y$3:$AH$286,'Raw data -- quarterly'!D$1,FALSE) -> #N/A | E9: =VLOOKUP($A9,'Raw data -- monthly'!$Y$3:$AH$286,'Raw data -- quarterly'!E$1,FALSE) -> 0.24870609 | F9: =VLOOKUP($A9,'Raw data -- monthly'!$Y$3:$AH$286,'Raw data -- quarterly'!F$1,FALSE) -> 0.18743829 | G9: =VLOOKUP($A9,'Raw data -- monthly'!$Y$3:$AH$286,'Raw data -- quarterly'!G$1,FALSE) -> 0.016867474 | H9: =VLOOKUP($A9,'Raw data -- monthly'!$Y$3:$AH$286,'Raw data -- quarterly'!H$1,FALSE) -> 0.02607345 | I9: =VLOOKUP($A9,'Raw data -- monthly'!$Y$3:$AH$286,'Raw data -- quarterly'!I$1,FALSE) -> 0.027421862 | J9: =VLOOKUP($A9,'Raw data -- monthly'!$Y$3:$AH$286,'Raw data -- quarterly'!J$1,FALSE) -> 0.045298374
A10: =DATE(YEAR(A9),MONTH(A9)+3,1) -> 33573 | B10: =VLOOKUP($A10,'Raw data -- monthly'!$Y$3:$AH$286,'Raw data -- quarterly'!B$1,FALSE) -> 0.070974989 | C10: =VLOOKUP($A10,'Raw data -- monthly'!$Y$3:$AH$286,'Raw data -- quarterly'!C$1,FALSE) -> 0.51300369 | D10: =VLOOKUP($A10,'Raw data -- monthly'!$Y$3:$AH$286,'Raw data -- quarterly'!D$1,FALSE) -> #N/A | E10: =VLOOKUP($A10,'Raw data -- monthly'!$Y$3:$AH$286,'Raw data -- quarterly'!E$1,FALSE) -> 0.23293136 | F10: =VLOOKUP($A10,'Raw data -- monthly'!$Y$3:$AH$286,'Raw data -- quarterly'!F$1,FALSE) -> 0.18658574 | G10: =VLOOKUP($A10,'Raw data -- monthly'!$Y$3:$AH$286,'Raw data -- quarterly'!G$1,FALSE) -> 0.016772246 | H10: =VLOOKUP($A10,'Raw data -- monthly'!$Y$3:$AH$286,'Raw data -- quarterly'!H$1,FALSE) -> 0.025734062 | I10: =VLOOKUP($A10,'Raw data -- monthly'!$Y$3:$AH$286,'Raw data -- quarterly'!I$1,FALSE) -> 0.028735359 | J10: =VLOOKUP($A10,'Raw data -- monthly'!$Y$3:$AH$286,'Raw data -- quarterly'!J$1,FALSE) -> 0.042008425
A11: =DATE(YEAR(A10),MONTH(A10)+3,1) -> 33664 | B11: =VLOOKUP($A11,'Raw data -- monthly'!$Y$3:$AH$286,'Raw data -- quarterly'!B$1,FALSE) -> 0.073799998 | C11: =VLOOKUP($A11,'Raw data -- monthly'!$Y$3:$AH$286,'Raw data -- quarterly'!C$1,FALSE) -> 0.50815748 | D11: =VLOOKUP($A11,'Raw data -- monthly'!$Y$3:$AH$286,'Raw data -- quarterly'!D$1,FALSE) -> #N/A | E11: =VLOOKUP($A11,'Raw data -- monthly'!$Y$3:$AH$286,'Raw data -- quarterly'!E$1,FALSE) -> 0.23591936 | F11: =VLOOKUP($A11,'Raw data -- monthly'!$Y$3:$AH$286,'Raw data -- quarterly'!F$1,FALSE) -> 0.17115794 | G11: =VLOOKUP($A11,'Raw data -- monthly'!$Y$3:$AH$286,'Raw data -- quarterly'!G$1,FALSE) -> 0.016869696 | H11: =VLOOKUP($A11,'Raw data -- monthly'!$Y$3:$AH$286,'Raw data -- quarterly'!H$1,FALSE) -> 0.025087794 | I11: =VLOOKUP($A11,'Raw data -- monthly'!$Y$3:$AH$286,'Raw data -- quarterly'!I$1,FALSE) -> 0.028801533 | J11: =VLOOKUP($A11,'Raw data -- monthly'!$Y$3:$AH$286,'Raw data -- quarterly'!J$1,FALSE) -> 0.045132555
A12: =DATE(YEAR(A11),MONTH(A11)+3,1) -> 33756 | B12: =VLOOKUP($A12,'Raw data -- monthly'!$Y$3:$AH$286,'Raw data -- quarterly'!B$1,FALSE) -> 0.075952565 | C12: =VLOOKUP($A12,'Raw data -- monthly'!$Y$3:$AH$286,'Raw data -- quarterly'!C$1,FALSE) -> 0.50232299 | D12: =VLOOKUP($A12,'Raw data -- monthly'!$Y$3:$AH$286,'Raw data -- quarterly'!D$1,FALSE) -> #N/A | E12: =VLOOKUP($A12,'Raw data -- monthly'!$Y$3:$AH$286,'Raw data -- quarterly'!E$1,FALSE) -> 0.22920055 | F12: =VLOOKUP($A12,'Raw data -- monthly'!$Y$3:$AH$286,'Raw data -- quarterly'!F$1,FALSE) -> 0.17478451 | G12: =VLOOKUP($A12,'Raw data -- monthly'!$Y$3:$AH$286,'Raw data -- quarterly'!G$1,FALSE) -> 0.016903544 | H12: =VLOOKUP($A12,'Raw data -- monthly'!$Y$3:$AH$286,'Raw data -- quarterly'!H$1,FALSE) -> 0.025391767 | I12: =VLOOKUP($A12,'Raw data -- monthly'!$Y$3:$AH$286,'Raw data -- quarterly'!I$1,FALSE) -> 0.031205702 | J12: =VLOOKUP($A12,'Raw data -- monthly'!$Y$3:$AH$286,'Raw data -- quarterly'!J$1,FALSE) -> 0.044266583
A13: =DATE(YEAR(A12),MONTH(A12)+3,1) -> 33848 | B13: =VLOOKUP($A13,'Raw data -- monthly'!$Y$3:$AH$286,'Raw data -- quarterly'!B$1,FALSE) -> 0.07627626 | C13: =VLOOKUP($A13,'Raw data -- monthly'!$Y$3:$AH$286,'Raw data -- quarterly'!C$1,FALSE) -> 0.50144596 | D13: =VLOOKUP($A13,'Raw data -- monthly'!$Y$3:$AH$286,'Raw data -- quarterly'!D$1,FALSE) -> #N/A | E13: =VLOOKUP($A13,'Raw data -- monthly'!$Y$3:$AH$286,'Raw data -- quarterly'!E$1,FALSE) -> 0.22676415 | F13: =VLOOKUP($A13,'Raw data -- monthly'!$Y$3:$AH$286,'Raw data -- quarterly'!F$1,FALSE) -> 0.18070404 | G13: =VLOOKUP($A13,'Raw data -- monthly'!$Y$3:$AH$286,'Raw data -- quarterly'!G$1,FALSE) -> 0.016790724 | H13: =VLOOKUP($A13,'Raw data -- monthly'!$Y$3:$AH$286,'Raw data -- quarterly'!H$1,FALSE) -> 0.025858938 | I13: =VLOOKUP($A13,'Raw data -- monthly'!$Y$3:$AH$286,'Raw data -- quarterly'!I$1,FALSE) -> 0.02991641 | J13: =VLOOKUP($A13,'Raw data -- monthly'!$Y$3:$AH$286,'Raw data -- quarterly'!J$1,FALSE) -> 0.044202952
A14: =DATE(YEAR(A13),MONTH(A13)+3,1) -> 33939 | B14: =VLOOKUP($A14,'Raw data -- monthly'!$Y$3:$AH$286,'Raw data -- quarterly'!B$1,FALSE) -> 0.074073085 | C14: =VLOOKUP($A14,'Raw data -- monthly'!$Y$3:$AH$286,'Raw data -- quarterly'!C$1,FALSE) -> 0.5086141 | D14: =VLOOKUP($A14,'Raw data -- monthly'!$Y$3:$AH$286,'Raw data -- quarterly'!D$1,FALSE) -> #N/A | E14: =VLOOKUP($A14,'Raw data -- monthly'!$Y$3:$AH$286,'Raw data -- quarterly'!E$1,FALSE) -> 0.23533787 | F14: =VLOOKUP($A14,'Raw data -- monthly'!$Y$3:$AH$286,'Raw data -- quarterly'!F$1,FALSE) -> 0.18530872 | G14: =VLOOKUP($A14,'Raw data -- monthly'!$Y$3:$AH$286,'Raw data -- quarterly'!G$1,FALSE) -> 0.016663569 | H14: =VLOOKUP($A14,'Raw data -- monthly'!$Y$3:$AH$286,'Raw data -- quarterly'!H$1,FALSE) -> 0.026570298 | I14: =VLOOKUP($A14,'Raw data -- monthly'!$Y$3:$AH$286,'Raw data -- quarterly'!I$1,FALSE) -> 0.030099485 | J14: =VLOOKUP($A14,'Raw data -- monthly'!$Y$3:$AH$286,'Raw data -- quarterly'!J$1,FALSE) -> 0.044214178
A15: =DATE(YEAR(A14),MONTH(A14)+3,1) -> 34029 | B15: =VLOOKUP($A15,'Raw data -- monthly'!$Y$3:$AH$286,'Raw data -- quarterly'!B$1,FALSE) -> 0.071510671 | C15: =VLOOKUP($A15,'Raw data -- monthly'!$Y$3:$AH$286,'Raw data -- quarterly'!C$1,FALSE) -> 0.51072502 | D15: =VLOOKUP($A15,'Raw data -- monthly'!$Y$3:$AH$286,'Raw data -- quarterly'!D$1,FALSE) -> #N/A | E15: =VLOOKUP($A15,'Raw data -- monthly'!$Y$3:$AH$286,'Raw data -- quarterly'!E$1,FALSE) -> 0.23034156 | F15: =VLOOKUP($A15,'Raw data -- monthly'!$Y$3:$AH$286,'Raw data -- quarterly'!F$1,FALSE) -> 0.18978993 | G15: =VLOOKUP($A15,'Raw data -- monthly'!$Y$3:$AH$286,'Raw data -- quarterly'!G$1,FALSE) -> 0.015813438 | H15: =VLOOKUP($A15,'Raw data -- monthly'!$Y$3:$AH$286,'Raw data -- quarterly'!H$1,FALSE) -> 0.026526595 | I15: =VLOOKUP($A15,'Raw data -- monthly'!$Y$3:$AH$286,'Raw data -- quarterly'!I$1,FALSE) -> 0.028339427 | J15: =VLOOKUP($A15,'Raw data -- monthly'!$Y$3:$AH$286,'Raw data -- quarterly'!J$1,FALSE) -> 0.04584845
... A97: =DATE(YEAR(A96),MONTH(A96)+3,1) -> 41518 | B97: =VLOOKUP($A97,'Raw data -- monthly'!$Y$3:$AH$286,'Raw data -- quarterly'!B$1,FALSE) -> #N/A | C97: =VLOOKUP($A97,'Raw data -- monthly'!$Y$3:$AH$286,'Raw data -- quarterly'!C$1,FALSE) -> #N/A | D97: =VLOOKUP($A97,'Raw data -- monthly'!$Y$3:$AH$286,'Raw data -- quarterly'!D$1,FALSE) -> #N/A | E97: =VLOOKUP($A97,'Raw data -- monthly'!$Y$3:$AH$286,'Raw data -- quarterly'!E$1,FALSE) -> #N/A | F97: =VLOOKUP($A97,'Raw data -- monthly'!$Y$3:$AH$286,'Raw data -- quarterly'!F$1,FALSE) -> #N/A | G97: =VLOOKUP($A97,'Raw data -- monthly'!$Y$3:$AH$286,'Raw data -- quarterly'!G$1,FALSE) -> #N/A | H97: =VLOOKUP($A97,'Raw data -- monthly'!$Y$3:$AH$286,'Raw data -- quarterly'!H$1,FALSE) -> #N/A | I97: =VLOOKUP($A97,'Raw data -- monthly'!$Y$3:$AH$286,'Raw data -- quarterly'!I$1,FALSE) -> #N/A | J97: =VLOOKUP($A97,'Raw data -- monthly'!$Y$3:$AH$286,'Raw data -- quarterly'!J$1,FALSE) -> #N/A

Sheet Decomposition 1
B1: epsilon_f_theta | C1: f | D1: PI_UN | E1: Pi_NE | F1: PI_NU | G1: Lambda | H1: PI_EN | I1: PI_NE+PI_NU | J1: ξ (left axis) | K1: ϵ (right axis) | L1: w_lambda | M1: w_f | N1: w_eps | O1: w_xi | P1: w_nu
A2: ='Raw data -- quarterly'!A46 -> 36861 | B2: 0.5 | C2: ='Raw data -- quarterly'!E46 -> 0.31507463 | D2: ='Raw data -- quarterly'!F46 -> 0.22679976 | E2: ='Raw data -- quarterly'!J46 -> 0.053293856 | F2: ='Raw data -- quarterly'!I46 -> 0.021607097 | G2: ='Raw data -- quarterly'!G46 -> 0.010856039 | H2: ='Raw data -- quarterly'!H46 -> 0.028133292 | I2: =F2+E2 -> 0.074900952 | J2: =D2*E2/I2 -> 0.16137356 | K2: =H2*F2/I2 -> 0.008115768 | L2: =G2/(G2+K2) -> 0.57221957 | M2: =C2/(C2+J2) -> 0.66129882 | N2: =1-L2 -> 0.42778043 | O2: =1-M2 -> 0.33870118 | P2: =F2/I2 -> 0.28847559
A3: ='Raw data -- quarterly'!A47 -> 36951 | B3: 0.5 | C3: ='Raw data -- quarterly'!E47 -> 0.31045817 | D3: ='Raw data -- quarterly'!F47 -> 0.23481312 | E3: ='Raw data -- quarterly'!J47 -> 0.055270961 | F3: ='Raw data -- quarterly'!I47 -> 0.023028987 | G3: ='Raw data -- quarterly'!G47 -> 0.012757829 | H3: ='Raw data -- quarterly'!H47 -> 0.028812699 | I3: =F3+E3 -> 0.078299948 | J3: =D3*E3/I3 -> 0.16575167 | K3: =H3*F3/I3 -> 0.0084741724 | L3: =G3/(G3+K3) -> 0.60087737 | M3: =C3/(C3+J3) -> 0.65193565 | N3: =1-L3 -> 0.39912263 | O3: =1-M3 -> 0.34806435 | P3: =F3/I3 -> 0.29411242
A4: ='Raw data -- quarterly'!A48 -> 37043 | B4: 0.5 | C4: ='Raw data -- quarterly'!E48 -> 0.31128255 | D4: ='Raw data -- quarterly'!F48 -> 0.2380217 | E4: ='Raw data -- quarterly'!J48 -> 0.05106403 | F4: ='Raw data -- quarterly'!I48 -> 0.023403367 | G4: ='Raw data -- quarterly'!G48 -> 0.013378141 | H4: ='Raw data -- quarterly'!H48 -> 0.029874574 | I4: =F4+E4 -> 0.074467396 | J4: =D4*E4/I4 -> 0.16321703 | K4: =H4*F4/I4 -> 0.0093888821 | L4: =G4/(G4+K4) -> 0.58761047 | M4: =C4/(C4+J4) -> 0.65602282 | N4: =1-L4 -> 0.41238953 | O4: =1-M4 -> 0.34397718 | P4: =F4/I4 -> 0.31427669
A5: ='Raw data -- quarterly'!A49 -> 37135 | B5: 0.5 | C5: ='Raw data -- quarterly'!E49 -> 0.29427166 | D5: ='Raw data -- quarterly'!F49 -> 0.2218442 | E5: ='Raw data -- quarterly'!J49 -> 0.05476048 | F5: ='Raw data -- quarterly'!I49 -> 0.02498276 | G5: ='Raw data -- quarterly'!G49 -> 0.013656566 | H5: ='Raw data -- quarterly'!H49 -> 0.030201415 | I5: =F5+E5 -> 0.07974324 | J5: =D5*E5/I5 -> 0.15234263 | K5: =H5*F5/I5 -> 0.0094618017 | L5: =G5/(G5+K5) -> 0.59072363 | M5: =C5/(C5+J5) -> 0.65889441 | N5: =1-L5 -> 0.40927637 | O5: =1-M5 -> 0.34110559 | P5: =F5/I5 -> 0.31329001
A6: ='Raw data -- quarterly'!A50 -> 37226 | B6: 0.5 | C6: ='Raw data -- quarterly'!E50 -> 0.26994934 | D6: ='Raw data -- quarterly'!F50 -> 0.2132337 | E6: ='Raw data -- quarterly'!J50 -> 0.048440996 | F6: ='Raw data -- quarterly'!I50 -> 0.027589629 | G6: ='Raw data -- quarterly'!G50 -> 0.014945957 | H6: ='Raw data -- quarterly'!H50 -> 0.028064901 | I6: =F6+E6 -> 0.076030625 | J6: =D6*E6/I6 -> 0.13585647 | K6: =H6*F6/I6 -> 0.010184057 | L6: =G6/(G6+K6) -> 0.59474527 | M6: =C6/(C6+J6) -> 0.66521802 | N6: =1-L6 -> 0.40525473 | O6: =1-M6 -> 0.33478198 | P6: =F6/I6 -> 0.36287521
A7: ='Raw data -- quarterly'!A51 -> 37316 | B7: 0.5 | C7: ='Raw data -- quarterly'!E51 -> 0.26919959 | D7: ='Raw data -- quarterly'!F51 -> 0.20515859 | E7: ='Raw data -- quarterly'!J51 -> 0.049245694 | F7: ='Raw data -- quarterly'!I51 -> 0.026440812 | G7: ='Raw data -- quarterly'!G51 -> 0.014611551 | H7: ='Raw data -- quarterly'!H51 -> 0.027699441 | I7: =F7+E7 -> 0.075686506 | J7: =D7*E7/I7 -> 0.13348717 | K7: =H7*F7/I7 -> 0.009676701 | L7: =G7/(G7+K7) -> 0.60158923 | M7: =C7/(C7+J7) -> 0.66850867 | N7: =1-L7 -> 0.39841077 | O7: =1-M7 -> 0.33149133 | P7: =F7/I7 -> 0.34934644
