Workbook
Name X12Dates_1: Calculations!$A$2:$A$235
Name X12Dates_2: Calculations!$A$2:$A$235
Name X12Dates_3: Calculations!$A$2:$A$235
Name X12Header_1: Calculations!$E$1
Name X12Header_2: Calculations!$F$1
Name X12Header_3: Calculations!$G$1
Name X12NSA_1: Calculations!$B$2:$B$235
Name X12NSA_2: Calculations!$C$2:$C$235
Name X12NSA_3: Calculations!$D$2:$D$235

Sheet raw FF data
A1: The data presented here are measures of gross worker flows as
A2: described in Fallick, Bruce and Charles Fleischman,
A3: "Employer-to-Employer Flows in the U.S. Labor Market: The Complete
A4: Picture of Gross Worker Flows" FEDS #2004-34, updated to include more
A5: recent months.
A7: The data currently cover the period January 1994 to June 2013.
A8: Data for several months in 1995 are missing because the public use
A9: files of the CPS do not allow one to match individuals across those months.
A11: The series with suffix "pop" are flows as a percent of population.
A12: The series with suffix "haz" are flows as hazard rates.
A14: E = employment U = unemployment N = not in the labor force
A15: EE* refers to persons who move from one employer to another.
... A27: The means over the entire sample period are
A29: EEpop | B29: SEpop | C29: EUpop | D29: ENpop | E29: UEpop | F29: SUpop | G29: UNpop | H29: NEpop | I29: NUpop | J29: SNpop | K29: EEhaz | L29: SEhaz | M29: EUhaz | N29: ENhaz | O29: UEhaz | P29: SUhaz | Q29: UNhaz | R29: NEhaz | S29: NUhaz | T29: SNhaz
A30: 1.4 | B30: 58.4 | C30: 0.8 | D30: 1.6 | E30: 0.9 | F30: 2.1 | G30: 0.9 | H30: 1.5 | I30: 0.9 | J30: 31.5 | K30: 2.2 | L30: 93.8 | M30: 1.3 | N30: 2.6 | O30: 25.5 | P30: 51.7 | Q30: 22.8 | R30: 4.5 | S30: 2.5 | T30: 92.9
A32: Year:Mnth | B32: EEpop | C32: SEpop | D32: EUpop | E32: ENpop | F32: UEpop | G32: SUpop | H32: UNpop | I32: NEpop | J32: NUpop | K32: SNpop | L32: EEhaz | M32: SEhaz | N32: EUhaz | O32: ENhaz | P32: UEhaz | Q32: SUhaz | R32: UNhaz | S32: NEhaz | T32: NUhaz | U32: SNhaz
A33: 1994:01 | B33: 2.1 | C33: 57 | D33: 0.9 | E33: 1.5 | F33: 1.2 | G33: 2.6 | H33: 0.9 | I33: 1.6 | J33: 1 | K33: 31.1 | L33: 3.4 | M33: 92.8 | N33: 1.4 | O33: 2.4 | P33: 25.1 | Q33: 55.1 | R33: 19.8 | S33: 4.7 | T33: 3.1 | U33: 92.2
A34: 1994:02 | B34: 1.7 | C34: 57.5 | D34: 0.8 | E34: 1.4 | F34: 1.1 | G34: 2.3 | H34: 0.9 | I34: 1.5 | J34: 1 | K34: 31.8 | L34: 2.7 | M34: 93.8 | N34: 1.2 | O34: 2.2 | P34: 24.8 | Q34: 53.7 | R34: 21.5 | S34: 4.4 | T34: 3 | U34: 92.7
A35: 1994:03 | B35: 1.8 | C35: 57.4 | D35: 0.9 | E35: 1.4 | F35: 1.2 | G35: 2.1 | H35: 0.9 | I35: 1.4 | J35: 0.9 | K35: 31.9 | L35: 2.9 | M35: 93.4 | N35: 1.4 | O35: 2.3 | P35: 28.4 | Q35: 49.4 | R35: 22.1 | S35: 4.1 | T35: 2.7 | U35: 93.2
A36: 1994:04 | B36: 1.7 | C36: 57.8 | D36: 0.7 | E36: 1.5 | F36: 1.2 | G36: 2 | H36: 0.9 | I36: 1.6 | J36: 0.9 | K36: 31.6 | L36: 2.8 | M36: 93.6 | N36: 1.2 | O36: 2.4 | P36: 29.5 | Q36: 47.9 | R36: 22.6 | S36: 4.6 | T36: 2.8 | U36: 92.7
A37: 1994:05 | B37: 2.2 | C37: 57.5 | D37: 1.1 | E37: 1.7 | F37: 1 | G37: 1.7 | H37: 0.9 | I37: 2.1 | J37: 1.3 | K37: 30.6 | L37: 3.5 | M37: 92.1 | N37: 1.7 | O37: 2.7 | P37: 27.4 | Q37: 47.4 | R37: 25.2 | S37: 6.3 | T37: 3.7 | U37: 90
A38: 1994:06 | B38: 1.9 | C38: 58.8 | D38: 1 | E38: 1.6 | F38: 1.2 | G38: 1.9 | H38: 0.9 | I38: 1.6 | J38: 1 | K38: 30 | L38: 3 | M38: 92.8 | N38: 1.6 | O38: 2.6 | P38: 29.3 | Q38: 48.4 | R38: 22.3 | S38: 4.8 | T38: 3.2 | U38: 92
A39: 1994:07 | B39: 1.9 | C39: 58.6 | D39: 0.9 | E39: 1.9 | F39: 1.1 | G39: 2 | H39: 1 | I39: 1.5 | J39: 1 | K39: 30.2 | L39: 2.9 | M39: 92.7 | N39: 1.5 | O39: 2.9 | P39: 26.3 | Q39: 49.6 | R39: 24.2 | S39: 4.5 | T39: 3 | U39: 92.5
A40: 1994:08 | B40: 2.6 | C40: 57.1 | D40: 1 | E40: 2.5 | F40: 1.2 | G40: 1.7 | H40: 0.9 | I40: 1.7 | J40: 0.9 | K40: 30.4 | L40: 4.2 | M40: 90.3 | N40: 1.6 | O40: 4 | P40: 31.6 | Q40: 44.3 | R40: 24.1 | S40: 5.2 | T40: 2.7 | U40: 92.1
A41: 1994:09 | B41: 1.7 | C41: 59.2 | D41: 0.7 | E41: 1.4 | F41: 1 | G41: 1.8 | H41: 0.8 | I41: 1.5 | J41: 0.9 | K41: 31 | L41: 2.8 | M41: 93.9 | N41: 1 | O41: 2.3 | P41: 27.5 | Q41: 49.8 | R41: 22.8 | S41: 4.5 | T41: 2.7 | U41: 92.9
A42: 1994:10 | B42: 1.5 | C42: 59.6 | D42: 0.9 | E42: 1.4 | F42: 0.9 | G42: 1.7 | H42: 0.9 | I42: 1.4 | J42: 0.8 | K42: 31 | L42: 2.4 | M42: 94 | N42: 1.4 | O42: 2.3 | P42: 26.4 | Q42: 48.4 | R42: 25.1 | S42: 4.1 | T42: 2.4 | U42: 93.5
A43: 1994:11 | B43: 1.4 | C43: 59.4 | D43: 0.9 | E43: 1.5 | F43: 0.9 | G43: 1.7 | H43: 0.9 | I43: 1.3 | J43: 0.7 | K43: 31.2 | L43: 2.3 | M43: 94 | N43: 1.4 | O43: 2.3 | P43: 26.4 | Q43: 49 | R43: 24.7 | S43: 3.9 | T43: 2.2 | U43: 93.9
A44: 1994:12 | B44: 1.6 | C44: 58.5 | D44: 1.3 | E44: 1.8 | F44: 0.7 | G44: 1.7 | H44: 0.8 | I44: 1.4 | J44: 0.9 | K44: 31.2 | L44: 2.5 | M44: 92.6 | N44: 2 | O44: 2.8 | P44: 22.2 | Q44: 52.3 | R44: 25.5 | S44: 4.2 | T44: 2.7 | U44: 93.1
... A48: 1995:04 | B48: 1.6 | C48: 58.9 | D48: 0.7 | E48: 1.6 | F48: 1 | G48: 1.8 | H48: 0.8 | I48: 1.3 | J48: 0.9 | K48: 31.4 | L48: 2.5 | M48: 93.8 | N48: 1.2 | O48: 2.5 | P48: 28.1 | Q48: 48.8 | R48: 23.1 | S48: 3.8 | T48: 2.8 | U48: 93.4
A49: 1995:05 | B49: n.a. | C49: n.a. | D49: n.a. | E49: n.a. | F49: n.a. | G49: n.a. | H49: n.a. | I49: n.a. | J49: n.a. | K49: n.a. | L49: n.a. | M49: n.a. | N49: n.a. | O49: n.a. | P49: n.a. | Q49: n.a. | R49: n.a. | S49: n.a. | T49: n.a. | U49: n.a.
A50: 1995:06 | B50: n.a. | C50: n.a. | D50: n.a. | E50: n.a. | F50: n.a. | G50: n.a. | H50: n.a. | I50: n.a. | J50: n.a. | K50: n.a. | L50: n.a. | M50: n.a. | N50: n.a. | O50: n.a. | P50: n.a. | Q50: n.a. | R50: n.a. | S50: n.a. | T50: n.a. | U50: n.a.
A51: 1995:07 | B51: n.a. | C51: n.a. | D51: n.a. | E51: n.a. | F51: n.a. | G51: n.a. | H51: n.a. | I51: n.a. | J51: n.a. | K51: n.a. | L51: n.a. | M51: n.a. | N51: n.a. | O51: n.a. | P51: n.a. | Q51: n.a. | R51: n.a. | S51: n.a. | T51: n.a. | U51: n.a.
A52: 1995:08 | B52: n.a. | C52: n.a. | D52: n.a. | E52: n.a. | F52: n.a. | G52: n.a. | H52: n.a. | I52: n.a. | J52: n.a. | K52: n.a. | L52: n.a. | M52: n.a. | N52: n.a. | O52: n.a. | P52: n.a. | Q52: n.a. | R52: n.a. | S52: n.a. | T52: n.a. | U52: n.a.
A53: 1995:09 | B53: 1.8 | C53: 59 | D53: 0.8 | E53: 1.5 | F53: 1 | G53: 1.6 | H53: 0.8 | I53: 1.7 | J53: 0.9 | K53: 31 | L53: 2.8 | M53: 93.6 | N53: 1.3 | O53: 2.3 | P53: 29.7 | Q53: 46.1 | R53: 24.3 | S53: 4.9 | T53: 2.6 | U53: 92.4
A54: 1995:10 | B54: 1.9 | C54: 58.8 | D54: 0.9 | E54: 1.6 | F54: 1 | G54: 1.6 | H54: 0.8 | I54: 1.4 | J54: 0.8 | K54: 31.2 | L54: 3.1 | M54: 93 | N54: 1.4 | O54: 2.5 | P54: 28.9 | Q54: 47.8 | R54: 23.3 | S54: 4.3 | T54: 2.4 | U54: 93.3
A55: 1995:11 | B55: 1.3 | C55: 59.6 | D55: 0.7 | E55: 1.3 | F55: 0.8 | G55: 1.9 | H55: 0.9 | I55: 1.1 | J55: 0.8 | K55: 31.7 | L55: 2 | M55: 94.8 | N55: 1.1 | O55: 2.1 | P55: 22.2 | Q55: 53.2 | R55: 24.6 | S55: 3.4 | T55: 2.3 | U55: 94.3
A56: 1995:12 | B56: 1.6 | C56: 58.3 | D56: 1.2 | E56: 1.7 | F56: 0.7 | G56: 1.8 | H56: 0.8 | I56: 1.2 | J56: 0.9 | K56: 31.8 | L56: 2.5 | M56: 92.8 | N56: 1.9 | O56: 2.8 | P56: 22.7 | Q56: 54.1 | R56: 23.2 | S56: 3.5 | T56: 2.6 | U56: 93.8
A57: 1996:01 | B57: 1.6 | C57: 57.9 | D57: 0.9 | E57: 1.5 | F57: 1.2 | G57: 2 | H57: 0.9 | I57: 1.5 | J57: 0.9 | K57: 31.7 | L57: 2.5 | M57: 93.6 | N57: 1.4 | O57: 2.4 | P57: 29.1 | Q57: 49 | R57: 21.9 | S57: 4.4 | T57: 2.6 | U57: 93
A58: 1996:02 | B58: 1.6 | C58: 58.6 | D58: 0.8 | E58: 1.3 | F58: 1 | G58: 2 | H58: 0.9 | I58: 1.4 | J58: 1 | K58: 31.5 | L58: 2.5 | M58: 94.1 | N58: 1.3 | O58: 2.1 | P58: 25.5 | Q58: 51.8 | R58: 22.7 | S58: 4.1 | T58: 2.8 | U58: 93.1
A59: 1996:03 | B59: 1.4 | C59: 59 | D59: 0.8 | E59: 1.3 | F59: 1 | G59: 2 | H59: 0.8 | I59: 1.2 | J59: 0.8 | K59: 31.8 | L59: 2.2 | M59: 94.5 | N59: 1.2 | O59: 2.1 | P59: 25.2 | Q59: 52.8 | R59: 22 | S59: 3.6 | T59: 2.3 | U59: 94.2
...

Sheet raw BLS data
A1: Data extracted on: September 24, 2013 (10:31:41 AM) | G1: Data extracted on: September 24, 2013 (10:34:54 AM) | N1: Data extracted on: September 25, 2013 (4:11:58 AM) | T1: Data extracted on: September 25, 2013 (4:13:15 AM)
A3: Job Openings and Labor Turnover Survey | G3: Labor Force Statistics from the Current Population Survey | N3: Job Openings and Labor Turnover Survey | T3: Labor Force Statistics from the Current Population Survey
A8: Series Id: JTS00000000QUR (4) | G8: Series Id: LNS14000000 | N8: Series Id: JTS00000000JOL | T8: Series Id: LNS11000000
A9: Seasonally adjusted | G9: Seasonally Adjusted | N9: Seasonally adjusted | T9: Seasonally Adjusted
A10: Industry: Total nonfarm | G10: Series title: (Seas) Unemployment Rate | N10: Industry: Total nonfarm | T10: Series title: (Seas) Civilian Labor Force Level
A11: Region: Total US | G11: Labor force status: Unemployment rate | N11: Region: Total US | T11: Labor force status: Civilian labor force
A12: Data Element: Quits | G12: Type of data: Percent or rate | N12: Data Element: Job openings | T12: Type of data: Number in thousands
A13: Rate/Level: Rate | G13: Age: 16 years and over | N13: Rate/Level: Level - In Thousands | T13: Age: 16 years and over
A16: Download: | G16: Download: | N16: Download: | T16: Download:
A18: Series Id | B18: Year | C18: Period | D18: Value | G18: Series id | H18: Year | I18: Period | J18: Value | N18: Series Id | O18: Year | P18: Period | Q18: Value | T18: Series id | U18: Year | V18: Period | W18: Value
A19: JTS00000000QUR | B19: 2000 | C19: M12 | D19: 2.3 | G19: LNS14000000 | H19: 1994 | I19: M01 | J19: 6.6 | N19: JTS00000000JOL | O19: 2000 | P19: M12 | Q19: 5191 | T19: LNS11000000 | U19: 2000 | V19: M01 | W19: 142267
A20: JTS00000000QUR | B20: 2001 | C20: M01 | D20: 2.5 | G20: LNS14000000 | H20: 1994 | I20: M02 | J20: 6.6 | N20: JTS00000000JOL | O20: 2001 | P20: M01 | Q20: 5186 | T20: LNS11000000 | U20: 2000 | V20: M02 | W20: 142456
A21: JTS00000000QUR | B21: 2001 | C21: M02 | D21: 2.5 | G21: LNS14000000 | H21: 1994 | I21: M03 | J21: 6.5 | N21: JTS00000000JOL | O21: 2001 | P21: M02 | Q21: 4702 | T21: LNS11000000 | U21: 2000 | V21: M03 | W21: 142434
A22: JTS00000000QUR | B22: 2001 | C22: M03 | D22: 2.4 | G22: LNS14000000 | H22: 1994 | I22: M04 | J22: 6.4 | N22: JTS00000000JOL | O22: 2001 | P22: M03 | Q22: 4774 | T22: LNS11000000 | U22: 2000 | V22: M04 | W22: 142751
A23: JTS00000000QUR | B23: 2001 | C23: M04 | D23: 2.4 | G23: LNS14000000 | H23: 1994 | I23: M05 | J23: 6.1 | N23: JTS00000000JOL | O23: 2001 | P23: M04 | Q23: 4653 | T23: LNS11000000 | U23: 2000 | V23: M05 | W23: 142388
A24: JTS00000000QUR | B24: 2001 | C24: M05 | D24: 2.3 | G24: LNS14000000 | H24: 1994 | I24: M06 | J24: 6.1 | N24: JTS00000000JOL | O24: 2001 | P24: M05 | Q24: 4452 | T24: LNS11000000 | U24: 2000 | V24: M06 | W24: 142591
A25: JTS00000000QUR | B25: 2001 | C25: M06 | D25: 2.2 | G25: LNS14000000 | H25: 1994 | I25: M07 | J25: 6.1 | N25: JTS00000000JOL | O25: 2001 | P25: M06 | Q25: 4337 | T25: LNS11000000 | U25: 2000 | V25: M07 | W25: 142278
A26: JTS00000000QUR | B26: 2001 | C26: M07 | D26: 2.2 | G26: LNS14000000 | H26: 1994 | I26: M08 | J26: 6 | N26: JTS00000000JOL | O26: 2001 | P26: M07 | Q26: 4231 | T26: LNS11000000 | U26: 2000 | V26: M08 | W26: 142514
A27: JTS00000000QUR | B27: 2001 | C27: M08 | D27: 2.2 | G27: LNS14000000 | H27: 1994 | I27: M09 | J27: 5.9 | N27: JTS00000000JOL | O27: 2001 | P27: M08 | Q27: 4139 | T27: LNS11000000 | U27: 2000 | V27: M09 | W27: 142518
A28: JTS00000000QUR | B28: 2001 | C28: M09 | D28: 2.1 | G28: LNS14000000 | H28: 1994 | I28: M10 | J28: 5.8 | N28: JTS00000000JOL | O28: 2001 | P28: M09 | Q28: 4006 | T28: LNS11000000 | U28: 2000 | V28: M10 | W28: 142622
A29: JTS00000000QUR | B29: 2001 | C29: M10 | D29: 2.2 | G29: LNS14000000 | H29: 1994 | I29: M11 | J29: 5.6 | N29: JTS00000000JOL | O29: 2001 | P29: M10 | Q29: 3583 | T29: LNS11000000 | U29: 2000 | V29: M11 | W29: 142962
A30: JTS00000000QUR | B30: 2001 | C30: M11 | D30: 2 | G30: LNS14000000 | H30: 1994 | I30: M12 | J30: 5.5 | N30: JTS00000000JOL | O30: 2001 | P30: M11 | Q30: 3538 | T30: LNS11000000 | U30: 2000 | V30: M12 | W30: 143248
... A170: JTS00000000QUR | B170: 2013 | C170: M07 | D170: 1.7 | G170: LNS14000000 | H170: 2006 | I170: M08 | J170: 4.7 | N170: JTS00000000JOL | O170: 2013 | P170: M07 | Q170: 3689 | T170: LNS11000000 | U170: 2012 | V170: M08 | W170: 154647
A171: 4 : The quits rate is the number of quits as a percent of total employment. | G171: LNS14000000 | H171: 2006 | I171: M09 | J171: 4.5 | N171: P : preliminary | T171: LNS11000000 | U171: 2012 | V171: M09 | W171: 155056
A172: P : preliminary | G172: LNS14000000 | H172: 2006 | I172: M10 | J172: 4.4 | T172: LNS11000000 | U172: 2012 | V172: M10 | W172: 155576
G173: LNS14000000 | H173: 2006 | I173: M11 | J173: 4.5 | T173: LNS11000000 | U173: 2012 | V173: M11 | W173: 155319
G174: LNS14000000 | H174: 2006 | I174: M12 | J174: 4.4 | T174: LNS11000000 | U174: 2012 | V174: M12 | W174: 155511
G175: LNS14000000 | H175: 2007 | I175: M01 | J175: 4.6 | T175: LNS11000000 | U175: 2013 | V175: M01 | W175: 155654
G176: LNS14000000 | H176: 2007 | I176: M02 | J176: 4.5 | T176: LNS11000000 | U176: 2013 | V176: M02 | W176: 155524
G177: LNS14000000 | H177: 2007 | I177: M03 | J177: 4.4 | T177: LNS11000000 | U177: 2013 | V177: M03 | W177: 155028
G178: LNS14000000 | H178: 2007 | I178: M04 | J178: 4.5 | T178: LNS11000000 | U178: 2013 | V178: M04 | W178: 155238
G179: LNS14000000 | H179: 2007 | I179: M05 | J179: 4.4 | T179: LNS11000000 | U179: 2013 | V179: M05 | W179: 155658
G180: LNS14000000 | H180: 2007 | I180: M06 | J180: 4.6 | T180: LNS11000000 | U180: 2013 | V180: M06 | W180: 155835
G181: LNS14000000 | H181: 2007 | I181: M07 | J181: 4.7 | T181: LNS11000000 | U181: 2013 | V181: M07 | W181: 155798
G182: LNS14000000 | H182: 2007 | I182: M08 | J182: 4.6 | T182: LNS11000000 | U182: 2013 | V182: M08 | W182: 155486
G183: LNS14000000 | H183: 2007 | I183: M09 | J183: 4.7 | T183: 1 : Data affected by changes in population controls.
G184: LNS14000000 | H184: 2007 | I184: M10 | J184: 4.7
G185: LNS14000000 | H185: 2007 | I185: M11 | J185: 4.7
G186: LNS14000000 | H186: 2007 | I186: M12 | J186: 5
G187: LNS14000000 | H187: 2008 | I187: M01 | J187: 5
...

Sheet Calculations
B1: EE rate (FF, NSA) | C1: UE rate (FF, NSA) | D1: EU rate (FF, NSA) | E1: EE rate (FF, SA) | F1: UE rate (FF, SA) | G1: EU rate (FF, SA) | H1: Quit rate (JOLTS, SA) | I1: Unemployment rate (CPS, SA) | J1: Implied search intensity of employed (FF) | K1: Implied search intensity of employed (JOLTS)
A2: =DATE(1994,1,1) -> 34335 | B2: ='raw FF data'!L33 -> 3.4 | C2: ='raw FF data'!P33 -> 25.1 | D2: ='raw FF data'!N33 -> 1.4 | E2: 3.291798 | F2: 24.819655 | G2: 1.3987889 | H2: =NA() -> #N/A | I2: ='raw BLS data'!J19 -> 6.6 | J2: =E2*( 1 - (I2/100) )/F2 -> 0.12387518 | K2: =H2*( 1 - (I2/100) )/F2 -> #N/A
A3: =DATE(YEAR(A2),MONTH(A2)+1,1) -> 34366 | B3: ='raw FF data'!L34 -> 2.7 | C3: ='raw FF data'!P34 -> 24.8 | D3: ='raw FF data'!N34 -> 1.2 | E3: 2.8930374 | F3: 26.083321 | G3: 1.3474183 | H3: =NA() -> #N/A | I3: ='raw BLS data'!J20 -> 6.6 | J3: =E3*( 1 - (I3/100) )/F3 -> 0.10359482 | K3: =H3*( 1 - (I3/100) )/F3 -> #N/A
A4: =DATE(YEAR(A3),MONTH(A3)+1,1) -> 34394 | B4: ='raw FF data'!L35 -> 2.9 | C4: ='raw FF data'!P35 -> 28.4 | D4: ='raw FF data'!N35 -> 1.4 | E4: 3.2781081 | F4: 28.544053 | G4: 1.5220962 | H4: =NA() -> #N/A | I4: ='raw BLS data'!J21 -> 6.5 | J4: =E4*( 1 - (I4/100) )/F4 -> 0.10737897 | K4: =H4*( 1 - (I4/100) )/F4 -> #N/A
A5: =DATE(YEAR(A4),MONTH(A4)+1,1) -> 34425 | B5: ='raw FF data'!L36 -> 2.8 | C5: ='raw FF data'!P36 -> 29.5 | D5: ='raw FF data'!N36 -> 1.2 | E5: 2.8560582 | F5: 27.55146 | G5: 1.2506208 | H5: =NA() -> #N/A | I5: ='raw BLS data'!J22 -> 6.4 | J5: =E5*( 1 - (I5/100) )/F5 -> 0.09702827 | K5: =H5*( 1 - (I5/100) )/F5 -> #N/A
A6: =DATE(YEAR(A5),MONTH(A5)+1,1) -> 34455 | B6: ='raw FF data'!L37 -> 3.5 | C6: ='raw FF data'!P37 -> 27.4 | D6: ='raw FF data'!N37 -> 1.7 | E6: 3.2420075 | F6: 26.889006 | G6: 1.6297717 | H6: =NA() -> #N/A | I6: ='raw BLS data'!J23 -> 6.1 | J6: =E6*( 1 - (I6/100) )/F6 -> 0.11321523 | K6: =H6*( 1 - (I6/100) )/F6 -> #N/A
A7: =DATE(YEAR(A6),MONTH(A6)+1,1) -> 34486 | B7: ='raw FF data'!L38 -> 3 | C7: ='raw FF data'!P38 -> 29.3 | D7: ='raw FF data'!N38 -> 1.6 | E7: 2.8348145 | F7: 27.615791 | G7: 1.5713787 | H7: =NA() -> #N/A | I7: ='raw BLS data'!J24 -> 6.1 | J7: =E7*( 1 - (I7/100) )/F7 -> 0.09639017 | K7: =H7*( 1 - (I7/100) )/F7 -> #N/A
A8: =DATE(YEAR(A7),MONTH(A7)+1,1) -> 34516 | B8: ='raw FF data'!L39 -> 2.9 | C8: ='raw FF data'!P39 -> 26.3 | D8: ='raw FF data'!N39 -> 1.5 | E8: 2.5567081 | F8: 25.017465 | G8: 1.5786076 | H8: =NA() -> #N/A | I8: ='raw BLS data'!J25 -> 6.1 | J8: =E8*( 1 - (I8/100) )/F8 -> 0.095962917 | K8: =H8*( 1 - (I8/100) )/F8 -> #N/A
A9: =DATE(YEAR(A8),MONTH(A8)+1,1) -> 34547 | B9: ='raw FF data'!L40 -> 4.2 | C9: ='raw FF data'!P40 -> 31.6 | D9: ='raw FF data'!N40 -> 1.6 | E9: 3.7540402 | F9: 28.751026 | G9: 1.6820008 | H9: =NA() -> #N/A | I9: ='raw BLS data'!J26 -> 6 | J9: =E9*( 1 - (I9/100) )/F9 -> 0.12273641 | K9: =H9*( 1 - (I9/100) )/F9 -> #N/A
A10: =DATE(YEAR(A9),MONTH(A9)+1,1) -> 34578 | B10: ='raw FF data'!L41 -> 2.8 | C10: ='raw FF data'!P41 -> 27.5 | D10: ='raw FF data'!N41 -> 1 | E10: 2.6791151 | F10: 25.824315 | G10: 1.052054 | H10: =NA() -> #N/A | I10: ='raw BLS data'!J27 -> 5.9 | J10: =E10*( 1 - (I10/100) )/F10 -> 0.097623008 | K10: =H10*( 1 - (I10/100) )/F10 -> #N/A
A11: =DATE(YEAR(A10),MONTH(A10)+1,1) -> 34608 | B11: ='raw FF data'!L42 -> 2.4 | C11: ='raw FF data'!P42 -> 26.4 | D11: ='raw FF data'!N42 -> 1.4 | E11: 2.468975 | F11: 26.538001 | G11: 1.3946172 | H11: =NA() -> #N/A | I11: ='raw BLS data'!J28 -> 5.8 | J11: =E11*( 1 - (I11/100) )/F11 -> 0.087639399 | K11: =H11*( 1 - (I11/100) )/F11 -> #N/A
A12: =DATE(YEAR(A11),MONTH(A11)+1,1) -> 34639 | B12: ='raw FF data'!L43 -> 2.3 | C12: ='raw FF data'!P43 -> 26.4 | D12: ='raw FF data'!N43 -> 1.4 | E12: 2.8766786 | F12: 31.582506 | G12: 1.5732538 | H12: =NA() -> #N/A | I12: ='raw BLS data'!J29 -> 5.6 | J12: =E12*( 1 - (I12/100) )/F12 -> 0.085983825 | K12: =H12*( 1 - (I12/100) )/F12 -> #N/A
A13: =DATE(YEAR(A12),MONTH(A12)+1,1) -> 34669 | B13: ='raw FF data'!L44 -> 2.5 | C13: ='raw FF data'!P44 -> 22.2 | D13: ='raw FF data'!N44 -> 2 | E13: 2.58217 | F13: 26.137402 | G13: 1.4069473 | H13: =NA() -> #N/A | I13: ='raw BLS data'!J30 -> 5.5 | J13: =E13*( 1 - (I13/100) )/F13 -> 0.093358578 | K13: =H13*( 1 - (I13/100) )/F13 -> #N/A
A14: =DATE(YEAR(A13),MONTH(A13)+1,1) -> 34700 | B14: ='raw FF data'!L45 -> 2.9 | C14: ='raw FF data'!P45 -> 30.5 | D14: ='raw FF data'!N45 -> 1.4 | E14: 2.8310838 | F14: 30.315138 | G14: 1.4008013 | H14: =NA() -> #N/A | I14: ='raw BLS data'!J31 -> 5.6 | J14: =E14*( 1 - (I14/100) )/F14 -> 0.088158697 | K14: =H14*( 1 - (I14/100) )/F14 -> #N/A
... A17: =DATE(YEAR(A16),MONTH(A16)+1,1) -> 34790 | B17: ='raw FF data'!L48 -> 2.5 | C17: ='raw FF data'!P48 -> 28.1 | D17: ='raw FF data'!N48 -> 1.2 | E17: 2.5600216 | F17: 26.398603 | G17: 1.2577942 | H17: =NA() -> #N/A | I17: ='raw BLS data'!J34 -> 5.8 | J17: =E17*( 1 - (I17/100) )/F17 -> 0.091351058 | K17: =H17*( 1 - (I17/100) )/F17 -> #N/A
A18: =DATE(YEAR(A17),MONTH(A17)+1,1) -> 34820 | B18: =B$17+( (MONTH($A18)-4)*(B$22-B$17)/5 ) -> 2.56 | C18: =C$17+( (MONTH($A18)-4)*(C$22-C$17)/5 ) -> 28.42 | D18: =D$17+( (MONTH($A18)-4)*(D$22-D$17)/5 ) -> 1.22 | E18: 2.3743557 | F18: 27.833497 | G18: 1.1668608 | H18: =NA() -> #N/A | I18: ='raw BLS data'!J35 -> 5.6 | J18: =E18*( 1 - (I18/100) )/F18 -> 0.080528572 | K18: =H18*( 1 - (I18/100) )/F18 -> #N/A
A19: =DATE(YEAR(A18),MONTH(A18)+1,1) -> 34851 | B19: =B$17+( (MONTH($A19)-4)*(B$22-B$17)/5 ) -> 2.62 | C19: =C$17+( (MONTH($A19)-4)*(C$22-C$17)/5 ) -> 28.74 | D19: =D$17+( (MONTH($A19)-4)*(D$22-D$17)/5 ) -> 1.24 | E19: 2.4554982 | F19: 26.999308 | G19: 1.2130946 | H19: =NA() -> #N/A | I19: ='raw BLS data'!J36 -> 5.6 | J19: =E19*( 1 - (I19/100) )/F19 -> 0.085853693 | K19: =H19*( 1 - (I19/100) )/F19 -> #N/A
A20: =DATE(YEAR(A19),MONTH(A19)+1,1) -> 34881 | B20: =B$17+( (MONTH($A20)-4)*(B$22-B$17)/5 ) -> 2.68 | C20: =C$17+( (MONTH($A20)-4)*(C$22-C$17)/5 ) -> 29.06 | D20: =D$17+( (MONTH($A20)-4)*(D$22-D$17)/5 ) -> 1.26 | E20: 2.3637486 | F20: 27.7762 | G20: 1.3225066 | H20: =NA() -> #N/A | I20: ='raw BLS data'!J37 -> 5.7 | J20: =E20*( 1 - (I20/100) )/F20 -> 0.080249095 | K20: =H20*( 1 - (I20/100) )/F20 -> #N/A
A21: =DATE(YEAR(A20),MONTH(A20)+1,1) -> 34912 | B21: =B$17+( (MONTH($A21)-4)*(B$22-B$17)/5 ) -> 2.74 | C21: =C$17+( (MONTH($A21)-4)*(C$22-C$17)/5 ) -> 29.38 | D21: =D$17+( (MONTH($A21)-4)*(D$22-D$17)/5 ) -> 1.28 | E21: 2.4396917 | F21: 26.590684 | G21: 1.3481499 | H21: =NA() -> #N/A | I21: ='raw BLS data'!J38 -> 5.7 | J21: =E21*( 1 - (I21/100) )/F21 -> 0.086520123 | K21: =H21*( 1 - (I21/100) )/F21 -> #N/A
A22: =DATE(YEAR(A21),MONTH(A21)+1,1) -> 34943 | B22: ='raw FF data'!L53 -> 2.8 | C22: ='raw FF data'!P53 -> 29.7 | D22: ='raw FF data'!N53 -> 1.3 | E22: 2.6596799 | F22: 27.947444 | G22: 1.3642426 | H22: =NA() -> #N/A | I22: ='raw BLS data'!J39 -> 5.6 | J22: =E22*( 1 - (I22/100) )/F22 -> 0.089837835 | K22: =H22*( 1 - (I22/100) )/F22 -> #N/A
A23: =DATE(YEAR(A22),MONTH(A22)+1,1) -> 34973 | B23: ='raw FF data'!L54 -> 3.1 | C23: ='raw FF data'!P54 -> 28.9 | D23: ='raw FF data'!N54 -> 1.4 | E23: 3.2069441 | F23: 29.145482 | G23: 1.4057664 | H23: =NA() -> #N/A | I23: ='raw BLS data'!J40 -> 5.5 | J23: =E23*( 1 - (I23/100) )/F23 -> 0.10398051 | K23: =H23*( 1 - (I23/100) )/F23 -> #N/A
A24: =DATE(YEAR(A23),MONTH(A23)+1,1) -> 35004 | B24: ='raw FF data'!L55 -> 2 | C24: ='raw FF data'!P55 -> 22.2 | D24: ='raw FF data'!N55 -> 1.1 | E24: 2.4875257 | F24: 26.531463 | G24: 1.2230077 | H24: =NA() -> #N/A | I24: ='raw BLS data'!J41 -> 5.6 | J24: =E24*( 1 - (I24/100) )/F24 -> 0.088507153 | K24: =H24*( 1 - (I24/100) )/F24 -> #N/A
A25: =DATE(YEAR(A24),MONTH(A24)+1,1) -> 35034 | B25: ='raw FF data'!L56 -> 2.5 | C25: ='raw FF data'!P56 -> 22.7 | D25: ='raw FF data'!N56 -> 1.9 | E25: 2.5853931 | F25: 26.54127 | G25: 1.349203 | H25: =NA() -> #N/A | I25: ='raw BLS data'!J42 -> 5.6 | J25: =E25*( 1 - (I25/100) )/F25 -> 0.091955326 | K25: =H25*( 1 - (I25/100) )/F25 -> #N/A
A26: =DATE(YEAR(A25),MONTH(A25)+1,1) -> 35065 | B26: ='raw FF data'!L57 -> 2.5 | C26: ='raw FF data'!P57 -> 29.1 | D26: ='raw FF data'!N57 -> 1.4 | E26: 2.4794311 | F26: 29.050188 | G26: 1.4008525 | H26: =NA() -> #N/A | I26: ='raw BLS data'!J43 -> 5.6 | J26: =E26*( 1 - (I26/100) )/F26 -> 0.080570321 | K26: =H26*( 1 - (I26/100) )/F26 -> #N/A
A27: =DATE(YEAR(A26),MONTH(A26)+1,1) -> 35096 | B27: ='raw FF data'!L58 -> 2.5 | C27: ='raw FF data'!P58 -> 25.5 | D27: ='raw FF data'!N58 -> 1.3 | E27: 2.6584983 | F27: 26.679341 | G27: 1.4253651 | H27: =NA() -> #N/A | I27: ='raw BLS data'!J44 -> 5.5 | J27: =E27*( 1 - (I27/100) )/F27 -> 0.094165778 | K27: =H27*( 1 - (I27/100) )/F27 -> #N/A
A28: =DATE(YEAR(A27),MONTH(A27)+1,1) -> 35125 | B28: ='raw FF data'!L59 -> 2.2 | C28: ='raw FF data'!P59 -> 25.2 | D28: ='raw FF data'!N59 -> 1.2 | E28: 2.5143459 | F28: 25.238347 | G28: 1.3215328 | H28: =NA() -> #N/A | I28: ='raw BLS data'!J45 -> 5.5 | J28: =E28*( 1 - (I28/100) )/F28 -> 0.094144712 | K28: =H28*( 1 - (I28/100) )/F28 -> #N/A
A29: =DATE(YEAR(A28),MONTH(A28)+1,1) -> 35156 | B29: ='raw FF data'!L60 -> 2.7 | C29: ='raw FF data'!P60 -> 31.7 | D29: ='raw FF data'!N60 -> 1.4 | E29: 2.7778105 | F29: 29.937021 | G29: 1.4701882 | H29: =NA() -> #N/A | I29: ='raw BLS data'!J46 -> 5.6 | J29: =E29*( 1 - (I29/100) )/F29 -> 0.087592321 | K29: =H29*( 1 - (I29/100) )/F29 -> #N/A
A30: =DATE(YEAR(A29),MONTH(A29)+1,1) -> 35186 | B30: ='raw FF data'!L61 -> 2.8 | C30: ='raw FF data'!P61 -> 27.8 | D30: ='raw FF data'!N61 -> 1.4 | E30: 2.6227864 | F30: 27.147591 | G30: 1.3448424 | H30: =NA() -> #N/A | I30: ='raw BLS data'!J47 -> 5.6 | J30: =E30*( 1 - (I30/100) )/F30 -> 0.091201844 | K30: =H30*( 1 - (I30/100) )/F30 -> #N/A
A31: =DATE(YEAR(A30),MONTH(A30)+1,1) -> 35217 | B31: ='raw FF data'!L62 -> 2.9 | C31: ='raw FF data'!P62 -> 29.1 | D31: ='raw FF data'!N62 -> 1.4 | E31: 2.6698081 | F31: 27.411189 | G31: 1.359135 | H31: =NA() -> #N/A | I31: ='raw BLS data'!J48 -> 5.3 | J31: =E31*( 1 - (I31/100) )/F31 -> 0.092236357 | K31: =H31*( 1 - (I31/100) )/F31 -> #N/A
A32: =DATE(YEAR(A31),MONTH(A31)+1,1) -> 35247 | B32: ='raw FF data'!L63 -> 3.1 | C32: ='raw FF data'!P63 -> 31.5 | D32: ='raw FF data'!N63 -> 1.1 | E32: 2.7446123 | F32: 30.173544 | G32: 1.1479353 | H32: =NA() -> #N/A | I32: ='raw BLS data'!J49 -> 5.5 | J32: =E32*( 1 - (I32/100) )/F32 -> 0.085958037 | K32: =H32*( 1 - (I32/100) )/F32 -> #N/A
A33: =DATE(YEAR(A32),MONTH(A32)+1,1) -> 35278 | B33: ='raw FF data'!L64 -> 2.9 | C33: ='raw FF data'!P64 -> 30.7 | D33: ='raw FF data'!N64 -> 1.2 | E33: 2.5473559 | F33: 27.59107 | G33: 1.2699932 | H33: =NA() -> #N/A | I33: ='raw BLS data'!J50 -> 5.1 | J33: =E33*( 1 - (I33/100) )/F33 -> 0.087616782 | K33: =H33*( 1 - (I33/100) )/F33 -> #N/A
... A84: =DATE(YEAR(A83),MONTH(A83)+1,1) -> 36831 | B84: ='raw FF data'!L115 -> 1.9 | C84: ='raw FF data'!P115 -> 25.2 | D84: ='raw FF data'!N115 -> 0.9 | E84: 2.4474805 | F84: 29.551242 | G84: 1.0286032 | H84: =NA() -> #N/A | I84: ='raw BLS data'!J101 -> 3.9 | J84: =E84*( 1 - (I84/100) )/F84 -> 0.079591537 | K84: =H84*( 1 - (I84/100) )/F84 -> #N/A
A85: =DATE(YEAR(A84),MONTH(A84)+1,1) -> 36861 | B85: ='raw FF data'!L116 -> 2.6 | C85: ='raw FF data'!P116 -> 26.9 | D85: ='raw FF data'!N116 -> 1.6 | E85: 2.733223 | F85: 31.481018 | G85: 1.171453 | H85: ='raw BLS data'!D19 -> 2.3 | I85: ='raw BLS data'!J102 -> 3.9 | J85: =E85*( 1 - (I85/100) )/F85 -> 0.083435273 | K85: =H85*( 1 - (I85/100) )/F85 -> 0.070210563
A86: =DATE(YEAR(A85),MONTH(A85)+1,1) -> 36892 | B86: ='raw FF data'!L117 -> 2.8 | C86: ='raw FF data'!P117 -> 32.9 | D86: ='raw FF data'!N117 -> 1.3 | E86: 2.8888122 | F86: 33.185825 | G86: 1.2626443 | H86: ='raw BLS data'!D20 -> 2.5 | I86: ='raw BLS data'!J103 -> 4.2 | J86: =E86*( 1 - (I86/100) )/F86 -> 0.083393499 | K86: =H86*( 1 - (I86/100) )/F86 -> 0.072169367
A87: =DATE(YEAR(A86),MONTH(A86)+1,1) -> 36923 | B87: ='raw FF data'!L118 -> 2.4 | C87: ='raw FF data'!P118 -> 28.5 | D87: ='raw FF data'!N118 -> 1 | E87: 2.5343082 | F87: 30.438631 | G87: 1.1177926 | H87: ='raw BLS data'!D21 -> 2.5 | I87: ='raw BLS data'!J104 -> 4.2 | J87: =E87*( 1 - (I87/100) )/F87 -> 0.079762696 | K87: =H87*( 1 - (I87/100) )/F87 -> 0.078682908
A88: =DATE(YEAR(A87),MONTH(A87)+1,1) -> 36951 | B88: ='raw FF data'!L119 -> 2.1 | C88: ='raw FF data'!P119 -> 30.4 | D88: ='raw FF data'!N119 -> 1.1 | E88: 2.4805476 | F88: 29.8251 | G88: 1.2760138 | H88: ='raw BLS data'!D22 -> 2.4 | I88: ='raw BLS data'!J105 -> 4.3 | J88: =E88*( 1 - (I88/100) )/F88 -> 0.079593497 | K88: =H88*( 1 - (I88/100) )/F88 -> 0.077008962
A89: =DATE(YEAR(A88),MONTH(A88)+1,1) -> 36982 | B89: ='raw FF data'!L120 -> 2.2 | C89: ='raw FF data'!P120 -> 34.3 | D89: ='raw FF data'!N120 -> 1 | E89: 2.3227032 | F89: 33.05143 | G89: 1.1049667 | H89: ='raw BLS data'!D23 -> 2.4 | I89: ='raw BLS data'!J106 -> 4.4 | J89: =E89*( 1 - (I89/100) )/F89 -> 0.067183303 | K89: =H89*( 1 - (I89/100) )/F89 -> 0.069419083
A90: =DATE(YEAR(A89),MONTH(A89)+1,1) -> 37012 | B90: ='raw FF data'!L121 -> 2.7 | C90: ='raw FF data'!P121 -> 33.3 | D90: ='raw FF data'!N121 -> 1.4 | E90: 2.4658389 | F90: 32.914346 | G90: 1.3109432 | H90: ='raw BLS data'!D24 -> 2.3 | I90: ='raw BLS data'!J107 -> 4.3 | J90: =E90*( 1 - (I90/100) )/F90 -> 0.071695418 | K90: =H90*( 1 - (I90/100) )/F90 -> 0.066873576
A91: =DATE(YEAR(A90),MONTH(A90)+1,1) -> 37043 | B91: ='raw FF data'!L122 -> 2.8 | C91: ='raw FF data'!P122 -> 27 | D91: ='raw FF data'!N122 -> 1.3 | E91: 2.4749382 | F91: 26.407177 | G91: 1.2252335 | H91: ='raw BLS data'!D25 -> 2.2 | I91: ='raw BLS data'!J108 -> 4.5 | J91: =E91*( 1 - (I91/100) )/F91 -> 0.089504682 | K91: =H91*( 1 - (I91/100) )/F91 -> 0.079561705
A92: =DATE(YEAR(A91),MONTH(A91)+1,1) -> 37073 | B92: ='raw FF data'!L123 -> 3.2 | C92: ='raw FF data'!P123 -> 33.4 | D92: ='raw FF data'!N123 -> 1.4 | E92: 2.8716647 | F92: 30.996879 | G92: 1.3078941 | H92: ='raw BLS data'!D26 -> 2.2 | I92: ='raw BLS data'!J109 -> 4.6 | J92: =E92*( 1 - (I92/100) )/F92 -> 0.088382064 | K92: =H92*( 1 - (I92/100) )/F92 -> 0.067710043
...

Sheet 3m MA
B1: =Calculations!B1 -> EE rate (FF, NSA) | C1: =Calculations!C1 -> UE rate (FF, NSA) | D1: =Calculations!E1 -> EE rate (FF, SA) | E1: =Calculations!F1 -> UE rate (FF, SA) | F1: =Calculations!G1 -> EU rate (FF, SA) | G1: =Calculations!H1 -> Quit rate (JOLTS, SA) | H1: =Calculations!I1 -> Unemployment rate (CPS, SA) | I1: =Calculations!J1 -> Implied search intensity of employed (FF) | J1: =Calculations!K1 -> Implied search intensity of employed (JOLTS)
A2: =Calculations!A2 -> 34335 | B2: =NA() -> #N/A | C2: =NA() -> #N/A | D2: =NA() -> #N/A | E2: =NA() -> #N/A | F2: =NA() -> #N/A | G2: =NA() -> #N/A | H2: =NA() -> #N/A | I2: =NA() -> #N/A | J2: =NA() -> #N/A
A3: =Calculations!A3 -> 34366 | B3: =NA() -> #N/A | C3: =NA() -> #N/A | D3: =NA() -> #N/A | E3: =NA() -> #N/A | F3: =NA() -> #N/A | G3: =NA() -> #N/A | H3: =NA() -> #N/A | I3: =NA() -> #N/A | J3: =NA() -> #N/A
A4: =Calculations!A4 -> 34394 | B4: =AVERAGE(Calculations!B2:B4) -> 3 | C4: =AVERAGE(Calculations!C2:C4) -> 26.1 | D4: =AVERAGE(Calculations!E2:E4) -> 3.1543145 | E4: =AVERAGE(Calculations!F2:F4) -> 26.482343 | F4: =AVERAGE(Calculations!G2:G4) -> 1.4227678 | G4: =AVERAGE(Calculations!H2:H4) -> #N/A | H4: =AVERAGE(Calculations!I2:I4) -> 6.5666667 | I4: =AVERAGE(Calculations!J2:J4) -> 0.11161633 | J4: =AVERAGE(Calculations!K2:K4) -> #N/A
A5: =Calculations!A5 -> 34425 | B5: =AVERAGE(Calculations!B3:B5) -> 2.8 | C5: =AVERAGE(Calculations!C3:C5) -> 27.566667 | D5: =AVERAGE(Calculations!E3:E5) -> 3.0090679 | E5: =AVERAGE(Calculations!F3:F5) -> 27.392945 | F5: =AVERAGE(Calculations!G3:G5) -> 1.3733784 | G5: =AVERAGE(Calculations!H3:H5) -> #N/A | H5: =AVERAGE(Calculations!I3:I5) -> 6.5 | I5: =AVERAGE(Calculations!J3:J5) -> 0.10266735 | J5: =AVERAGE(Calculations!K3:K5) -> #N/A
A6: =Calculations!A6 -> 34455 | B6: =AVERAGE(Calculations!B4:B6) -> 3.0666667 | C6: =AVERAGE(Calculations!C4:C6) -> 28.433333 | D6: =AVERAGE(Calculations!E4:E6) -> 3.1253913 | E6: =AVERAGE(Calculations!F4:F6) -> 27.661507 | F6: =AVERAGE(Calculations!G4:G6) -> 1.4674963 | G6: =AVERAGE(Calculations!H4:H6) -> #N/A | H6: =AVERAGE(Calculations!I4:I6) -> 6.3333333 | I6: =AVERAGE(Calculations!J4:J6) -> 0.10587416 | J6: =AVERAGE(Calculations!K4:K6) -> #N/A
A7: =Calculations!A7 -> 34486 | B7: =AVERAGE(Calculations!B5:B7) -> 3.1 | C7: =AVERAGE(Calculations!C5:C7) -> 28.733333 | D7: =AVERAGE(Calculations!E5:E7) -> 2.9776268 | E7: =AVERAGE(Calculations!F5:F7) -> 27.352086 | F7: =AVERAGE(Calculations!G5:G7) -> 1.4839237 | G7: =AVERAGE(Calculations!H5:H7) -> #N/A | H7: =AVERAGE(Calculations!I5:I7) -> 6.2 | I7: =AVERAGE(Calculations!J5:J7) -> 0.10221122 | J7: =AVERAGE(Calculations!K5:K7) -> #N/A
A8: =Calculations!A8 -> 34516 | B8: =AVERAGE(Calculations!B6:B8) -> 3.1333333 | C8: =AVERAGE(Calculations!C6:C8) -> 27.666667 | D8: =AVERAGE(Calculations!E6:E8) -> 2.8778434 | E8: =AVERAGE(Calculations!F6:F8) -> 26.507421 | F8: =AVERAGE(Calculations!G6:G8) -> 1.5932527 | G8: =AVERAGE(Calculations!H6:H8) -> #N/A | H8: =AVERAGE(Calculations!I6:I8) -> 6.1 | I8: =AVERAGE(Calculations!J6:J8) -> 0.10185611 | J8: =AVERAGE(Calculations!K6:K8) -> #N/A
A9: =Calculations!A9 -> 34547 | B9: =AVERAGE(Calculations!B7:B9) -> 3.3666667 | C9: =AVERAGE(Calculations!C7:C9) -> 29.066667 | D9: =AVERAGE(Calculations!E7:E9) -> 3.0485209 | E9: =AVERAGE(Calculations!F7:F9) -> 27.128094 | F9: =AVERAGE(Calculations!G7:G9) -> 1.6106624 | G9: =AVERAGE(Calculations!H7:H9) -> #N/A | H9: =AVERAGE(Calculations!I7:I9) -> 6.0666667 | I9: =AVERAGE(Calculations!J7:J9) -> 0.10502983 | J9: =AVERAGE(Calculations!K7:K9) -> #N/A
A10: =Calculations!A10 -> 34578 | B10: =AVERAGE(Calculations!B8:B10) -> 3.3 | C10: =AVERAGE(Calculations!C8:C10) -> 28.466667 | D10: =AVERAGE(Calculations!E8:E10) -> 2.9966211 | E10: =AVERAGE(Calculations!F8:F10) -> 26.530935 | F10: =AVERAGE(Calculations!G8:G10) -> 1.4375542 | G10: =AVERAGE(Calculations!H8:H10) -> #N/A | H10: =AVERAGE(Calculations!I8:I10) -> 6 | I10: =AVERAGE(Calculations!J8:J10) -> 0.10544078 | J10: =AVERAGE(Calculations!K8:K10) -> #N/A
A11: =Calculations!A11 -> 34608 | B11: =AVERAGE(Calculations!B9:B11) -> 3.1333333 | C11: =AVERAGE(Calculations!C9:C11) -> 28.5 | D11: =AVERAGE(Calculations!E9:E11) -> 2.9673768 | E11: =AVERAGE(Calculations!F9:F11) -> 27.037781 | F11: =AVERAGE(Calculations!G9:G11) -> 1.376224 | G11: =AVERAGE(Calculations!H9:H11) -> #N/A | H11: =AVERAGE(Calculations!I9:I11) -> 5.9 | I11: =AVERAGE(Calculations!J9:J11) -> 0.10266627 | J11: =AVERAGE(Calculations!K9:K11) -> #N/A
A12: =Calculations!A12 -> 34639 | B12: =AVERAGE(Calculations!B10:B12) -> 2.5 | C12: =AVERAGE(Calculations!C10:C12) -> 26.766667 | D12: =AVERAGE(Calculations!E10:E12) -> 2.6749229 | E12: =AVERAGE(Calculations!F10:F12) -> 27.981607 | F12: =AVERAGE(Calculations!G10:G12) -> 1.339975 | G12: =AVERAGE(Calculations!H10:H12) -> #N/A | H12: =AVERAGE(Calculations!I10:I12) -> 5.7666667 | I12: =AVERAGE(Calculations!J10:J12) -> 0.090415411 | J12: =AVERAGE(Calculations!K10:K12) -> #N/A
A13: =Calculations!A13 -> 34669 | B13: =AVERAGE(Calculations!B11:B13) -> 2.4 | C13: =AVERAGE(Calculations!C11:C13) -> 25 | D13: =AVERAGE(Calculations!E11:E13) -> 2.6426079 | E13: =AVERAGE(Calculations!F11:F13) -> 28.085969 | F13: =AVERAGE(Calculations!G11:G13) -> 1.4582728 | G13: =AVERAGE(Calculations!H11:H13) -> #N/A | H13: =AVERAGE(Calculations!I11:I13) -> 5.6333333 | I13: =AVERAGE(Calculations!J11:J13) -> 0.088993934 | J13: =AVERAGE(Calculations!K11:K13) -> #N/A
A14: =Calculations!A14 -> 34700 | B14: =AVERAGE(Calculations!B12:B14) -> 2.5666667 | C14: =AVERAGE(Calculations!C12:C14) -> 26.366667 | D14: =AVERAGE(Calculations!E12:E14) -> 2.7633108 | E14: =AVERAGE(Calculations!F12:F14) -> 29.345015 | F14: =AVERAGE(Calculations!G12:G14) -> 1.4603342 | G14: =AVERAGE(Calculations!H12:H14) -> #N/A | H14: =AVERAGE(Calculations!I12:I14) -> 5.5666667 | I14: =AVERAGE(Calculations!J12:J14) -> 0.089167033 | J14: =AVERAGE(Calculations!K12:K14) -> #N/A
A15: =Calculations!A15 -> 34731 | B15: =AVERAGE(Calculations!B13:B15) -> 2.6333333 | C15: =AVERAGE(Calculations!C13:C15) -> 26.6 | D15: =AVERAGE(Calculations!E13:E15) -> 2.6968872 | E15: =AVERAGE(Calculations!F13:F15) -> 28.285897 | F15: =AVERAGE(Calculations!G13:G15) -> 1.3812114 | G15: =AVERAGE(Calculations!H13:H15) -> #N/A | H15: =AVERAGE(Calculations!I13:I15) -> 5.5 | I15: =AVERAGE(Calculations!J13:J15) -> 0.090228394 | J15: =AVERAGE(Calculations!K13:K15) -> #N/A
... A235: =Calculations!A235 -> 41426 | B235: =AVERAGE(Calculations!B233:B235) -> 1.6333333 | C235: =AVERAGE(Calculations!C233:C235) -> 19.9 | D235: =AVERAGE(Calculations!E233:E235) -> 1.6081095 | E235: =AVERAGE(Calculations!F233:F235) -> 20.053218 | F235: =AVERAGE(Calculations!G233:G235) -> 1.3326933 | G235: =AVERAGE(Calculations!H233:H235) -> 1.6 | H235: =AVERAGE(Calculations!I233:I235) -> 7.5666667 | I235: =AVERAGE(Calculations!J233:J235) -> 0.074142996 | J235: =AVERAGE(Calculations!K233:K235) -> 0.074181434

Sheet Beveridge curve
B1: V | C1: L | D1: U/L | E1: U/L (3m MA) | F1: V/L | G1: V/L (3m MA) | H1: Aug 2009 and before | I1: Post Aug 2009 | J1: V/U | K1: V/(U+S) | L1: UE rate | M1: d ln EU rate | N1: Elasticity of f wrt theta | O1: Cumulative vertical BC shift due to EU (logs) | P1: Implied V/L (EU constant) | Q1: Implied V/L (EU constant, 3m MA) | R1: s/(u+s) | S1: d ln s | T1: Cumulative vertical BC shift due to s (logs) | U1: Implied V/L (s constant) | V1: Implied V/L (s constant, 3m MA) | W1: Combined cumulative vertical shift (logs) | X1: Implied V/L (EU and s constant) | Y1: Implied V/L (EU and s constant, 3m MA) | AA1: Quarterly averages: | AD1: U/L | AE1: V/L | AF1: Implied V/L (EU constant) | AG1: Implied V/L (s constant) | AH1: Implied V/L (EU and s constant)
A2: =DATE(2000,12,1) -> 36861 | B2: ='raw BLS data'!Q19 -> 5191 | C2: ='raw BLS data'!W30 -> 143248 | D2: ='raw BLS data'!J102/100 -> 0.039 | E2: =NA() -> #N/A | F2: =B2/C2 -> 0.036237853 | G2: =NA() -> #N/A | H2: =IF( $A2<=$A$106, F2, NA() ) -> 0.036237853 | I2: =IF( $A2>$A$106, F2, NA() ) -> #N/A | J2: =F2/D2 -> 0.92917572 | K2: =F2/(D2+Calculations!J85) -> 0.2959756 | L2: =Calculations!F85/100 -> 0.31481018 | M2: =NA() -> #N/A | N2: 0.5 | O2: =NA() -> #N/A | P2: =F2/EXP(O2) -> #N/A | Q2: =NA() -> #N/A | R2: =Calculations!J85/( (Calculations!I85/100) + Calculations!J85 ) -> 0.68146434 | S2: =NA() -> #N/A | T2: =NA() -> #N/A | U2: =F2/EXP(T2) -> #N/A | V2: =NA() -> #N/A | W2: =O2+T2 -> #N/A | X2: =F2/EXP(W2) -> #N/A | Y2: =NA() -> #N/A | AC2: =DATE(2001,3,1) -> 36951 | AD2: =VLOOKUP(AC2,A$1:Y$152,5) -> 0.042333333 | AE2: =VLOOKUP(AC2,A$1:Y$152,7) -> 0.033984994 | AF2: =VLOOKUP(AC2,A$1:Y$152,17) -> 0.031645788 | AG2: =VLOOKUP(AC2,A$1:Y$152,22) -> 0.03466213 | AH2: =VLOOKUP(AC2,A$1:Y$152,25) -> 0.032299979
A3: =DATE(YEAR(A2),MONTH(A2)+1,1) -> 36892 | B3: ='raw BLS data'!Q20 -> 5186 | C3: ='raw BLS data'!W31 -> 143800 | D3: ='raw BLS data'!J103/100 -> 0.042 | E3: =NA() -> #N/A | F3: =B3/C3 -> 0.036063978 | G3: =NA() -> #N/A | H3: =IF( $A3<=$A$106, F3, NA() ) -> 0.036063978 | I3: =IF( $A3>$A$106, F3, NA() ) -> #N/A | J3: =F3/D3 -> 0.85866614 | K3: =F3/(D3+Calculations!J86) -> 0.28760644 | L3: =Calculations!F86/100 -> 0.33185825 | M3: =LN(Calculations!G86/Calculations!G85) -> 0.074963284 | N3: 0.5 | O3: =M3/N3 -> 0.14992657 | P3: =F3/EXP(O3) -> 0.031042833 | Q3: =NA() -> #N/A | R3: =Calculations!J86/( (Calculations!I86/100) + Calculations!J86 ) -> 0.66505441 | S3: =LN(Calculations!J86/Calculations!J85) -> -0.00050080204 | T3: =R3*S3 -> -0.0003330606 | U3: =F3/EXP(T3) -> 0.036075991 | V3: =NA() -> #N/A | W3: =O3+T3 -> 0.14959351 | X3: =F3/EXP(W3) -> 0.031053174 | Y3: =NA() -> #N/A | AC3: =DATE(YEAR(AC2),MONTH(AC2)+3,1) -> 37043 | AD3: =VLOOKUP(AC3,A$1:Y$152,5) -> 0.044 | AE3: =VLOOKUP(AC3,A$1:Y$152,7) -> 0.031242145 | AF3: =VLOOKUP(AC3,A$1:Y$152,17) -> 0.029629143 | AG3: =VLOOKUP(AC3,A$1:Y$152,22) -> 0.033248555 | AH3: =VLOOKUP(AC3,A$1:Y$152,25) -> 0.031670249
A4: =DATE(YEAR(A3),MONTH(A3)+1,1) -> 36923 | B4: ='raw BLS data'!Q21 -> 4702 | C4: ='raw BLS data'!W32 -> 143701 | D4: ='raw BLS data'!J104/100 -> 0.042 | E4: =AVERAGE(D2:D4) -> 0.041 | F4: =B4/C4 -> 0.032720719 | G4: =AVERAGE(F2:F4) -> 0.035007517 | H4: =IF( $A4<=$A$106, F4, NA() ) -> 0.032720719 | I4: =IF( $A4>$A$106, F4, NA() ) -> #N/A | J4: =F4/D4 -> 0.77906473 | K4: =F4/(D4+Calculations!J87) -> 0.26872531 | L4: =Calculations!F87/100 -> 0.30438631 | M4: =LN(Calculations!G87/Calculations!G86) -> -0.12185226 | N4: 0.5 | O4: =O3+(M4/N4) -> -0.093777955 | P4: =F4/EXP(O4) -> 0.035937684 | Q4: =NA() -> #N/A | R4: =Calculations!J87/( (Calculations!I87/100) + Calculations!J87 ) -> 0.65506677 | S4: =LN(Calculations!J87/Calculations!J86) -> -0.04451443 | T4: =T3+(R4*S4) -> -0.029492985 | U4: =F4/EXP(T4) -> 0.033700122 | V4: =NA() -> #N/A | W4: =O4+T4 -> -0.12327094 | X4: =F4/EXP(W4) -> 0.037013378 | Y4: =NA() -> #N/A | AC4: =DATE(YEAR(AC3),MONTH(AC3)+3,1) -> 37135 | AD4: =VLOOKUP(AC4,A$1:Y$152,5) -> 0.048333333 | AE4: =VLOOKUP(AC4,A$1:Y$152,7) -> 0.028720323 | AF4: =VLOOKUP(AC4,A$1:Y$152,17) -> 0.023285548 | AG4: =VLOOKUP(AC4,A$1:Y$152,22) -> 0.028145409 | AH4: =VLOOKUP(AC4,A$1:Y$152,25) -> 0.02281634
A5: =DATE(YEAR(A4),MONTH(A4)+1,1) -> 36951 | B5: ='raw BLS data'!Q22 -> 4774 | C5: ='raw BLS data'!W33 -> 143924 | D5: ='raw BLS data'!J105/100 -> 0.043 | E5: =AVERAGE(D3:D5) -> 0.042333333 | F5: =B5/C5 -> 0.033170284 | G5: =AVERAGE(F3:F5) -> 0.033984994 | H5: =IF( $A5<=$A$106, F5, NA() ) -> 0.033170284 | I5: =IF( $A5>$A$106, F5, NA() ) -> #N/A | J5: =F5/D5 -> 0.77140196 | K5: =F5/(D5+Calculations!J88) -> 0.27057132 | L5: =Calculations!F88/100 -> 0.298251 | M5: =LN(Calculations!G88/Calculations!G87) -> 0.13238508 | N5: 0.5 | O5: =O4+(M5/N5) -> 0.17099221 | P5: =F5/EXP(O5) -> 0.027956849 | Q5: =AVERAGE(P3:P5) -> 0.031645788 | R5: =Calculations!J88/( (Calculations!I88/100) + Calculations!J88 ) -> 0.6492473 | S5: =LN(Calculations!J88/Calculations!J87) -> -0.0021235266 | T5: =T4+(R5*S5) -> -0.030871679 | U5: =F5/EXP(T5) -> 0.034210277 | V5: =AVERAGE(U3:U5) -> 0.03466213 | W5: =O5+T5 -> 0.14012054 | X5: =F5/EXP(W5) -> 0.028833384 | Y5: =AVERAGE(X3:X5) -> 0.032299979 | AC5: =DATE(YEAR(AC4),MONTH(AC4)+3,1) -> 37226 | AD5: =VLOOKUP(AC5,A$1:Y$152,5) -> 0.055 | AE5: =VLOOKUP(AC5,A$1:Y$152,7) -> 0.024686232 | AF5: =VLOOKUP(AC5,A$1:Y$152,17) -> 0.016526794 | AG5: =VLOOKUP(AC5,A$1:Y$152,22) -> 0.025289258 | AH5: =VLOOKUP(AC5,A$1:Y$152,25) -> 0.016905626
A6: =DATE(YEAR(A5),MONTH(A5)+1,1) -> 36982 | B6: ='raw BLS data'!Q23 -> 4653 | C6: ='raw BLS data'!W34 -> 143569 | D6: ='raw BLS data'!J106/100 -> 0.044 | E6: =AVERAGE(D4:D6) -> 0.043 | F6: =B6/C6 -> 0.032409503 | G6: =AVERAGE(F4:F6) -> 0.032766835 | H6: =IF( $A6<=$A$106, F6, NA() ) -> 0.032409503 | I6: =IF( $A6>$A$106, F6, NA() ) -> #N/A | J6: =F6/D6 -> 0.73657962 | K6: =F6/(D6+Calculations!J89) -> 0.29149614 | L6: =Calculations!F89/100 -> 0.3305143 | M6: =LN(Calculations!G89/Calculations!G88) -> -0.14392573 | N6: 0.5 | O6: =O5+(M6/N6) -> -0.11685926 | P6: =F6/EXP(O6) -> 0.036427025 | Q6: =AVERAGE(P4:P6) -> 0.033440519 | R6: =Calculations!J89/( (Calculations!I89/100) + Calculations!J89 ) -> 0.60425712 | S6: =LN(Calculations!J89/Calculations!J88) -> -0.16950765 | T6: =T5+(R6*S6) -> -0.13329788 | U6: =F6/EXP(T6) -> 0.037030784 | V6: =AVERAGE(U4:U6) -> 0.034980395 | W6: =O6+T6 -> -0.25015714 | X6: =F6/EXP(W6) -> 0.041621166 | Y6: =AVERAGE(X4:X6) -> 0.035822643 | AC6: =DATE(YEAR(AC5),MONTH(AC5)+3,1) -> 37316 | AD6: =VLOOKUP(AC6,A$1:Y$152,5) -> 0.057 | AE6: =VLOOKUP(AC6,A$1:Y$152,7) -> 0.024254259 | AF6: =VLOOKUP(AC6,A$1:Y$152,17) -> 0.017094584 | AG6: =VLOOKUP(AC6,A$1:Y$152,22) -> 0.024272227 | AH6: =VLOOKUP(AC6,A$1:Y$152,25) -> 0.017105038
A7: =DATE(YEAR(A6),MONTH(A6)+1,1) -> 37012 | B7: ='raw BLS data'!Q24 -> 4452 | C7: ='raw BLS data'!W35 -> 143318 | D7: ='raw BLS data'!J107/100 -> 0.043 | E7: =AVERAGE(D5:D7) -> 0.043333333 | F7: =B7/C7 -> 0.031063788 | G7: =AVERAGE(F5:F7) -> 0.032214525 | H7: =IF( $A7<=$A$106, F7, NA() ) -> 0.031063788 | I7: =IF( $A7>$A$106, F7, NA() ) -> #N/A | J7: =F7/D7 -> 0.72241368 | K7: =F7/(D7+Calculations!J90) -> 0.27083722 | L7: =Calculations!F90/100 -> 0.32914346 | M7: =LN(Calculations!G90/Calculations!G89) -> 0.17093165 | N7: 0.5 | O7: =O6+(M7/N7) -> 0.22500405 | P7: =F7/EXP(O7) -> 0.024804838 | Q7: =AVERAGE(P5:P7) -> 0.029729571 | R7: =Calculations!J90/( (Calculations!I90/100) + Calculations!J90 ) -> 0.625094 | S7: =LN(Calculations!J90/Calculations!J89) -> 0.065002102 | T7: =T6+(R7*S7) -> -0.09266546 | U7: =F7/EXP(T7) -> 0.034079916 | V7: =AVERAGE(U5:U7) -> 0.035106993 | W7: =O7+T7 -> 0.13233859 | X7: =F7/EXP(W7) -> 0.027213255 | Y7: =AVERAGE(X5:X7) -> 0.032555935 | AC7: =DATE(YEAR(AC6),MONTH(AC6)+3,1) -> 37408 | AD7: =VLOOKUP(AC7,A$1:Y$152,5) -> 0.058333333 | AE7: =VLOOKUP(AC7,A$1:Y$152,7) -> 0.023260251 | AF7: =VLOOKUP(AC7,A$1:Y$152,17) -> 0.018367521 | AG7: =VLOOKUP(AC7,A$1:Y$152,22) -> 0.021601684 | AH7: =VLOOKUP(AC7,A$1:Y$152,25) -> 0.017043285
A8: =DATE(YEAR(A7),MONTH(A7)+1,1) -> 37043 | B8: ='raw BLS data'!Q25 -> 4337 | C8: ='raw BLS data'!W36 -> 143357 | D8: ='raw BLS data'!J108/100 -> 0.045 | E8: =AVERAGE(D6:D8) -> 0.044 | F8: =B8/C8 -> 0.030253144 | G8: =AVERAGE(F6:F8) -> 0.031242145 | H8: =IF( $A8<=$A$106, F8, NA() ) -> 0.030253144 | I8: =IF( $A8>$A$106, F8, NA() ) -> #N/A | J8: =F8/D8 -> 0.67229209 | K8: =F8/(D8+Calculations!J91) -> 0.22492261 | L8: =Calculations!F91/100 -> 0.26407177 | M8: =LN(Calculations!G91/Calculations!G90) -> -0.06761546 | N8: 0.5 | O8: =O7+(M8/N8) -> 0.089773129 | P8: =F8/EXP(O8) -> 0.027655566 | Q8: =AVERAGE(P6:P8) -> 0.029629143 | R8: =Calculations!J91/( (Calculations!I91/100) + Calculations!J91 ) -> 0.66543916 | S8: =LN(Calculations!J91/Calculations!J90) -> 0.22186409 | T8: =T7+(R8*S8) -> 0.054971596 | U8: =F8/EXP(T8) -> 0.028634965 | V8: =AVERAGE(U6:U8) -> 0.033248555 | W8: =O8+T8 -> 0.14474472 | X8: =F8/EXP(W8) -> 0.026176326 | Y8: =AVERAGE(X6:X8) -> 0.031670249 | AC8: =DATE(YEAR(AC7),MONTH(AC7)+3,1) -> 37500 | AD8: =VLOOKUP(AC8,A$1:Y$152,5) -> 0.057333333 | AE8: =VLOOKUP(AC8,A$1:Y$152,7) -> 0.023218254 | AF8: =VLOOKUP(AC8,A$1:Y$152,17) -> 0.017680477 | AG8: =VLOOKUP(AC8,A$1:Y$152,22) -> 0.02284428 | AH8: =VLOOKUP(AC8,A$1:Y$152,25) -> 0.017391995
A9: =DATE(YEAR(A8),MONTH(A8)+1,1) -> 37073 | B9: ='raw BLS data'!Q26 -> 4231 | C9: ='raw BLS data'!W37 -> 143654 | D9: ='raw BLS data'!J109/100 -> 0.046 | E9: =AVERAGE(D7:D9) -> 0.044666667 | F9: =B9/C9 -> 0.029452713 | G9: =AVERAGE(F7:F9) -> 0.030256548 | H9: =IF( $A9<=$A$106, F9, NA() ) -> 0.029452713 | I9: =IF( $A9>$A$106, F9, NA() ) -> #N/A | J9: =F9/D9 -> 0.64027636 | K9: =F9/(D9+Calculations!J92) -> 0.21917146 | L9: =Calculations!F92/100 -> 0.30996879 | M9: =LN(Calculations!G92/Calculations!G91) -> 0.065286888 | N9: 0.5 | O9: =O8+(M9/N9) -> 0.2203469 | P9: =F9/EXP(O9) -> 0.023628158 | Q9: =AVERAGE(P7:P9) -> 0.025362854 | R9: =Calculations!J92/( (Calculations!I92/100) + Calculations!J92 ) -> 0.65769241 | S9: =LN(Calculations!J92/Calculations!J91) -> -0.012621891 | T9: =T8+(R9*S9) -> 0.046670274 | U9: =F9/EXP(T9) -> 0.028109729 | V9: =AVERAGE(U7:U9) -> 0.03027487 | W9: =O9+T9 -> 0.26701718 | X9: =F9/EXP(W9) -> 0.022550762 | Y9: =AVERAGE(X7:X9) -> 0.025313448 | AC9: =DATE(YEAR(AC8),MONTH(AC8)+3,1) -> 37591 | AD9: =VLOOKUP(AC9,A$1:Y$152,5) -> 0.058666667 | AE9: =VLOOKUP(AC9,A$1:Y$152,7) -> 0.023261894 | AF9: =VLOOKUP(AC9,A$1:Y$152,17) -> 0.017319697 | AG9: =VLOOKUP(AC9,A$1:Y$152,22) -> 0.022179364 | AH9: =VLOOKUP(AC9,A$1:Y$152,25) -> 0.016585333
A10: =DATE(YEAR(A9),MONTH(A9)+1,1) -> 37104 | B10: ='raw BLS data'!Q27 -> 4139 | C10: ='raw BLS data'!W38 -> 143284 | D10: ='raw BLS data'!J110/100 -> 0.049 | E10: =AVERAGE(D8:D10) -> 0.046666667 | F10: =B10/C10 -> 0.028886687 | G10: =AVERAGE(F8:F10) -> 0.029530848 | H10: =IF( $A10<=$A$106, F10, NA() ) -> 0.028886687 | I10: =IF( $A10>$A$106, F10, NA() ) -> #N/A | J10: =F10/D10 -> 0.58952422 | K10: =F10/(D10+Calculations!J93) -> 0.21830817 | L10: =Calculations!F93/100 -> 0.2689066 | M10: =LN(Calculations!G93/Calculations!G92) -> -0.075111778 | N10: 0.5 | O10: =O9+(M10/N10) -> 0.070123348 | P10: =F10/EXP(O10) -> 0.026930446 | Q10: =AVERAGE(P8:P10) -> 0.02607139 | R10: =Calculations!J93/( (Calculations!I93/100) + Calculations!J93 ) -> 0.62968753 | S10: =LN(Calculations!J93/Calculations!J92) -> -0.05897219 | T10: =T9+(R10*S10) -> 0.0095362208 | U10: =F10/EXP(T10) -> 0.028612526 | V10: =AVERAGE(U8:U10) -> 0.028452407 | W10: =O10+T10 -> 0.079659569 | X10: =F10/EXP(W10) -> 0.026674852 | Y10: =AVERAGE(X8:X10) -> 0.02513398 | AC10: =DATE(YEAR(AC9),MONTH(AC9)+3,1) -> 37681 | AD10: =VLOOKUP(AC10,A$1:Y$152,5) -> 0.058666667 | AE10: =VLOOKUP(AC10,A$1:Y$152,7) -> 0.022947008 | AF10: =VLOOKUP(AC10,A$1:Y$152,17) -> 0.01926605 | AG10: =VLOOKUP(AC10,A$1:Y$152,22) -> 0.022610832 | AH10: =VLOOKUP(AC10,A$1:Y$152,25) -> 0.019025242
A11: =DATE(YEAR(A10),MONTH(A10)+1,1) -> 37135 | B11: ='raw BLS data'!Q28 -> 4006 | C11: ='raw BLS data'!W39 -> 143989 | D11: ='raw BLS data'!J111/100 -> 0.05 | E11: =AVERAGE(D9:D11) -> 0.048333333 | F11: =B11/C11 -> 0.02782157 | G11: =AVERAGE(F9:F11) -> 0.028720323 | H11: =IF( $A11<=$A$106, F11, NA() ) -> 0.02782157 | I11: =IF( $A11>$A$106, F11, NA() ) -> #N/A | J11: =F11/D11 -> 0.55643139 | K11: =F11/(D11+Calculations!J94) -> 0.20986837 | L11: =Calculations!F94/100 -> 0.26970626 | M11: =LN(Calculations!G94/Calculations!G93) -> 0.14784235 | N11: 0.5 | O11: =O10+(M11/N11) -> 0.36580805 | P11: =F11/EXP(O11) -> 0.01929804 | Q11: =AVERAGE(P9:P11) -> 0.023285548 | R11: =Calculations!J94/( (Calculations!I94/100) + Calculations!J94 ) -> 0.62283155 | S11: =LN(Calculations!J94/Calculations!J93) -> -0.0090896791 | T11: =T10+(R11*S11) -> 0.0038748819 | U11: =F11/EXP(T11) -> 0.027713973 | V11: =AVERAGE(U9:U11) -> 0.028145409 | W11: =O11+T11 -> 0.36968293 | X11: =F11/EXP(W11) -> 0.019223407 | Y11: =AVERAGE(X9:X11) -> 0.02281634 | AC11: =DATE(YEAR(AC10),MONTH(AC10)+3,1) -> 37773 | AD11: =VLOOKUP(AC11,A$1:Y$152,5) -> 0.061333333 | AE11: =VLOOKUP(AC11,A$1:Y$152,7) -> 0.02138673 | AF11: =VLOOKUP(AC11,A$1:Y$152,17) -> 0.015385426 | AG11: =VLOOKUP(AC11,A$1:Y$152,22) -> 0.019946165 | AH11: =VLOOKUP(AC11,A$1:Y$152,25) -> 0.014426079
A12: =DATE(YEAR(A11),MONTH(A11)+1,1) -> 37165 | B12: ='raw BLS data'!Q29 -> 3583 | C12: ='raw BLS data'!W40 -> 144086 | D12: ='raw BLS data'!J112/100 -> 0.053 | E12: =AVERAGE(D10:D12) -> 0.050666667 | F12: =B12/C12 -> 0.024867093 | G12: =AVERAGE(F10:F12) -> 0.027191783 | H12: =IF( $A12<=$A$106, F12, NA() ) -> 0.024867093 | I12: =IF( $A12>$A$106, F12, NA() ) -> #N/A | J12: =F12/D12 -> 0.46919044 | K12: =F12/(D12+Calculations!J95) -> 0.19322929 | L12: =Calculations!F95/100 -> 0.29778987 | M12: =LN(Calculations!G95/Calculations!G94) -> 0.080472202 | N12: 0.5 | O12: =O11+(M12/N12) -> 0.52675246 | P12: =F12/EXP(O12) -> 0.014684506 | Q12: =AVERAGE(P10:P12) -> 0.020304331 | R12: =Calculations!J95/( (Calculations!I95/100) + Calculations!J95 ) -> 0.58816448 | S12: =LN(Calculations!J95/Calculations!J94) -> -0.086932671 | T12: =T11+(R12*S12) -> -0.047255827 | U12: =F12/EXP(T12) -> 0.026070416 | V12: =AVERAGE(U10:U12) -> 0.027465638 | W12: =O12+T12 -> 0.47949663 | X12: =F12/EXP(W12) -> 0.015395092 | Y12: =AVERAGE(X10:X12) -> 0.020431117 | AC12: =DATE(YEAR(AC11),MONTH(AC11)+3,1) -> 37865 | AD12: =VLOOKUP(AC12,A$1:Y$152,5) -> 0.061333333 | AE12: =VLOOKUP(AC12,A$1:Y$152,7) -> 0.021251168 | AF12: =VLOOKUP(AC12,A$1:Y$152,17) -> 0.018940974 | AG12: =VLOOKUP(AC12,A$1:Y$152,22) -> 0.020603744 | AH12: =VLOOKUP(AC12,A$1:Y$152,25) -> 0.018344887
A13: =DATE(YEAR(A12),MONTH(A12)+1,1) -> 37196 | B13: ='raw BLS data'!Q30 -> 3538 | C13: ='raw BLS data'!W41 -> 144240 | D13: ='raw BLS data'!J113/100 -> 0.055 | E13: =AVERAGE(D11:D13) -> 0.052666667 | F13: =B13/C13 -> 0.024528564 | G13: =AVERAGE(F11:F13) -> 0.025739075 | H13: =IF( $A13<=$A$106, F13, NA() ) -> 0.024528564 | I13: =IF( $A13>$A$106, F13, NA() ) -> #N/A | J13: =F13/D13 -> 0.44597388 | K13: =F13/(D13+Calculations!J96) -> 0.1851318 | L13: =Calculations!F96/100 -> 0.28438504 | M13: =LN(Calculations!G96/Calculations!G95) -> -0.089175212 | N13: 0.5 | O13: =O12+(M13/N13) -> 0.34840203 | P13: =F13/EXP(O13) -> 0.01731263 | Q13: =AVERAGE(P11:P13) -> 0.017098392 | R13: =Calculations!J96/( (Calculations!I96/100) + Calculations!J96 ) -> 0.58488198 | S13: =LN(Calculations!J96/Calculations!J95) -> 0.023505875 | T13: =T12+(R13*S13) -> -0.033507665 | U13: =F13/EXP(T13) -> 0.025364383 | V13: =AVERAGE(U11:U13) -> 0.026382924 | W13: =O13+T13 -> 0.31489437 | X13: =F13/EXP(W13) -> 0.017902564 | Y13: =AVERAGE(X11:X13) -> 0.017507021 | AC13: =DATE(YEAR(AC12),MONTH(AC12)+3,1) -> 37956 | AD13: =VLOOKUP(AC13,A$1:Y$152,5) -> 0.058333333 | AE13: =VLOOKUP(AC13,A$1:Y$152,7) -> 0.021979796 | AF13: =VLOOKUP(AC13,A$1:Y$152,17) -> 0.019893856 | AG13: =VLOOKUP(AC13,A$1:Y$152,22) -> 0.022181456 | AH13: =VLOOKUP(AC13,A$1:Y$152,25) -> 0.019923277
A14: =DATE(YEAR(A13),MONTH(A13)+1,1) -> 37226 | B14: ='raw BLS data'!Q31 -> 3559 | C14: ='raw BLS data'!W42 -> 144305 | D14: ='raw BLS data'!J114/100 -> 0.057 | E14: =AVERAGE(D12:D14) -> 0.055 | F14: =B14/C14 -> 0.02466304 | G14: =AVERAGE(F12:F14) -> 0.024686232 | H14: =IF( $A14<=$A$106, F14, NA() ) -> 0.02466304 | I14: =IF( $A14>$A$106, F14, NA() ) -> #N/A | J14: =F14/D14 -> 0.43268491 | K14: =F14/(D14+Calculations!J97) -> 0.17579262 | L14: =Calculations!F97/100 -> 0.26075127 | M14: =LN(Calculations!G97/Calculations!G96) -> -0.0050213675 | N14: 0.5 | O14: =O13+(M14/N14) -> 0.3383593 | P14: =F14/EXP(O14) -> 0.017583245 | Q14: =AVERAGE(P12:P14) -> 0.016526794 | R14: =Calculations!J97/( (Calculations!I97/100) + Calculations!J97 ) -> 0.59371678 | S14: =LN(Calculations!J97/Calculations!J96) -> 0.072222775 | T14: =T13+(R14*S14) -> 0.0093722079 | U14: =F14/EXP(T14) -> 0.024432973 | V14: =AVERAGE(U12:U14) -> 0.025289258 | W14: =O14+T14 -> 0.3477315 | X14: =F14/EXP(W14) -> 0.017419221 | Y14: =AVERAGE(X12:X14) -> 0.016905626 | AC14: =DATE(YEAR(AC13),MONTH(AC13)+3,1) -> 38047 | AD14: =VLOOKUP(AC14,A$1:Y$152,5) -> 0.057 | AE14: =VLOOKUP(AC14,A$1:Y$152,7) -> 0.022999187 | AF14: =VLOOKUP(AC14,A$1:Y$152,17) -> 0.021539001 | AG14: =VLOOKUP(AC14,A$1:Y$152,22) -> 0.020764174 | AH14: =VLOOKUP(AC14,A$1:Y$152,25) -> 0.019389072
A15: =DATE(YEAR(A14),MONTH(A14)+1,1) -> 37257 | B15: ='raw BLS data'!Q32 -> 3572 | C15: ='raw BLS data'!W43 -> 143883 | D15: ='raw BLS data'!J115/100 -> 0.057 | E15: =AVERAGE(D13:D15) -> 0.056333333 | F15: =B15/C15 -> 0.024825726 | G15: =AVERAGE(F13:F15) -> 0.024672443 | H15: =IF( $A15<=$A$106, F15, NA() ) -> 0.024825726 | I15: =IF( $A15>$A$106, F15, NA() ) -> #N/A | J15: =F15/D15 -> 0.43553906 | K15: =F15/(D15+Calculations!J98) -> 0.1840737 | L15: =Calculations!F98/100 -> 0.29921149 | M15: =LN(Calculations!G98/Calculations!G97) -> 0.042975773 | N15: 0.5 | O15: =O14+(M15/N15) -> 0.42431084 | P15: =F15/EXP(O15) -> 0.016241499 | Q15: =AVERAGE(P13:P15) -> 0.017045791 | R15: =Calculations!J98/( (Calculations!I98/100) + Calculations!J98 ) -> 0.57736579 | S15: =LN(Calculations!J98/Calculations!J97) -> -0.067382908 | T15: =T14+(R15*S15) -> -0.029532378 | U15: =F15/EXP(T15) -> 0.025569823 | V15: =AVERAGE(U13:U15) -> 0.025122393 | W15: =O15+T15 -> 0.39477846 | X15: =F15/EXP(W15) -> 0.016728302 | Y15: =AVERAGE(X13:X15) -> 0.017350029 | AC15: =DATE(YEAR(AC14),MONTH(AC14)+3,1) -> 38139 | AD15: =VLOOKUP(AC15,A$1:Y$152,5) -> 0.056 | AE15: =VLOOKUP(AC15,A$1:Y$152,7) -> 0.023941772 | AF15: =VLOOKUP(AC15,A$1:Y$152,17) -> 0.021615647 | AG15: =VLOOKUP(AC15,A$1:Y$152,22) -> 0.023530745 | AH15: =VLOOKUP(AC15,A$1:Y$152,25) -> 0.021280804
A16: =DATE(YEAR(A15),MONTH(A15)+1,1) -> 37288 | B16: ='raw BLS data'!Q33 -> 3370 | C16: ='raw BLS data'!W44 -> 144653 | D16: ='raw BLS data'!J116/100 -> 0.057 | E16: =AVERAGE(D14:D16) -> 0.057 | F16: =B16/C16 -> 0.023297132 | G16: =AVERAGE(F14:F16) -> 0.024261966 | H16: =IF( $A16<=$A$106, F16, NA() ) -> 0.023297132 | I16: =IF( $A16>$A$106, F16, NA() ) -> #N/A | J16: =F16/D16 -> 0.40872161 | K16: =F16/(D16+Calculations!J99) -> 0.17033778 | L16: =Calculations!F99/100 -> 0.27445278 | M16: =LN(Calculations!G99/Calculations!G98) -> -0.079610499 | N16: 0.5 | O16: =O15+(M16/N16) -> 0.26508984 | P16: =F16/EXP(O16) -> 0.017872092 | Q16: =AVERAGE(P14:P16) -> 0.017232279 | R16: =Calculations!J99/( (Calculations!I99/100) + Calculations!J99 ) -> 0.58324253 | S16: =LN(Calculations!J99/Calculations!J98) -> 0.024129687 | T16: =T15+(R16*S16) -> -0.015458918 | U16: =F16/EXP(T16) -> 0.023660078 | V16: =AVERAGE(U14:U16) -> 0.024554291 | W16: =O16+T16 -> 0.24963092 | X16: =F16/EXP(W16) -> 0.018150522 | Y16: =AVERAGE(X14:X16) -> 0.017432682 | AC16: =DATE(YEAR(AC15),MONTH(AC15)+3,1) -> 38231 | AD16: =VLOOKUP(AC16,A$1:Y$152,5) -> 0.054333333 | AE16: =VLOOKUP(AC16,A$1:Y$152,7) -> 0.025264732 | AF16: =VLOOKUP(AC16,A$1:Y$152,17) -> 0.022326426 | AG16: =VLOOKUP(AC16,A$1:Y$152,22) -> 0.024226657 | AH16: =VLOOKUP(AC16,A$1:Y$152,25) -> 0.021404702
... A51: =DATE(YEAR(A50),MONTH(A50)+1,1) -> 38353 | B51: ='raw BLS data'!Q68 -> 3638 | C51: ='raw BLS data'!W79 -> 148029 | D51: ='raw BLS data'!J151/100 -> 0.053 | E51: =AVERAGE(D49:D51) -> 0.053666667 | F51: =B51/C51 -> 0.024576265 | G51: =AVERAGE(F49:F51) -> 0.024376286 | H51: =IF( $A51<=$A$106, F51, NA() ) -> 0.024576265 | I51: =IF( $A51>$A$106, F51, NA() ) -> #N/A | J51: =F51/D51 -> 0.46370312 | K51: =F51/(D51+Calculations!J134) -> 0.17833559 | L51: =Calculations!F134/100 -> 0.25244729 | M51: =LN(Calculations!G134/Calculations!G133) -> -0.065208595 | N51: 0.5 | O51: =O50+(M51/N51) -> 0.016845719 | P51: =F51/EXP(O51) -> 0.024165728 | Q51: =AVERAGE(P49:P51) -> 0.022890479 | R51: =Calculations!J134/( (Calculations!I134/100) + Calculations!J134 ) -> 0.61540999 | S51: =LN(Calculations!J134/Calculations!J133) -> -0.045083747 | T51: =T50+(R51*S51) -> 0.065779662 | U51: =F51/EXP(T51) -> 0.02301167 | V51: =AVERAGE(U49:U51) -> 0.022580586 | W51: =O51+T51 -> 0.082625382 | X51: =F51/EXP(W51) -> 0.022627269 | Y51: =AVERAGE(X49:X51) -> 0.021220004 | AC51: =DATE(YEAR(AC50),MONTH(AC50)+3,1) -> 41426 | AD51: =VLOOKUP(AC51,A$1:Y$152,5) -> 0.075666667 | AE51: =VLOOKUP(AC51,A$1:Y$152,7) -> 0.024801994 | AF51: =VLOOKUP(AC51,A$1:Y$152,17) -> 0.019175054 | AG51: =VLOOKUP(AC51,A$1:Y$152,22) -> 0.02238173 | AH51: =VLOOKUP(AC51,A$1:Y$152,25) -> 0.017303759
A52: =DATE(YEAR(A51),MONTH(A51)+1,1) -> 38384 | B52: ='raw BLS data'!Q69 -> 3757 | C52: ='raw BLS data'!W80 -> 148364 | D52: ='raw BLS data'!J152/100 -> 0.054 | E52: =AVERAGE(D50:D52) -> 0.053666667 | F52: =B52/C52 -> 0.025322855 | G52: =AVERAGE(F50:F52) -> 0.025206199 | H52: =IF( $A52<=$A$106, F52, NA() ) -> 0.025322855 | I52: =IF( $A52>$A$106, F52, NA() ) -> #N/A | J52: =F52/D52 -> 0.46894175 | K52: =F52/(D52+Calculations!J135) -> 0.18374444 | L52: =Calculations!F135/100 -> 0.24670089 | M52: =LN(Calculations!G135/Calculations!G134) -> -0.011178771 | N52: 0.5 | O52: =O51+(M52/N52) -> -0.0055118227 | P52: =F52/EXP(O52) -> 0.025462815 | Q52: =AVERAGE(P50:P52) -> 0.023942059 | R52: =Calculations!J135/( (Calculations!I135/100) + Calculations!J135 ) -> 0.60817214 | S52: =LN(Calculations!J135/Calculations!J134) -> -0.011783375 | T52: =T51+(R52*S52) -> 0.058613341 | U52: =F52/EXP(T52) -> 0.023881259 | V52: =AVERAGE(U50:U52) -> 0.023438686 | W52: =O52+T52 -> 0.053101519 | X52: =F52/EXP(W52) -> 0.024013251 | Y52: =AVERAGE(X50:X52) -> 0.022285417
A53: =DATE(YEAR(A52),MONTH(A52)+1,1) -> 38412 | B53: ='raw BLS data'!Q70 -> 3916 | C53: ='raw BLS data'!W81 -> 148391 | D53: ='raw BLS data'!J153/100 -> 0.052 | E53: =AVERAGE(D51:D53) -> 0.053 | F53: =B53/C53 -> 0.026389741 | G53: =AVERAGE(F51:F53) -> 0.02542962 | H53: =IF( $A53<=$A$106, F53, NA() ) -> 0.026389741 | I53: =IF( $A53>$A$106, F53, NA() ) -> #N/A | J53: =F53/D53 -> 0.50749501 | K53: =F53/(D53+Calculations!J136) -> 0.1879308 | L53: =Calculations!F136/100 -> 0.28156617 | M53: =LN(Calculations!G136/Calculations!G135) -> 0.0079560708 | N53: 0.5 | O53: =O52+(M53/N53) -> 0.010400319 | P53: =F53/EXP(O53) -> 0.026116701 | Q53: =AVERAGE(P51:P53) -> 0.025248415 | R53: =Calculations!J136/( (Calculations!I136/100) + Calculations!J136 ) -> 0.62968936 | S53: =LN(Calculations!J136/Calculations!J135) -> 0.053508721 | T53: =T52+(R53*S53) -> 0.092307214 | U53: =F53/EXP(T53) -> 0.024062825 | V53: =AVERAGE(U51:U53) -> 0.023651918 | W53: =O53+T53 -> 0.10270753 | X53: =F53/EXP(W53) -> 0.023813861 | Y53: =AVERAGE(X51:X53) -> 0.023484794
A54: =DATE(YEAR(A53),MONTH(A53)+1,1) -> 38443 | B54: ='raw BLS data'!Q71 -> 4057 | C54: ='raw BLS data'!W82 -> 148926 | D54: ='raw BLS data'!J154/100 -> 0.052 | E54: =AVERAGE(D52:D54) -> 0.052666667 | F54: =B54/C54 -> 0.027241717 | G54: =AVERAGE(F52:F54) -> 0.026318104 | H54: =IF( $A54<=$A$106, F54, NA() ) -> 0.027241717 | I54: =IF( $A54>$A$106, F54, NA() ) -> #N/A | J54: =F54/D54 -> 0.52387918 | K54: =F54/(D54+Calculations!J137) -> 0.20526018 | L54: =Calculations!F137/100 -> 0.24824831 | M54: =LN(Calculations!G137/Calculations!G136) -> -0.045043717 | N54: 0.5 | O54: =O53+(M54/N54) -> -0.079687116 | P54: =F54/EXP(O54) -> 0.029501368 | Q54: =AVERAGE(P52:P54) -> 0.027026961 | R54: =Calculations!J137/( (Calculations!I137/100) + Calculations!J137 ) -> 0.60819175 | S54: =LN(Calculations!J137/Calculations!J136) -> -0.09116673 | T54: =T53+(R54*S54) -> 0.03686036 | U54: =F54/EXP(T54) -> 0.026255859 | V54: =AVERAGE(U52:U54) -> 0.024733314 | W54: =O54+T54 -> -0.042826755 | X54: =F54/EXP(W54) -> 0.028433735 | Y54: =AVERAGE(X52:X54) -> 0.025420282
