Workbook

Sheet raw CPS data
A1: Data extracted on: October 9, 2013 (10:27:31 AM)
A4: Labor Force Statistics from the Current Population Survey
A5: Original Data Value
A7: Download:
A9: Series ID | B9: 17533 | C9: 17564 | D9: 17593 | E9: 17624 | F9: 17654 | G9: 17685 | H9: 17715 | I9: 17746 | J9: 17777 | K9: 17807 | L9: 17838 | M9: 17868 | N9: Annual 1948 | O9: 17899 | P9: 17930 | Q9: 17958 | R9: 17989 | S9: 18019 | T9: 18050 | U9: 18080 | V9: 18111 | W9: 18142 | X9: 18172 | Y9: 18203 | Z9: 18233 | AA9: Annual 1949 | AB9: 18264 | AC9: 18295 | AD9: 18323 | AE9: 18354 | AF9: 18384 | AG9: 18415 | AH9: 18445 | AI9: 18476 | AJ9: 18507 | AK9: 18537 | AL9: 18568 | AM9: 18598 | AN9: Annual 1950 | AO9: 18629 | AP9: 18660 | AQ9: 18688 | AR9: 18719 | AS9: 18749 | AT9: 18780 | AU9: 18810 | AV9: 18841 | AW9: 18872 | AX9: 18902 | AY9: 18933 | AZ9: 18963 | BA9: Annual 1951 | BB9: 18994 | BC9: 19025 | BD9: 19054 | BE9: 19085 | BF9: 19115 | BG9: 19146 | BH9: 19176 | BI9: 19207 | BJ9: 19238 | BK9: 19268 | BL9: 19299 | BM9: 19329 | BN9: Annual 1952 | BO9: 19360 | BP9: 19391 | BQ9: 19419 | BR9: 19450 | BS9: 19480 | BT9: 19511 | BU9: 19541 | BV9: 19572 | BW9: 19603 | BX9: 19633 | BY9: 19664 | BZ9: 19694 | CA9: Annual 1953 | CB9: 19725 | CC9: 19756 | CD9: 19784 | CE9: 19815 | CF9: 19845 | CG9: 19876 | CH9: 19906 | CI9: 19937 | CJ9: 19968 | CK9: 19998 | CL9: 20029 | CM9: 20059 | CN9: Annual 1954 | CO9: 20090 | CP9: 20121 | CQ9: 20149 | CR9: 20180 | CS9: 20210 | CT9: 20241 | CU9: 20271 | CV9: 20302 | CW9: 20333 | CX9: 20363 | CY9: 20394 | CZ9: 20424 | DA9: Annual 1955 | DB9: 20455 | DC9: 20486 | DD9: 20515 | DE9: 20546 | DF9: 20576 | DG9: 20607 | DH9: 20637 | DI9: 20668 | DJ9: 20699 | DK9: 20729 | DL9: 20760 | DM9: 20790 | DN9: Annual 1956 | DO9: 20821 | DP9: 20852 | DQ9: 20880 | DR9: 20911 | DS9: 20941 | DT9: 20972 | DU9: 21002 | DV9: 21033 | DW9: 21064 | DX9: 21094 | DY9: 21125 | DZ9: 21155 | EA9: Annual 1957 | EB9: 21186 | EC9: 21217 | ED9: 21245 | EE9: 21276 | EF9: 21306 | EG9: 21337 | EH9: 21367 | EI9: 21398 | EJ9: 21429 | EK9: 21459 | EL9: 21490 | EM9: 21520 | EN9: Annual 1958 | EO9: 21551 | EP9: 21582 | EQ9: 21610 | ER9: 21641 | ES9: 21671 | ET9: 21702 | EU9: 21732 | EV9: 21763 | EW9: 21794 | EX9: 21824 | EY9: 21855 | EZ9: 21885 | FA9: Annual 1959 | FB9: 21916 | FC9: 21947 | FD9: 21976 | FE9: 22007 | FF9: 22037 | FG9: 22068 | FH9: 22098 | FI9: 22129 | FJ9: 22160 | FK9: 22190 | FL9: 22221 | FM9: 22251 | FN9: Annual 1960 | FO9: 22282 | FP9: 22313 | FQ9: 22341 | FR9: 22372 | FS9: 22402 | FT9: 22433 | FU9: 22463 | FV9: 22494 | FW9: 22525 | FX9: 22555 | FY9: 22586 | FZ9: 22616 | GA9: Annual 1961 | GB9: 22647 | GC9: 22678 | GD9: 22706 | GE9: 22737 | GF9: 22767 | GG9: 22798 | GH9: 22828 | GI9: 22859 | GJ9: 22890 | GK9: 22920 | GL9: 22951 | GM9: 22981 | GN9: Annual 1962 | GO9: 23012 | GP9: 23043 | GQ9: 23071 | GR9: 23102 | GS9: 23132 | GT9: 23163 | GU9: 23193 | GV9: 23224 | GW9: 23255 | GX9: 23285 | GY9: 23316 | GZ9: 23346 | HA9: Annual 1963 | HB9: 23377 | HC9: 23408 | HD9: 23437 | HE9: 23468 | HF9: 23498 | HG9: 23529 | HH9: 23559 | HI9: 23590 | HJ9: 23621 | HK9: 23651 | HL9: 23682 | HM9: 23712 | HN9: Annual 1964 | HO9: 23743 | HP9: 23774 | HQ9: 23802 | HR9: 23833 | HS9: 23863 | HT9: 23894 | HU9: 23924 | HV9: 23955 | HW9: 23986 | HX9: 24016 | HY9: 24047 | HZ9: 24077 | IA9: Annual 1965 | IB9: 24108 | IC9: 24139 | ID9: 24167 | IE9: 24198 | IF9: 24228 | IG9: 24259 | IH9: 24289 | II9: 24320 | IJ9: 24351 | IK9: 24381 | IL9: 24412 | IM9: 24442 | IN9: Annual 1966 | IO9: 24473 | IP9: 24504 | IQ9: 24532 | IR9: 24563 | IS9: 24593 | IT9: 24624 | IU9: 24654 | IV9: 24685 | IW9: 24716 | IX9: 24746 | IY9: 24777 | IZ9: 24807 | JA9: Annual 1967 | JB9: 24838 | JC9: 24869 | JD9: 24898 | JE9: 24929 | JF9: 24959 | JG9: 24990 | JH9: 25020 | JI9: 25051 | JJ9: 25082 | JK9: 25112 | JL9: 25143 | JM9: 25173 | JN9: Annual 1968 | JO9: 25204 | JP9: 25235 | JQ9: 25263 | JR9: 25294 | JS9: 25324 | JT9: 25355 | JU9: 25385 | JV9: 25416 | JW9: 25447 | JX9: 25477 | JY9: 25508 | JZ9: 25538 | KA9: Annual 1969 | KB9: 25569 | KC9: 25600 | KD9: 25628 | KE9: 25659 | KF9: 25689 | KG9: 25720 | KH9: 25750 | KI9: 25781 | KJ9: 25812 | KK9: 25842 | KL9: 25873 | KM9: 25903 | KN9: Annual 1970 | KO9: 25934 | KP9: 25965 | KQ9: 25993 | KR9: 26024 | KS9: 26054 | KT9: 26085 | KU9: 26115 | KV9: 26146 | KW9: 26177 | KX9: 26207 | KY9: 26238 | KZ9: 26268 | LA9: Annual 1971 | LB9: 26299 | LC9: 26330 | LD9: 26359 | LE9: 26390 | LF9: 26420 | LG9: 26451 | LH9: 26481 | LI9: 26512 | LJ9: 26543 | LK9: 26573 | LL9: 26604 | LM9: 26634 | LN9: Annual 1972 | LO9: 26665 | LP9: 26696 | LQ9: 26724 | LR9: 26755 | LS9: 26785 | LT9: 26816 | LU9: 26846 | LV9: 26877 | LW9: 26908 | LX9: 26938 | LY9: 26969 | LZ9: 26999 | MA9: Annual 1973 | MB9: 27030 | MC9: 27061 | MD9: 27089 | ME9: 27120 | MF9: 27150 | MG9: 27181 | MH9: 27211 | MI9: 27242 | MJ9: 27273 | MK9: 27303 | ML9: 27334 | MM9: 27364 | MN9: Annual 1974 | MO9: 27395 | MP9: 27426 | MQ9: 27454 | MR9: 27485 | MS9: 27515 | MT9: 27546 | MU9: 27576 | MV9: 27607 | MW9: 27638 | MX9: 27668 | MY9: 27699 | MZ9: 27729 | NA9: Annual 1975 | NB9: 27760 | NC9: 27791 | ND9: 27820 | NE9: 27851 | NF9: 27881 | NG9: 27912 | NH9: 27942 | NI9: 27973 | NJ9: 28004 | NK9: 28034 | NL9: 28065 | NM9: 28095 | NN9: Annual 1976 | NO9: 28126 | NP9: 28157 | NQ9: 28185 | NR9: 28216 | NS9: 28246 | NT9: 28277 | NU9: 28307 | NV9: 28338 | NW9: 28369 | NX9: 28399 | NY9: 28430 | NZ9: 28460 | OA9: Annual 1977 | OB9: 28491 | OC9: 28522 | OD9: 28550 | OE9: 28581 | OF9: 28611 | OG9: 28642 | OH9: 28672 | OI9: 28703 | OJ9: 28734 | OK9: 28764 | OL9: 28795 | OM9: 28825 | ON9: Annual 1978 | OO9: 28856 | OP9: 28887 | OQ9: 28915 | OR9: 28946 | OS9: 28976 | OT9: 29007 | OU9: 29037 | OV9: 29068 | OW9: 29099 | OX9: 29129 | OY9: 29160 | OZ9: 29190 | PA9: Annual 1979 | PB9: 29221 | PC9: 29252 | PD9: 29281 | PE9: 29312 | PF9: 29342 | PG9: 29373 | PH9: 29403 | PI9: 29434 | PJ9: 29465 | PK9: 29495 | PL9: 29526 | PM9: 29556 | PN9: Annual 1980 | PO9: 29587 | PP9: 29618 | PQ9: 29646 | PR9: 29677 | PS9: 29707 | PT9: 29738 | PU9: 29768 | PV9: 29799 | PW9: 29830 | PX9: 29860 | PY9: 29891 | PZ9: 29921 | QA9: Annual 1981 | QB9: 29952 | QC9: 29983 | QD9: 30011 | QE9: 30042 | QF9: 30072 | QG9: 30103 | QH9: 30133 | QI9: 30164 | QJ9: 30195 | QK9: 30225 | QL9: 30256 | QM9: 30286 | QN9: Annual 1982 | QO9: 30317 | QP9: 30348 | QQ9: 30376 | QR9: 30407 | QS9: 30437 | QT9: 30468 | QU9: 30498 | QV9: 30529 | QW9: 30560 | QX9: 30590 | QY9: 30621 | QZ9: 30651 | RA9: Annual 1983 | RB9: 30682 | RC9: 30713 | RD9: 30742 | RE9: 30773 | RF9: 30803 | RG9: 30834 | RH9: 30864 | RI9: 30895 | RJ9: 30926 | RK9: 30956 | RL9: 30987 | RM9: 31017 | RN9: Annual 1984 | RO9: 31048 | RP9: 31079 | RQ9: 31107 | RR9: 31138 | RS9: 31168 | RT9: 31199 | RU9: 31229 | RV9: 31260 | RW9: 31291 | RX9: 31321 | RY9: 31352 | RZ9: 31382 | SA9: Annual 1985 | SB9: 31413 | SC9: 31444 | SD9: 31472 | SE9: 31503 | SF9: 31533 | SG9: 31564 | SH9: 31594 | SI9: 31625 | SJ9: 31656 | SK9: 31686 | SL9: 31717 | SM9: 31747 | SN9: Annual 1986 | SO9: 31778 | SP9: 31809 | SQ9: 31837 | SR9: 31868 | SS9: 31898 | ST9: 31929 | SU9: 31959 | SV9: 31990 | SW9: 32021 | SX9: 32051 | SY9: 32082 | SZ9: 32112 | TA9: Annual 1987 | TB9: 32143 | TC9: 32174 | TD9: 32203 | TE9: 32234 | TF9: 32264 | TG9: 32295 | TH9: 32325 | TI9: 32356 | TJ9: 32387 | TK9: 32417 | TL9: 32448 | TM9: 32478 | TN9: Annual 1988 | TO9: 32509 | TP9: 32540 | TQ9: 32568 | TR9: 32599 | TS9: 32629 | TT9: 32660 | TU9: 32690 | TV9: 32721 | TW9: 32752 | TX9: 32782 | TY9: 32813 | TZ9: 32843 | UA9: Annual 1989 | UB9: 32874 | UC9: 32905 | UD9: 32933 | UE9: 32964 | UF9: 32994 | UG9: 33025 | UH9: 33055 | UI9: 33086 | UJ9: 33117 | UK9: 33147 | UL9: 33178 | UM9: 33208 | UN9: Annual 1990 | UO9: 33239 | UP9: 33270 | UQ9: 33298 | UR9: 33329 | US9: 33359 | UT9: 33390 | UU9: 33420 | UV9: 33451 | UW9: 33482 | UX9: 33512 | UY9: 33543 | UZ9: 33573 | VA9: Annual 1991 | VB9: 33604 | VC9: 33635 | VD9: 33664 | VE9: 33695 | VF9: 33725 | VG9: 33756 | VH9: 33786 | VI9: 33817 | VJ9: 33848 | VK9: 33878 | VL9: 33909 | VM9: 33939 | VN9: Annual 1992 | VO9: 33970 | VP9: 34001 | VQ9: 34029 | VR9: 34060 | VS9: 34090 | VT9: 34121 | VU9: 34151 | VV9: 34182 | VW9: 34213 | VX9: 34243 | VY9: 34274 | VZ9: 34304 | WA9: Annual 1993 | WB9: 34335 | WC9: 34366 | WD9: 34394 | WE9: 34425 | WF9: 34455 | WG9: 34486 | WH9: 34516 | WI9: 34547 | WJ9: 34578 | WK9: 34608 | WL9: 34639 | WM9: 34669 | WN9: Annual 1994 | WO9: 34700 | WP9: 34731 | WQ9: 34759 | WR9: 34790 | WS9: 34820 | WT9: 34851 | WU9: 34881 | WV9: 34912 | WW9: 34943 | WX9: 34973 | WY9: 35004 | WZ9: 35034 | XA9: Annual 1995 | XB9: 35065 | XC9: 35096 | XD9: 35125 | XE9: 35156 | XF9: 35186 | XG9: 35217 | XH9: 35247 | XI9: 35278 | XJ9: 35309 | XK9: 35339 | XL9: 35370 | XM9: 35400 | XN9: Annual 1996 | XO9: 35431 | XP9: 35462 | XQ9: 35490 | XR9: 35521 | XS9: 35551 | XT9: 35582 | XU9: 35612 | XV9: 35643 | XW9: 35674 | XX9: 35704 | XY9: 35735 | XZ9: 35765 | YA9: Annual 1997 | YB9: 35796 | YC9: 35827 | YD9: 35855 | YE9: 35886 | YF9: 35916 | YG9: 35947 | YH9: 35977 | YI9: 36008 | YJ9: 36039 | YK9: 36069 | YL9: 36100 | YM9: 36130 | YN9: Annual 1998 | YO9: 36161 | YP9: 36192 | YQ9: 36220 | YR9: 36251 | YS9: 36281 | YT9: 36312 | YU9: 36342 | YV9: 36373 | YW9: 36404 | YX9: 36434 | YY9: 36465 | YZ9: 36495 | ZA9: Annual 1999 | ZB9: 36526 | ZC9: 36557 | ZD9: 36586 | ZE9: 36617 | ZF9: 36647 | ZG9: 36678 | ZH9: 36708 | ZI9: 36739 | ZJ9: 36770 | ZK9: 36800 | ZL9: 36831 | ZM9: 36861 | ZN9: Annual 2000 | ZO9: 36892 | ZP9: 36923 | ZQ9: 36951 | ZR9: 36982 | ZS9: 37012 | ZT9: 37043 | ZU9: 37073 | ZV9: 37104 | ZW9: 37135 | ZX9: 37165 | ZY9: 37196 | ZZ9: 37226 | AAA9: Annual 2001 | AAB9: 37257 | AAC9: 37288 | AAD9: 37316 | AAE9: 37347 | AAF9: 37377 | AAG9: 37408 | AAH9: 37438 | AAI9: 37469 | AAJ9: 37500 | AAK9: 37530 | AAL9: 37561 | AAM9: 37591 | AAN9: Annual 2002 | AAO9: 37622 | AAP9: 37653 | AAQ9: 37681 | AAR9: 37712 | AAS9: 37742 | AAT9: 37773 | AAU9: 37803 | AAV9: 37834 | AAW9: 37865 | AAX9: 37895 | AAY9: 37926 | AAZ9: 37956 | ABA9: Annual 2003 | ABB9: 37987 | ABC9: 38018 | ABD9: 38047 | ABE9: 38078 | ABF9: 38108 | ABG9: 38139 | ABH9: 38169 | ABI9: 38200 | ABJ9: 38231 | ABK9: 38261 | ABL9: 38292 | ABM9: 38322 | ABN9: Annual 2004 | ABO9: 38353 | ABP9: 38384 | ABQ9: 38412 | ABR9: 38443 | ABS9: 38473 | ABT9: 38504 | ABU9: 38534 | ABV9: 38565 | ABW9: 38596 | ABX9: 38626 | ABY9: 38657 | ABZ9: 38687 | ACA9: Annual 2005 | ACB9: 38718 | ACC9: 38749 | ACD9: 38777 | ACE9: 38808 | ACF9: 38838 | ACG9: 38869 | ACH9: 38899 | ACI9: 38930 | ACJ9: 38961 | ACK9: 38991 | ACL9: 39022 | ACM9: 39052 | ACN9: Annual 2006 | ACO9: 39083 | ACP9: 39114 | ACQ9: 39142 | ACR9: 39173 | ACS9: 39203 | ACT9: 39234 | ACU9: 39264 | ACV9: 39295 | ACW9: 39326 | ACX9: 39356 | ACY9: 39387 | ACZ9: 39417 | ADA9: Annual 2007 | ADB9: 39448 | ADC9: 39479 | ADD9: 39508 | ADE9: 39539 | ADF9: 39569 | ADG9: 39600 | ADH9: 39630 | ADI9: 39661 | ADJ9: 39692 | ADK9: 39722 | ADL9: 39753 | ADM9: 39783 | ADN9: Annual 2008 | ADO9: 39814 | ADP9: 39845 | ADQ9: 39873 | ADR9: 39904 | ADS9: 39934 | ADT9: 39965 | ADU9: 39995 | ADV9: 40026 | ADW9: 40057 | ADX9: 40087 | ADY9: 40118 | ADZ9: 40148 | AEA9: Annual 2009 | AEB9: 40179 | AEC9: 40210 | AED9: 40238 | AEE9: 40269 | AEF9: 40299 | AEG9: 40330 | AEH9: 40360 | AEI9: 40391 | AEJ9: 40422 | AEK9: 40452 | AEL9: 40483 | AEM9: 40513 | AEN9: Annual 2010 | AEO9: 40544 | AEP9: 40575 | AEQ9: 40603 | AER9: 40634 | AES9: 40664 | AET9: 40695 | AEU9: 40725 | AEV9: 40756 | AEW9: 40787 | AEX9: 40817 | AEY9: 40848 | AEZ9: 40878 | AFA9: Annual 2011 | AFB9: 40909 | AFC9: 40940 | AFD9: 40969 | AFE9: 41000 | AFF9: 41030 | AFG9: 41061 | AFH9: 41091 | AFI9: 41122 | AFJ9: 41153 | AFK9: 41183 | AFL9: 41214 | AFM9: 41244 | AFN9: Annual 2012 | AFO9: 41275 | AFP9: 41306 | AFQ9: 41334 | AFR9: 41365 | AFS9: 41395 | AFT9: 41426 | AFU9: 41456 | AFV9: 41487 | AFW9: 41518 | AFX9: 41548 | AFY9: 41579 | AFZ9: 41609 | AGA9: Annual 2013
A10: LNS11000000 | B10: 60095 | C10: 60524 | D10: 60070 | E10: 60677 | F10: 59972 | G10: 60957 | H10: 61181 | I10: 60806 | J10: 60815 | K10: 60646 | L10: 60702 | M10: 61169 | O10: 60771 | P10: 61057 | Q10: 61073 | R10: 61007 | S10: 61259 | T10: 60948 | U10: 61301 | V10: 61590 | W10: 61633 | X10: 62185 | Y10: 62005 | Z10: 61908 | AB10: 61661 | AC10: 61687 | AD10: 61604 | AE10: 62158 | AF10: 62083 | AG10: 62419 | AH10: 62121 | AI10: 62596 | AJ10: 62349 | AK10: 62428 | AL10: 62286 | AM10: 62068 | AO10: 61941 | AP10: 61778 | AQ10: 62526 | AR10: 61808 | AS10: 62044 | AT10: 61615 | AU10: 62106 | AV10: 61927 | AW10: 61780 | AX10: 62204 | AY10: 62014 | AZ10: 62457 | BB10: 62432 | BC10: 62419 | BD10: 61721 | BE10: 61720 | BF10: 62058 | BG10: 62103 | BH10: 61962 | BI10: 61877 | BJ10: 62457 | BK10: 61971 | BL10: 62491 | BM10: 62621 | BO10: 63439 | BP10: 63520 | BQ10: 63657 | BR10: 63167 | BS10: 62615 | BT10: 63063 | BU10: 63057 | BV10: 62816 | BW10: 62727 | BX10: 62867 | BY10: 62949 | BZ10: 62795 | CB10: 63101 | CC10: 63994 | CD10: 63793 | CE10: 63934 | CF10: 63675 | CG10: 63343 | CH10: 63302 | CI10: 63707 | CJ10: 64209 | CK10: 63936 | CL10: 63759 | CM10: 63312 | CO10: 63910 | CP10: 63696 | CQ10: 63882 | CR10: 64564 | CS10: 64381 | CT10: 64482 | CU10: 65145 | CV10: 65581 | CW10: 65628 | CX10: 65821 | CY10: 66037 | CZ10: 66445 | DB10: 66419 | DC10: 66124 | DD10: 66175 | DE10: 66264 | DF10: 66722 | DG10: 66702 | DH10: 66752 | DI10: 66673 | DJ10: 66714 | DK10: 66546 | DL10: 66657 | DM10: 66700 | DO10: 66428 | DP10: 66879 | DQ10: 66913 | DR10: 66647 | DS10: 66695 | DT10: 67052 | DU10: 67336 | DV10: 66706 | DW10: 67064 | DX10: 67066 | DY10: 67123 | DZ10: 67398 | EB10: 67095 | EC10: 67201 | ED10: 67223 | EE10: 67647 | EF10: 67895 | EG10: 67674 | EH10: 67824 | EI10: 68037 | EJ10: 68002 | EK10: 68045 | EL10: 67658 | EM10: 67740 | EO10: 67936 | EP10: 67649 | EQ10: 68068 | ER10: 68339 | ES10: 68178 | ET10: 68278 | EU10: 68539 | EV10: 68432 | EW10: 68545 | EX10: 68821 | EY10: 68533 | EZ10: 68994 | FB10: 68962 | FC10: 68949 | FD10: 68399 | FE10: 69579 | FF10: 69626 | FG10: 69934 | FH10: 69745 | FI10: 69841 | FJ10: 70151 | FK10: 69884 | FL10: 70439 | FM10: 70395 | FO10: 70447 | FP10: 70420 | FQ10: 70703 | FR10: 70267 | FS10: 70452 | FT10: 70878 | FU10: 70536 | FV10: 70534 | FW10: 70217 | FX10: 70492 | FY10: 70376 | FZ10: 70077 | GB10: 70189 | GC10: 70409 | GD10: 70414 | GE10: 70278 | GF10: 70551 | GG10: 70514 | GH10: 70302 | GI10: 70981 | GJ10: 71153 | GK10: 70917 | GL10: 70871 | GM10: 70854 | GO10: 71146 | GP10: 71262 | GQ10: 71423 | GR10: 71697 | GS10: 71832 | GT10: 71626 | GU10: 71956 | GV10: 71786 | GW10: 72131 | GX10: 72281 | GY10: 72418 | GZ10: 72188 | HB10: 72356 | HC10: 72683 | HD10: 72713 | HE10: 73274 | HF10: 73395 | HG10: 73032 | HH10: 73007 | HI10: 73118 | HJ10: 73290 | HK10: 73308 | HL10: 73286 | HM10: 73465 | HO10: 73569 | HP10: 73857 | HQ10: 73949 | HR10: 74228 | HS10: 74466 | HT10: 74412 | HU10: 74761 | HV10: 74616 | HW10: 74502 | HX10: 74838 | HY10: 74797 | HZ10: 75093 | IB10: 75186 | IC10: 74954 | ID10: 75075 | IE10: 75338 | IF10: 75447 | IG10: 75647 | IH10: 75736 | II10: 76046 | IJ10: 76056 | IK10: 76199 | IL10: 76610 | IM10: 76641 | IO10: 76639 | IP10: 76521 | IQ10: 76328 | IR10: 76777 | IS10: 76773 | IT10: 77270 | IU10: 77464 | IV10: 77712 | IW10: 77812 | IX10: 78194 | IY10: 78191 | IZ10: 78491 | JB10: 77578 | JC10: 78230 | JD10: 78256 | JE10: 78270 | JF10: 78847 | JG10: 79120 | JH10: 78970 | JI10: 78811 | JJ10: 78858 | JK10: 78913 | JL10: 79209 | JM10: 79463 | JO10: 79523 | JP10: 80019 | JQ10: 80079 | JR10: 80281 | JS10: 80125 | JT10: 80696 | JU10: 80827 | JV10: 81106 | JW10: 81290 | JX10: 81494 | JY10: 81397 | JZ10: 81624 | KB10: 81981 | KC10: 82151 | KD10: 82498 | KE10: 82727 | KF10: 82483 | KG10: 82484 | KH10: 82901 | KI10: 82880 | KJ10: 82954 | KK10: 83276 | KL10: 83548 | KM10: 83670 | KO10: 83850 | KP10: 83603 | KQ10: 83575 | KR10: 83946 | KS10: 84135 | KT10: 83706 | KU10: 84340 | KV10: 84673 | KW10: 84731 | KX10: 84872 | KY10: 85458 | KZ10: 85625 | LB10: 85978 | LC10: 86036 | LD10: 86611 | LE10: 86614 | LF10: 86809 | LG10: 87006 | LH10: 87143 | LI10: 87517 | LJ10: 87392 | LK10: 87491 | LL10: 87592 | LM10: 87943 | LO10: 87487 | LP10: 88364 | LQ10: 88846 | LR10: 89018 | LS10: 88977 | LT10: 89548 | LU10: 89604 | LV10: 89509 | LW10: 89838 | LX10: 90131 | LY10: 90716 | LZ10: 90890 | MB10: 91199 | MC10: 91485 | MD10: 91453 | ME10: 91287 | MF10: 91596 | MG10: 91868 | MH10: 92212 | MI10: 92059 | MJ10: 92488 | MK10: 92518 | ML10: 92766 | MM10: 92780 | MO10: 93128 | MP10: 92776 | MQ10: 93165 | MR10: 93399 | MS10: 93884 | MT10: 93575 | MU10: 94021 | MV10: 94162 | MW10: 94202 | MX10: 94267 | MY10: 94250 | MZ10: 94409 | NB10: 94934 | NC10: 94998 | ND10: 95215 | NE10: 95746 | NF10: 95847 | NG10: 95885 | NH10: 96583 | NI10: 96741 | NJ10: 96553 | NK10: 96704 | NL10: 97254 | NM10: 97348 | NO10: 97208 | NP10: 97785 | NQ10: 98115 | NR10: 98330 | NS10: 98665 | NT10: 99093 | NU10: 98913 | NV10: 99366 | NW10: 99453 | NX10: 99815 | NY10: 100576 | NZ10: 100491 | OB10: 100873 | OC10: 100837 | OD10: 101092 | OE10: 101574 | OF10: 101896 | OG10: 102371 | OH10: 102399 | OI10: 102511 | OJ10: 102795 | OK10: 103080 | OL10: 103562 | OM10: 103809 | OO10: 104057 | OP10: 104502 | OQ10: 104589 | OR10: 104172 | OS10: 104171 | OT10: 104638 | OU10: 105002 | OV10: 105096 | OW10: 105530 | OX10: 105700 | OY10: 105812 | OZ10: 106258 | PB10: 106562 | PC10: 106697 | PD10: 106442 | PE10: 106591 | PF10: 106929 | PG10: 106780 | PH10: 107159 | PI10: 107105 | PJ10: 107098 | PK10: 107405 | PL10: 107568 | PM10: 107352 | PO10: 108026 | PP10: 108242 | PQ10: 108553 | PR10: 108925 | PS10: 109222 | PT10: 108396 | PU10: 108556 | PV10: 108725 | PW10: 108294 | PX10: 109024 | PY10: 109236 | PZ10: 108912 | QB10: 109089 | QC10: 109467 | QD10: 109567 | QE10: 109820 | QF10: 110451 | QG10: 110081 | QH10: 110342 | QI10: 110514 | QJ10: 110721 | QK10: 110744 | QL10: 111050 | QM10: 111083 | QO10: 110695 | QP10: 110634 | QQ10: 110587 | QR10: 110828 | QS10: 110796 | QT10: 111879 | QU10: 111756 | QV10: 112231 | QW10: 112298 | QX10: 111926 | QY10: 112228 | QZ10: 112327 | RB10: 112209 | RC10: 112615 | RD10: 112713 | RE10: 113098 | RF10: 113649 | RG10: 113817 | RH10: 113972 | RI10: 113682 | RJ10: 113857 | RK10: 114019 | RL10: 114170 | RM10: 114581 | RO10: 114725 | RP10: 114876 | RQ10: 115328 | RR10: 115331 | RS10: 115234 | RT10: 114965 | RU10: 115320 | RV10: 115291 | RW10: 115905 | RX10: 116145 | RY10: 116135 | RZ10: 116354 | SB10: 116682 | SC10: 116882 | SD10: 117220 | SE10: 117316 | SF10: 117528 | SG10: 118084 | SH10: 118129 | SI10: 118150 | SJ10: 118395 | SK10: 118516 | SL10: 118634 | SM10: 118611 | SO10: 118845 | SP10: 119122 | SQ10: 119270 | SR10: 119336 | SS10: 120008 | ST10: 119644 | SU10: 119902 | SV10: 120318 | SW10: 120011 | SX10: 120509 | SY10: 120540 | SZ10: 120729 | TB10: 120969 | TC10: 121156 | TD10: 120913 | TE10: 121251 | TF10: 121071 | TG10: 121473 | TH10: 121665 | TI10: 122125 | TJ10: 121960 | TK10: 122206 | TL10: 122637 | TM10: 122622 | TO10: 123390 | TP10: 123135 | TQ10: 123227 | TR10: 123565 | TS10: 123474 | TT10: 123995 | TU10: 123967 | TV10: 124166 | TW10: 123944 | TX10: 124211 | TY10: 124637 | TZ10: 124497 | UB10: 125833 | UC10: 125710 | UD10: 125801 | UE10: 125649 | UF10: 125893 | UG10: 125573 | UH10: 125732 | UI10: 125990 | UJ10: 125892 | UK10: 125995 | UL10: 126070 | UM10: 126142 | UO10: 125955 | UP10: 126020 | UQ10: 126238 | UR10: 126548 | US10: 126176 | UT10: 126331 | UU10: 126154 | UV10: 126150 | UW10: 126650 | UX10: 126642 | UY10: 126701 | UZ10: 126664 | VB10: 127261 | VC10: 127207 | VD10: 127604 | VE10: 127841 | VF10: 128119 | VG10: 128459 | VH10: 128563 | VI10: 128613 | VJ10: 128501 | VK10: 128026 | VL10: 128441 | VM10: 128554 | VO10: 128400 | VP10: 128458 | VQ10: 128598 | VR10: 128584 | VS10: 129264 | VT10: 129411 | VU10: 129397 | VV10: 129619 | VW10: 129268 | VX10: 129573 | VY10: 129711 | VZ10: 129941 | WB10: 130596 | WC10: 130669 | WD10: 130400 | WE10: 130621 | WF10: 130779 | WG10: 130561 | WH10: 130652 | WI10: 131275 | WJ10: 131421 | WK10: 131744 | WL10: 131891 | WM10: 131951 | WO10: 132038 | WP10: 132115 | WQ10: 132108 | WR10: 132590 | WS10: 131851 | WT10: 131949 | WU10: 132343 | WV10: 132336 | WW10: 132611 | WX10: 132716 | WY10: 132614 | WZ10: 132511 | XB10: 132616 | XC10: 132952 | XD10: 133180 | XE10: 133409 | XF10: 133667 | XG10: 133697 | XH10: 134284 | XI10: 134054 | XJ10: 134515 | XK10: 134921 | XL10: 135007 | XM10: 135113 | XO10: 135456 | XP10: 135400 | XQ10: 135891 | XR10: 136016 | XS10: 136119 | XT10: 136211 | XU10: 136477 | XV10: 136618 | XW10: 136675 | XX10: 136633 | XY10: 136961 | XZ10: 137155 | YB10: 137095 | YC10: 137112 | YD10: 137236 | YE10: 137150 | YF10: 137372 | YG10: 137455 | YH10: 137588 | YI10: 137570 | YJ10: 138286 | YK10: 138279 | YL10: 138381 | YM10: 138634 | YO10: 139003 | YP10: 138967 | YQ10: 138730 | YR10: 138959 | YS10: 139107 | YT10: 139329 | YU10: 139439 | YV10: 139430 | YW10: 139622 | YX10: 139771 | YY10: 140025 | YZ10: 140177 | ZB10: 142267(1) | ZC10: 142456 | ZD10: 142434 | ZE10: 142751 | ZF10: 142388 | ZG10: 142591 | ZH10: 142278 | ZI10: 142514 | ZJ10: 142518 | ZK10: 142622 | ZL10: 142962 | ZM10: 143248 | ZO10: 143800 | ZP10: 143701 | ZQ10: 143924 | ZR10: 143569 | ZS10: 143318 | ZT10: 143357 | ZU10: 143654 | ZV10: 143284 | ZW10: 143989 | ZX10: 144086 | ZY10: 144240 | ZZ10: 144305 | AAB10: 143883 | AAC10: 144653 | AAD10: 144481 | AAE10: 144725 | AAF10: 144938 | AAG10: 144808 | AAH10: 144803 | AAI10: 145009 | AAJ10: 145552 | AAK10: 145314 | AAL10: 145041 | AAM10: 145066 | AAO10: 145937(1) | AAP10: 146100 | AAQ10: 146022 | AAR10: 146474 | AAS10: 146500 | AAT10: 147056 | AAU10: 146485 | AAV10: 146445 | AAW10: 146530 | AAX10: 146716 | AAY10: 147000 | AAZ10: 146729 | ABB10: 146842(1) | ABC10: 146709 | ABD10: 146944 | ABE10: 146850 | ABF10: 147065 | ABG10: 147460 | ABH10: 147692 | ABI10: 147564 | ABJ10: 147415 | ABK10: 147793 | ABL10: 148162 | ABM10: 148059 | ABO10: 148029(1) | ABP10: 148364 | ABQ10: 148391 | ABR10: 148926 | ABS10: 149261 | ABT10: 149238 | ABU10: 149432 | ABV10: 149779 | ABW10: 149954 | ABX10: 150001 | ABY10: 150065 | ABZ10: 150030 | ACB10: 150214(1) | ACC10: 150641 | ACD10: 150813 | ACE10: 150881 | ACF10: 151069 | ACG10: 151354 | ACH10: 151377 | ACI10: 151716 | ACJ10: 151662 | ACK10: 152041 | ACL10: 152406 | ACM10: 152732 | ACO10: 153144(1) | ACP10: 152983 | ACQ10: 153051 | ACR10: 152435 | ACS10: 152670 | ACT10: 153041 | ACU10: 153054 | ACV10: 152749 | ACW10: 153414 | ACX10: 153183 | ACY10: 153835 | ACZ10: 153918 | ADB10: 154063(1) | ADC10: 153653 | ADD10: 153908 | ADE10: 153769 | ADF10: 154303 | ADG10: 154313 | ADH10: 154469 | ADI10: 154641 | ADJ10: 154570 | ADK10: 154876 | ADL10: 154639 | ADM10: 154655 | ADO10: 154232(1) | ADP10: 154526 | ADQ10: 154142 | ADR10: 154479 | ADS10: 154742 | ADT10: 154710 | ADU10: 154505 | ADV10: 154300 | ADW10: 153815 | ADX10: 153804 | ADY10: 153887 | ADZ10: 153120 | AEB10: 153455(1) | AEC10: 153702 | AED10: 153960 | AEE10: 154577 | AEF10: 154110 | AEG10: 153623 | AEH10: 153709 | AEI10: 154078 | AEJ10: 153966 | AEK10: 153681 | AEL10: 154140 | AEM10: 153649 | AEO10: 153244(1) | AEP10: 153269 | AEQ10: 153358 | AER10: 153478 | AES10: 153552 | AET10: 153369 | AEU10: 153325 | AEV10: 153707 | AEW10: 154074 | AEX10: 154010 | AEY10: 154096 | AEZ10: 153945 | AFB10: 154356(1) | AFC10: 154825 | AFD10: 154707 | AFE10: 154451 | AFF10: 154998 | AFG10: 155149 | AFH10: 154995 | AFI10: 154647 | AFJ10: 155056 | AFK10: 155576 | AFL10: 155319 | AFM10: 155511 | AFO10: 155654(1) | AFP10: 155524 | AFQ10: 155028 | AFR10: 155238 | AFS10: 155658 | AFT10: 155835 | AFU10: 155798 | AFV10: 155486
A11: LNS13000000 | B11: 2034 | C11: 2328 | D11: 2399 | E11: 2386 | F11: 2118 | G11: 2214 | H11: 2213 | I11: 2350 | J11: 2302 | K11: 2259 | L11: 2285 | M11: 2429 | O11: 2596 | P11: 2849 | Q11: 3030 | R11: 3260 | S11: 3707 | T11: 3776 | U11: 4111 | V11: 4193 | W11: 4049 | X11: 4916 | Y11: 3996 | Z11: 4063 | AB11: 4026 | AC11: 3936 | AD11: 3876 | AE11: 3575 | AF11: 3434 | AG11: 3367 | AH11: 3120 | AI11: 2799 | AJ11: 2774 | AK11: 2625 | AL11: 2589 | AM11: 2639 | AO11: 2305 | AP11: 2117 | AQ11: 2125 | AR11: 1919 | AS11: 1856 | AT11: 1995 | AU11: 1950 | AV11: 1933 | AW11: 2067 | AX11: 2194 | AY11: 2178 | AZ11: 1960 | BB11: 1972 | BC11: 1957 | BD11: 1813 | BE11: 1811 | BF11: 1863 | BG11: 1884 | BH11: 1991 | BI11: 2087 | BJ11: 1936 | BK11: 1839 | BL11: 1743 | BM11: 1667 | BO11: 1839 | BP11: 1636 | BQ11: 1647 | BR11: 1723 | BS11: 1596 | BT11: 1607 | BU11: 1660 | BV11: 1665 | BW11: 1821 | BX11: 1974 | BY11: 2211 | BZ11: 2818 | CB11: 3077 | CC11: 3331 | CD11: 3607 | CE11: 3749 | CF11: 3767 | CG11: 3551 | CH11: 3659 | CI11: 3854 | CJ11: 3927 | CK11: 3666 | CL11: 3402 | CM11: 3196 | CO11: 3157 | CP11: 2969 | CQ11: 2918 | CR11: 3049 | CS11: 2747 | CT11: 2701 | CU11: 2632 | CV11: 2784 | CW11: 2678 | CX11: 2830 | CY11: 2780 | CZ11: 2761 | DB11: 2666 | DC11: 2606 | DD11: 2764 | DE11: 2650 | DF11: 2861 | DG11: 2882 | DH11: 2952 | DI11: 2701 | DJ11: 2635 | DK11: 2571 | DL11: 2861 | DM11: 2790 | DO11: 2796 | DP11: 2622 | DQ11: 2509 | DR11: 2600 | DS11: 2710 | DT11: 2856 | DU11: 2796 | DV11: 2747 | DW11: 2943 | DX11: 3020 | DY11: 3454 | DZ11: 3476 | EB11: 3875 | EC11: 4303 | ED11: 4492 | EE11: 5016 | EF11: 5021 | EG11: 4944 | EH11: 5079 | EI11: 5025 | EJ11: 4821 | EK11: 4570 | EL11: 4188 | EM11: 4191 | EO11: 4068 | EP11: 3965 | EQ11: 3801 | ER11: 3571 | ES11: 3479 | ET11: 3429 | EU11: 3528 | EV11: 3588 | EW11: 3775 | EX11: 3910 | EY11: 4003 | EZ11: 3653 | FB11: 3615 | FC11: 3329 | FD11: 3726 | FE11: 3620 | FF11: 3569 | FG11: 3766 | FH11: 3836 | FI11: 3946 | FJ11: 3884 | FK11: 4252 | FL11: 4330 | FM11: 4617 | FO11: 4671 | FP11: 4832 | FQ11: 4853 | FR11: 4893 | FS11: 5003 | FT11: 4885 | FU11: 4928 | FV11: 4682 | FW11: 4676 | FX11: 4573 | FY11: 4295 | FZ11: 4177 | GB11: 4081 | GC11: 3871 | GD11: 3921 | GE11: 3906 | GF11: 3863 | GG11: 3844 | GH11: 3819 | GI11: 4013 | GJ11: 3961 | GK11: 3803 | GL11: 4024 | GM11: 3907 | GO11: 4074 | GP11: 4238 | GQ11: 4072 | GR11: 4055 | GS11: 4217 | GT11: 3977 | GU11: 4051 | GV11: 3878 | GW11: 3957 | GX11: 3987 | GY11: 4151 | GZ11: 3975 | HB11: 4029 | HC11: 3932 | HD11: 3950 | HE11: 3918 | HF11: 3764 | HG11: 3814 | HH11: 3608 | HI11: 3655 | HJ11: 3712 | HK11: 3726 | HL11: 3551 | HM11: 3651 | HO11: 3572 | HP11: 3730 | HQ11: 3510 | HR11: 3595 | HS11: 3432 | HT11: 3387 | HU11: 3301 | HV11: 3254 | HW11: 3216 | HX11: 3143 | HY11: 3073 | HZ11: 3031 | IB11: 2988 | IC11: 2820 | ID11: 2887 | IE11: 2828 | IF11: 2950 | IG11: 2872 | IH11: 2876 | II11: 2900 | IJ11: 2798 | IK11: 2798 | IL11: 2770 | IM11: 2912 | IO11: 2968 | IP11: 2915 | IQ11: 2889 | IR11: 2895 | IS11: 2929 | IT11: 2992 | IU11: 2944 | IV11: 2945 | IW11: 2958 | IX11: 3143 | IY11: 3066 | IZ11: 3018 | JB11: 2878 | JC11: 3001 | JD11: 2877 | JE11: 2709 | JF11: 2740 | JG11: 2938 | JH11: 2883 | JI11: 2768 | JJ11: 2686 | JK11: 2689 | JL11: 2715 | JM11: 2685 | JO11: 2718 | JP11: 2692 | JQ11: 2712 | JR11: 2758 | JS11: 2713 | JT11: 2816 | JU11: 2868 | JV11: 2856 | JW11: 3040 | JX11: 3049 | JY11: 2856 | JZ11: 2884 | KB11: 3201 | KC11: 3453 | KD11: 3635 | KE11: 3797 | KF11: 3919 | KG11: 4071 | KH11: 4175 | KI11: 4256 | KJ11: 4456 | KK11: 4591 | KL11: 4898 | KM11: 5076 | KO11: 4986 | KP11: 4903 | KQ11: 4987 | KR11: 4959 | KS11: 4996 | KT11: 4949 | KU11: 5035 | KV11: 5134 | KW11: 5042 | KX11: 4954 | KY11: 5161 | KZ11: 5154 | LB11: 5019 | LC11: 4928 | LD11: 5038 | LE11: 4959 | LF11: 4922 | LG11: 4923 | LH11: 4913 | LI11: 4939 | LJ11: 4849 | LK11: 4875 | LL11: 4602 | LM11: 4543 | LO11: 4326 | LP11: 4452 | LQ11: 4394 | LR11: 4459 | LS11: 4329 | LT11: 4363 | LU11: 4305 | LV11: 4305 | LW11: 4350 | LX11: 4144 | LY11: 4396 | LZ11: 4489 | MB11: 4644 | MC11: 4731 | MD11: 4634 | ME11: 4618 | MF11: 4705 | MG11: 4927 | MH11: 5063 | MI11: 5022 | MJ11: 5437 | MK11: 5523 | ML11: 6140 | MM11: 6636 | MO11: 7501 | MP11: 7520 | MQ11: 7978 | MR11: 8210 | MS11: 8433 | MT11: 8220 | MU11: 8127 | MV11: 7928 | MW11: 7923 | MX11: 7897 | MY11: 7794 | MZ11: 7744 | NB11: 7534 | NC11: 7326 | ND11: 7230 | NE11: 7330 | NF11: 7053 | NG11: 7322 | NH11: 7490 | NI11: 7518 | NJ11: 7380 | NK11: 7430 | NL11: 7620 | NM11: 7545 | NO11: 7280 | NP11: 7443 | NQ11: 7307 | NR11: 7059 | NS11: 6911 | NT11: 7134 | NU11: 6829 | NV11: 6925 | NW11: 6751 | NX11: 6763 | NY11: 6815 | NZ11: 6386 | OB11: 6489 | OC11: 6318 | OD11: 6337 | OE11: 6180 | OF11: 6127 | OG11: 6028 | OH11: 6309 | OI11: 6080 | OJ11: 6125 | OK11: 5947 | OL11: 6077 | OM11: 6228 | OO11: 6109 | OP11: 6173 | OQ11: 6109 | OR11: 6069 | OS11: 5840 | OT11: 5959 | OU11: 5996 | OV11: 6320 | OW11: 6190 | OX11: 6296 | OY11: 6238 | OZ11: 6325 | PB11: 6683 | PC11: 6702 | PD11: 6729 | PE11: 7358 | PF11: 7984 | PG11: 8098 | PH11: 8363 | PI11: 8281 | PJ11: 8021 | PK11: 8088 | PL11: 8023 | PM11: 7718 | PO11: 8071 | PP11: 8051 | PQ11: 7982 | PR11: 7869 | PS11: 8174 | PT11: 8098 | PU11: 7863 | PV11: 8036 | PW11: 8230 | PX11: 8646 | PY11: 9029 | PZ11: 9267 | QB11: 9397 | QC11: 9705 | QD11: 9895 | QE11: 10244 | QF11: 10335 | QG11: 10538 | QH11: 10849 | QI11: 10881 | QJ11: 11217 | QK11: 11529 | QL11: 11938 | QM11: 12051 | QO11: 11534 | QP11: 11545 | QQ11: 11408 | QR11: 11268 | QS11: 11154 | QT11: 11246 | QU11: 10548 | QV11: 10623 | QW11: 10282 | QX11: 9887 | QY11: 9499 | QZ11: 9331 | RB11: 9008 | RC11: 8791 | RD11: 8746 | RE11: 8762 | RF11: 8456 | RG11: 8226 | RH11: 8537 | RI11: 8519 | RJ11: 8367 | RK11: 8381 | RL11: 8198 | RM11: 8358 | RO11: 8423 | RP11: 8321 | RQ11: 8339 | RR11: 8395 | RS11: 8302 | RT11: 8460 | RU11: 8513 | RV11: 8196 | RW11: 8248 | RX11: 8298 | RY11: 8128 | RZ11: 8138 | SB11: 7795 | SC11: 8402 | SD11: 8383 | SE11: 8364 | SF11: 8439 | SG11: 8508 | SH11: 8319 | SI11: 8135 | SJ11: 8310 | SK11: 8243 | SL11: 8159 | SM11: 7883 | SO11: 7892 | SP11: 7865 | SQ11: 7862 | SR11: 7542 | SS11: 7574 | ST11: 7398 | SU11: 7268 | SV11: 7261 | SW11: 7102 | SX11: 7227 | SY11: 7035 | SZ11: 6936 | TB11: 6953 | TC11: 6929 | TD11: 6876 | TE11: 6601 | TF11: 6779 | TG11: 6546 | TH11: 6605 | TI11: 6843 | TJ11: 6604 | TK11: 6568 | TL11: 6537 | TM11: 6518 | TO11: 6682 | TP11: 6359 | TQ11: 6205 | TR11: 6468 | TS11: 6375 | TT11: 6577 | TU11: 6495 | TV11: 6511 | TW11: 6590 | TX11: 6630 | TY11: 6725 | TZ11: 6667 | UB11: 6752 | UC11: 6651 | UD11: 6598 | UE11: 6797 | UF11: 6742 | UG11: 6590 | UH11: 6922 | UI11: 7188 | UJ11: 7368 | UK11: 7459 | UL11: 7764 | UM11: 7901 | UO11: 8015 | UP11: 8265 | UQ11: 8586 | UR11: 8439 | US11: 8736 | UT11: 8692 | UU11: 8586 | UV11: 8666 | UW11: 8722 | UX11: 8842 | UY11: 8931 | UZ11: 9198 | VB11: 9283 | VC11: 9454 | VD11: 9460 | VE11: 9415 | VF11: 9744 | VG11: 10040 | VH11: 9850 | VI11: 9787 | VJ11: 9781 | VK11: 9398 | VL11: 9565 | VM11: 9557 | VO11: 9325 | VP11: 9183 | VQ11: 9056 | VR11: 9110 | VS11: 9149 | VT11: 9121 | VU11: 8930 | VV11: 8763 | VW11: 8714 | VX11: 8750 | VY11: 8542 | VZ11: 8477 | WB11: 8630 | WC11: 8583 | WD11: 8470 | WE11: 8331 | WF11: 7915 | WG11: 7927 | WH11: 7946 | WI11: 7933 | WJ11: 7734 | WK11: 7632 | WL11: 7375 | WM11: 7230 | WO11: 7375 | WP11: 7187 | WQ11: 7153 | WR11: 7645 | WS11: 7430 | WT11: 7427 | WU11: 7527 | WV11: 7484 | WW11: 7478 | WX11: 7328 | WY11: 7426 | WZ11: 7423 | XB11: 7491 | XC11: 7313 | XD11: 7318 | XE11: 7415 | XF11: 7423 | XG11: 7095 | XH11: 7337 | XI11: 6882 | XJ11: 6979 | XK11: 7031 | XL11: 7236 | XM11: 7253 | XO11: 7158 | XP11: 7102 | XQ11: 7000 | XR11: 6873 | XS11: 6655 | XT11: 6799 | XU11: 6655 | XV11: 6608 | XW11: 6656 | XX11: 6454 | XY11: 6308 | XZ11: 6476 | YB11: 6368 | YC11: 6306 | YD11: 6422 | YE11: 5941 | YF11: 6047 | YG11: 6212 | YH11: 6259 | YI11: 6179 | YJ11: 6300 | YK11: 6280 | YL11: 6100 | YM11: 6032 | YO11: 5976 | YP11: 6111 | YQ11: 5783 | YR11: 6004 | YS11: 5796 | YT11: 5951 | YU11: 6025 | YV11: 5838 | YW11: 5915 | YX11: 5778 | YY11: 5716 | YZ11: 5653 | ZB11: 5708 | ZC11: 5858 | ZD11: 5733 | ZE11: 5481 | ZF11: 5758 | ZG11: 5651 | ZH11: 5747 | ZI11: 5853 | ZJ11: 5625 | ZK11: 5534 | ZL11: 5639 | ZM11: 5634 | ZO11: 6023 | ZP11: 6089 | ZQ11: 6141 | ZR11: 6271 | ZS11: 6226 | ZT11: 6484 | ZU11: 6583 | ZV11: 7042 | ZW11: 7142 | ZX11: 7694 | ZY11: 8003 | ZZ11: 8258 | AAB11: 8182 | AAC11: 8215 | AAD11: 8304 | AAE11: 8599 | AAF11: 8399 | AAG11: 8393 | AAH11: 8390 | AAI11: 8304 | AAJ11: 8251 | AAK11: 8307 | AAL11: 8520 | AAM11: 8640 | AAO11: 8520 | AAP11: 8618 | AAQ11: 8588 | AAR11: 8842 | AAS11: 8957 | AAT11: 9266 | AAU11: 9011 | AAV11: 8896 | AAW11: 8921 | AAX11: 8732 | AAY11: 8576 | AAZ11: 8317 | ABB11: 8370 | ABC11: 8167 | ABD11: 8491 | ABE11: 8170 | ABF11: 8212 | ABG11: 8286 | ABH11: 8136 | ABI11: 7990 | ABJ11: 7927 | ABK11: 8061 | ABL11: 7932 | ABM11: 7934 | ABO11: 7784 | ABP11: 7980 | ABQ11: 7737 | ABR11: 7672 | ABS11: 7651 | ABT11: 7524 | ABU11: 7406 | ABV11: 7345 | ABW11: 7553 | ABX11: 7453 | ABY11: 7566 | ABZ11: 7279 | ACB11: 7064 | ACC11: 7184 | ACD11: 7072 | ACE11: 7120 | ACF11: 6980 | ACG11: 7001 | ACH11: 7175 | ACI11: 7091 | ACJ11: 6847 | ACK11: 6727 | ACL11: 6872 | ACM11: 6762 | ACO11: 7116 | ACP11: 6927 | ACQ11: 6731 | ACR11: 6850 | ACS11: 6766 | ACT11: 6979 | ACU11: 7149 | ACV11: 7067 | ACW11: 7170 | ACX11: 7237 | ACY11: 7240 | ACZ11: 7645 | ADB11: 7685 | ADC11: 7497 | ADD11: 7822 | ADE11: 7637 | ADF11: 8395 | ADG11: 8575 | ADH11: 8937 | ADI11: 9438 | ADJ11: 9494 | ADK11: 10074 | ADL11: 10538 | ADM11: 11286 | ADO11: 12079 | ADP11: 12881 | ADQ11: 13421 | ADR11: 13826 | ADS11: 14492 | ADT11: 14705 | ADU11: 14607 | ADV11: 14819 | ADW11: 15005 | ADX11: 15382 | ADY11: 15223 | ADZ11: 15095 | AEB11: 15016 | AEC11: 15078 | AED11: 15192 | AEE11: 15281 | AEF11: 14856 | AEG11: 14475 | AEH11: 14542 | AEI11: 14673 | AEJ11: 14577 | AEK11: 14584 | AEL11: 15094 | AEM11: 14354 | AEO11: 13992 | AEP11: 13798 | AEQ11: 13716 | AER11: 13872 | AES11: 13871 | AET11: 13964 | AEU11: 13817 | AEV11: 13837 | AEW11: 13910 | AEX11: 13696 | AEY11: 13325 | AEZ11: 13049 | AFB11: 12748 | AFC11: 12806 | AFD11: 12686 | AFE11: 12518 | AFF11: 12695 | AFG11: 12701 | AFH11: 12745 | AFI11: 12483 | AFJ11: 12082 | AFK11: 12248 | AFL11: 12042 | AFM11: 12206 | AFO11: 12332 | AFP11: 12032 | AFQ11: 11742 | AFR11: 11659 | AFS11: 11760 | AFT11: 11777 | AFU11: 11514 | AFV11: 11316
A12: LNS13008396 | B12: 1188 | C12: 1377 | D12: 1279 | E12: 1461 | F12: 1146 | G12: 1287 | H12: 1259 | I12: 1511 | J12: 1245 | K12: 1210 | L12: 1251 | M12: 1432 | O12: 1510 | P12: 1603 | Q12: 1631 | R12: 1652 | S12: 1884 | T12: 1729 | U12: 1852 | V12: 1874 | W12: 1651 | X12: 2332 | Y12: 1747 | Z12: 1748 | AB12: 1780 | AC12: 1600 | AD12: 1503 | AE12: 1472 | AF12: 1464 | AG12: 1468 | AH12: 1411 | AI12: 1251 | AJ12: 1272 | AK12: 1262 | AL12: 1354 | AM12: 1459 | AO12: 1115 | AP12: 1107 | AQ12: 1215 | AR12: 1160 | AS12: 1125 | AT12: 1125 | AU12: 1183 | AV12: 1184 | AW12: 1294 | AX12: 1279 | AY12: 1233 | AZ12: 1138 | BB12: 1066 | BC12: 1181 | BD12: 1150 | BE12: 1137 | BF12: 1179 | BG12: 1196 | BH12: 1187 | BI12: 1270 | BJ12: 1130 | BK12: 1050 | BL12: 1017 | BM12: 1044 | BO12: 1059 | BP12: 1068 | BQ12: 1029 | BR12: 1131 | BS12: 973 | BT12: 985 | BU12: 1002 | BV12: 1076 | BW12: 1163 | BX12: 1242 | BY12: 1307 | BZ12: 1761 | CB12: 1631 | CC12: 1706 | CD12: 1729 | CE12: 1725 | CF12: 1643 | CG12: 1573 | CH12: 1623 | CI12: 1587 | CJ12: 1640 | CK12: 1535 | CL12: 1457 | CM12: 1414 | CO12: 1398 | CP12: 1296 | CQ12: 1184 | CR12: 1301 | CS12: 1295 | CT12: 1305 | CU12: 1282 | CV12: 1445 | CW12: 1357 | CX12: 1429 | CY12: 1386 | CZ12: 1338 | DB12: 1336 | DC12: 1289 | DD12: 1502 | DE12: 1353 | DF12: 1483 | DG12: 1505 | DH12: 1469 | DI12: 1376 | DJ12: 1356 | DK12: 1319 | DL12: 1481 | DM12: 1446 | DO12: 1373 | DP12: 1293 | DQ12: 1241 | DR12: 1335 | DS12: 1423 | DT12: 1392 | DU12: 1366 | DV12: 1395 | DW12: 1484 | DX12: 1399 | DY12: 1598 | DZ12: 1585 | EB12: 1701 | EC12: 1883 | ED12: 1933 | EE12: 1881 | EF12: 1855 | EG12: 1755 | EH12: 1818 | EI12: 1760 | EJ12: 1626 | EK12: 1643 | EL12: 1531 | EM12: 1692 | EO12: 1574 | EP12: 1554 | EQ12: 1459 | ER12: 1494 | ES12: 1479 | ET12: 1522 | EU12: 1591 | EV12: 1607 | EW12: 1602 | EX12: 1750 | EY12: 1745 | EZ12: 1657 | FB12: 1638 | FC12: 1431 | FD12: 1666 | FE12: 1735 | FF12: 1718 | FG12: 1738 | FH12: 1709 | FI12: 1746 | FJ12: 1677 | FK12: 1766 | FL12: 1718 | FM12: 2102 | FO12: 1884 | FP12: 2037 | FQ12: 1863 | FR12: 1729 | FS12: 1748 | FT12: 1841 | FU12: 1789 | FV12: 1701 | FW12: 1859 | FX12: 1811 | FY12: 1638 | FZ12: 1734 | GB12: 1701 | GC12: 1504 | GD12: 1721 | GE12: 1629 | GF12: 1543 | GG12: 1598 | GH12: 1592 | GI12: 1731 | GJ12: 1749 | GK12: 1636 | GL12: 1838 | GM12: 1732 | GO12: 1730 | GP12: 1858 | GQ12: 1701 | GR12: 1717 | GS12: 1870 | GT12: 1719 | GU12: 1693 | GV12: 1677 | GW12: 1695 | GX12: 1738 | GY12: 1859 | GZ12: 1774 | HB12: 1805 | HC12: 1708 | HD12: 1783 | HE12: 1767 | HF12: 1681 | HG12: 1719 | HH12: 1486 | HI12: 1696 | HJ12: 1703 | HK12: 1754 | HL12: 1596 | HM12: 1672 | HO12: 1626 | HP12: 1743 | HQ12: 1702 | HR12: 1747 | HS12: 1670 | HT12: 1656 | HU12: 1654 | HV12: 1613 | HW12: 1627 | HX12: 1533 | HY12: 1531 | HZ12: 1436 | IB12: 1523 | IC12: 1505 | ID12: 1523 | IE12: 1563 | IF12: 1631 | IG12: 1647 | IH12: 1640 | II12: 1622 | IJ12: 1555 | IK12: 1541 | IL12: 1499 | IM12: 1582 | IO12: 1608 | IP12: 1596 | IQ12: 1586 | IR12: 1547 | IS12: 1581 | IT12: 1704 | IU12: 1642 | IV12: 1595 | IW12: 1667 | IX12: 1730 | IY12: 1680 | IZ12: 1616 | JB12: 1458 | JC12: 1710 | JD12: 1651 | JE12: 1436 | JF12: 1567 | JG12: 1755 | JH12: 1647 | JI12: 1645 | JJ12: 1534 | JK12: 1507 | JL12: 1593 | JM12: 1527 | JO12: 1554 | JP12: 1442 | JQ12: 1603 | JR12: 1600 | JS12: 1649 | JT12: 1664 | JU12: 1686 | JV12: 1637 | JW12: 1693 | JX12: 1814 | JY12: 1580 | JZ12: 1585 | KB12: 1800 | KC12: 1950 | KD12: 1978 | KE12: 2139 | KF12: 2109 | KG12: 2100 | KH12: 2132 | KI12: 2182 | KJ12: 2235 | KK12: 2386 | KL12: 2338 | KM12: 2369 | KO12: 2302 | KP12: 2178 | KQ12: 2144 | KR12: 2206 | KS12: 2229 | KT12: 2180 | KU12: 2210 | KV12: 2337 | KW12: 2301 | KX12: 2222 | KY12: 2304 | KZ12: 2320 | LB12: 2324 | LC12: 2111 | LD12: 2303 | LE12: 2229 | LF12: 2192 | LG12: 2279 | LH12: 2248 | LI12: 2285 | LJ12: 2353 | LK12: 2351 | LL12: 2191 | LM12: 2003 | LO12: 2035 | LP12: 2259 | LQ12: 2136 | LR12: 2260 | LS12: 2223 | LT12: 2322 | LU12: 2271 | LV12: 2290 | LW12: 2211 | LX12: 2063 | LY12: 2288 | LZ12: 2332 | MB12: 2400 | MC12: 2432 | MD12: 2413 | ME12: 2337 | MF12: 2457 | MG12: 2497 | MH12: 2526 | MI12: 2609 | MJ12: 2723 | MK12: 2723 | ML12: 3052 | MM12: 3125 | MO12: 3293 | MP12: 2947 | MQ12: 3193 | MR12: 2915 | MS12: 3051 | MT12: 2872 | MU12: 2882 | MV12: 2808 | MW12: 2878 | MX12: 2962 | MY12: 2718 | MZ12: 2762 | NB12: 2749 | NC12: 2799 | ND12: 2628 | NE12: 2938 | NF12: 2795 | NG12: 2787 | NH12: 2965 | NI12: 2893 | NJ12: 2910 | NK12: 2945 | NL12: 2826 | NM12: 2921 | NO12: 2894 | NP12: 3015 | NQ12: 2993 | NR12: 3015 | NS12: 2754 | NT12: 3138 | NU12: 2859 | NV12: 2896 | NW12: 2883 | NX12: 2883 | NY12: 2924 | NZ12: 2729 | OB12: 2824 | OC12: 2764 | OD12: 2871 | OE12: 2750 | OF12: 2870 | OG12: 2788 | OH12: 3069 | OI12: 2858 | OJ12: 2941 | OK12: 2786 | OL12: 2903 | OM12: 2978 | OO12: 2791 | OP12: 2899 | OQ12: 2843 | OR12: 2938 | OS12: 2773 | OT12: 2947 | OU12: 2890 | OV12: 3296 | OW12: 2946 | OX12: 3039 | OY12: 3030 | OZ12: 3013 | PB12: 3215 | PC12: 3134 | PD12: 3097 | PE12: 3374 | PF12: 3754 | PG12: 3409 | PH12: 3458 | PI12: 3415 | PJ12: 3150 | PK12: 3236 | PL12: 3146 | PM12: 3097 | PO12: 3318 | PP12: 3287 | PQ12: 3328 | PR12: 3185 | PS12: 3409 | PT12: 3340 | PU12: 3307 | PV12: 3320 | PW12: 3493 | PX12: 3656 | PY12: 3812 | PZ12: 3949 | QB12: 3924 | QC12: 3808 | QD12: 3896 | QE12: 3951 | QF12: 3885 | QG12: 3606 | QH12: 3929 | QI12: 3895 | QJ12: 3966 | QK12: 3873 | QL12: 3974 | QM12: 3939 | QO12: 3654 | QP12: 3717 | QQ12: 3502 | QR12: 3539 | QS12: 3531 | QT12: 3686 | QU12: 3459 | QV12: 3632 | QW12: 3768 | QX12: 3491 | QY12: 3347 | QZ12: 3455 | RB12: 3309 | RC12: 3327 | RD12: 3335 | RE12: 3362 | RF12: 3167 | RG12: 3261 | RH12: 3392 | RI12: 3567 | RJ12: 3325 | RK12: 3423 | RL12: 3392 | RM12: 3371 | RO12: 3667 | RP12: 3471 | RQ12: 3519 | RR12: 3499 | RS12: 3503 | RT12: 3538 | RU12: 3555 | RV12: 3439 | RW12: 3494 | RX12: 3424 | RY12: 3463 | RZ12: 3393 | SB12: 3333 | SC12: 3516 | SD12: 3540 | SE12: 3598 | SF12: 3586 | SG12: 3489 | SH12: 3446 | SI12: 3439 | SJ12: 3405 | SK12: 3416 | SL12: 3343 | SM12: 3297 | SO12: 3390 | SP12: 3323 | SQ12: 3386 | SR12: 3162 | SS12: 3315 | ST12: 3167 | SU12: 3217 | SV12: 3191 | SW12: 3224 | SX12: 3241 | SY12: 3172 | SZ12: 3178 | TB12: 3086 | TC12: 3057 | TD12: 3042 | TE12: 3107 | TF12: 3095 | TG12: 3101 | TH12: 2998 | TI12: 3172 | TJ12: 3152 | TK12: 3106 | TL12: 3097 | TM12: 2972 | TO12: 3146 | TP12: 3194 | TQ12: 3042 | TR12: 3110 | TS12: 3052 | TT12: 3303 | TU12: 3173 | TV12: 3090 | TW12: 3214 | TX12: 3218 | TY12: 3247 | TZ12: 3275 | UB12: 3189 | UC12: 3223 | UD12: 3206 | UE12: 3269 | UF12: 3117 | UG12: 3151 | UH12: 3221 | UI12: 3320 | UJ12: 3280 | UK12: 3347 | UL12: 3442 | UM12: 3462 | UO12: 3470 | UP12: 3585 | UQ12: 3539 | UR12: 3400 | US12: 3621 | UT12: 3428 | UU12: 3422 | UV12: 3446 | UW12: 3478 | UX12: 3473 | UY12: 3460 | UZ12: 3473 | VB12: 3398 | VC12: 3277 | VD12: 3412 | VE12: 3296 | VF12: 3417 | VG12: 3518 | VH12: 3438 | VI12: 3436 | VJ12: 3428 | VK12: 3356 | VL12: 3317 | VM12: 3189 | VO12: 3299 | VP12: 3461 | VQ12: 3260 | VR12: 3350 | VS12: 3363 | VT12: 3218 | VU12: 3292 | VV12: 3176 | VW12: 3127 | VX12: 3336 | VY12: 3087 | VZ12: 3246 | WB12: 3184 | WC12: 2652 | WD12: 2789 | WE12: 2842 | WF12: 2652 | WG12: 2757 | WH12: 2820 | WI12: 2671 | WJ12: 2671 | WK12: 2424 | WL12: 2619 | WM12: 2581 | WO12: 2764 | WP12: 2578 | WQ12: 2572 | WR12: 2730 | WS12: 2603 | WT12: 2744 | WU12: 2627 | WV12: 2732 | WW12: 2857 | WX12: 2725 | WY12: 2812 | WZ12: 2662 | XB12: 2725 | XC12: 2713 | XD12: 2594 | XE12: 2530 | XF12: 2765 | XG12: 2552 | XH12: 2672 | XI12: 2496 | XJ12: 2525 | XK12: 2477 | XL12: 2920 | XM12: 2621 | XO12: 2758 | XP12: 2549 | XQ12: 2602 | XR12: 2439 | XS12: 2527 | XT12: 2562 | XU12: 2402 | XV12: 2525 | XW12: 2474 | XX12: 2566 | XY12: 2479 | XZ12: 2534 | YB12: 2587 | YC12: 2572 | YD12: 2789 | YE12: 2628 | YF12: 2641 | YG12: 2546 | YH12: 2593 | YI12: 2597 | YJ12: 2624 | YK12: 2823 | YL12: 2510 | YM12: 2587 | YO12: 2462 | YP12: 2566 | YQ12: 2473 | YR12: 2781 | YS12: 2511 | YT12: 2521 | YU12: 2643 | YV12: 2546 | YW12: 2611 | YX12: 2536 | YY12: 2562 | YZ12: 2642 | ZB12: 2541 | ZC12: 2604 | ZD12: 2780 | ZE12: 2510 | ZF12: 2564 | ZG12: 2579 | ZH12: 2498 | ZI12: 2550 | ZJ12: 2571 | ZK12: 2497 | ZL12: 2512 | ZM12: 2477 | ZO12: 2648 | ZP12: 2851 | ZQ12: 2681 | ZR12: 2972 | ZS12: 2701 | ZT12: 2808 | ZU12: 2642 | ZV12: 2966 | ZW12: 2837 | ZX12: 3111 | ZY12: 3090 | ZZ12: 3037 | AAB12: 3044 | AAC12: 2984 | AAD12: 3074 | AAE12: 2932 | AAF12: 2843 | AAG12: 2711 | AAH12: 2891 | AAI12: 2927 | AAJ12: 2772 | AAK12: 2765 | AAL12: 2950 | AAM12: 2838 | AAO12: 2856 | AAP12: 2798 | AAQ12: 2831 | AAR12: 2794 | AAS12: 2988 | AAT12: 2906 | AAU12: 2720 | AAV12: 2801 | AAW12: 2704 | AAX12: 2710 | AAY12: 2656 | AAZ12: 2554 | ABB12: 2685 | ABC12: 2425 | ABD12: 2637 | ABE12: 2780 | ABF12: 2723 | ABG12: 2677 | ABH12: 2820 | ABI12: 2660 | ABJ12: 2758 | ABK12: 2732 | ABL12: 2638 | ABM12: 2768 | ABO12: 2635 | ABP12: 2749 | ABQ12: 2483 | ABR12: 2688 | ABS12: 2754 | ABT12: 2659 | ABU12: 2568 | ABV12: 2570 | ABW12: 2763 | ABX12: 2719 | ABY12: 2823 | ABZ12: 2588 | ACB12: 2527 | ACC12: 2577 | ACD12: 2659 | ACE12: 2665 | ACF12: 2545 | ACG12: 2705 | ACH12: 2721 | ACI12: 2603 | ACJ12: 2608 | ACK12: 2616 | ACL12: 2511 | ACM12: 2596 | ACO12: 2561 | ACP12: 2574 | ACQ12: 2307 | ACR12: 2456 | ACS12: 2464 | ACT12: 2551 | ACU12: 2502 | ACV12: 2614 | ACW12: 2557 | ACX12: 2545 | ACY12: 2645 | ACZ12: 2718 | ADB12: 2554 | ADC12: 2653 | ADD12: 2823 | ADE12: 2493 | ADF12: 3278 | ADG12: 2753 | ADH12: 2854 | ADI12: 3256 | ADJ12: 2848 | ADK12: 3170 | ADL12: 3335 | ADM12: 3255 | ADO12: 3530 | ADP12: 3436 | ADQ12: 3421 | ADR12: 3337 | ADS12: 3246 | ADT12: 3132 | ADU12: 3136 | ADV12: 2953 | ADW12: 2845 | ADX12: 3230 | ADY12: 2812 | ADZ12: 2880 | AEB12: 2938 | AEC12: 2782 | AED12: 2703 | AEE12: 2711 | AEF12: 2782 | AEG12: 2718 | AEH12: 2807 | AEI12: 2701 | AEJ12: 2828 | AEK12: 2659 | AEL12: 2895 | AEM12: 2680 | AEO12: 2704 | AEP12: 2437 | AEQ12: 2453 | AER12: 2749 | AES12: 2696 | AET12: 2999 | AEU12: 2643 | AEV12: 2697 | AEW12: 2758 | AEX12: 2670 | AEY12: 2535 | AEZ12: 2640 | AFB12: 2495 | AFC12: 2563 | AFD12: 2596 | AFE12: 2567 | AFF12: 2602 | AFG12: 2825 | AFH12: 2697 | AFI12: 2865 | AFJ12: 2535 | AFK12: 2633 | AFL12: 2596 | AFM12: 2676 | AFO12: 2766 | AFP12: 2667 | AFQ12: 2464 | AFR12: 2474 | AFS12: 2706 | AFT12: 2692 | AFU12: 2563 | AFV12: 2563
A13: 1 : Data affected by changes in population controls.

Sheet raw JOLTS data
A1: Data extracted on: November 1, 2013 (5:12:10 AM)
A3: Job Openings and Labor Turnover Survey
A5: Series Id: JTS00000000JOL
A6: Seasonally adjusted
A7: Industry: Total nonfarm
A8: Region: Total US
A9: Data Element: Job openings
A10: Rate/Level: Level - In Thousands
A12: Download:
A13: Series Id | B13: Year | C13: Period | D13: Value
A14: JTS00000000JOL | B14: 2000 | C14: M12 | D14: 5191
A15: JTS00000000JOL | B15: 2001 | C15: M01 | D15: 5186
A16: JTS00000000JOL | B16: 2001 | C16: M02 | D16: 4702
A17: JTS00000000JOL | B17: 2001 | C17: M03 | D17: 4774
A18: JTS00000000JOL | B18: 2001 | C18: M04 | D18: 4653
A19: JTS00000000JOL | B19: 2001 | C19: M05 | D19: 4452
A20: JTS00000000JOL | B20: 2001 | C20: M06 | D20: 4337
A21: JTS00000000JOL | B21: 2001 | C21: M07 | D21: 4231
A22: JTS00000000JOL | B22: 2001 | C22: M08 | D22: 4139
A23: JTS00000000JOL | B23: 2001 | C23: M09 | D23: 4006
A24: JTS00000000JOL | B24: 2001 | C24: M10 | D24: 3583
A25: JTS00000000JOL | B25: 2001 | C25: M11 | D25: 3538
... A166: JTS00000000JOL | B166: 2013 | C166: M08 | D166: 3883
A167: P : preliminary

Sheet 2-state flows
B1: L | C1: U | D1: U[<5 weeks] | E1: U[<5 weeks] redesign adjusted | F1: F | G1: f | H1: s | I1: U* | J1: rate of convergence | K1: deviation^2 | L1: f, 3m MA | M1: s, 3m MA
A2: 17533 | B2: 60095 | C2: 2034 | D2: 1188 | E2: =IF(A2>A$554,1.16*D2,D2) -> 1188 | F2: =1 - ( (C3-E3)/C2 ) -> 0.53244838 | G2: =-LN(1-F2) -> 0.76024551 | H2: 0.033970879 | I2: =H2*B2/(H2+G2) -> 2570.433 | J2: =1-EXP(-H2-G2) -> 0.54806476 | K2: =( ( (J2*I2) + ( (1-J2)*C2 ) ) - C3 )^2 -> 3.3415599e-16 | L2: =NA() -> #N/A | M2: =NA() -> #N/A
A3: 17564 | B3: 60524 | C3: 2328 | D3: 1377 | E3: =IF(A3>A$554,1.16*D3,D3) -> 1377 | F3: =1 - ( (C4-E4)/C3 ) -> 0.51890034 | G3: =-LN(1-F3) -> 0.73168084 | H3: 0.031013084 | I3: =H3*B3/(H3+G3) -> 2461.0605 | J3: =1-EXP(-H3-G3) -> 0.53359174 | K3: =( ( (J3*I3) + ( (1-J3)*C3 ) ) - C4 )^2 -> 3.7516025e-16 | L3: =NA() -> #N/A | M3: =NA() -> #N/A
A4: 17593 | B4: 60070 | C4: 2399 | D4: 1279 | E4: =IF(A4>A$554,1.16*D4,D4) -> 1279 | F4: =1 - ( (C5-E5)/C4 ) -> 0.61442268 | G4: =-LN(1-F4) -> 0.95301353 | H4: 0.039288028 | I4: =H4*B4/(H4+G4) -> 2378.3414 | J4: =1-EXP(-H4-G4) -> 0.62927753 | K4: =( ( (J4*I4) + ( (1-J4)*C4 ) ) - C5 )^2 -> 4.8934682e-16 | L4: =AVERAGE(G2:G4) -> 0.81497996 | M4: =AVERAGE(H2:H4) -> 0.034757331
A5: 17624 | B5: 60677 | C5: 2386 | D5: 1461 | E5: =IF(A5>A$554,1.16*D5,D5) -> 1461 | F5: =1 - ( (C6-E6)/C5 ) -> 0.59262364 | G5: =-LN(1-F5) -> 0.8980178 | H5: 0.029702777 | I5: =H5*B5/(H5+G5) -> 1942.6921 | J5: =1-EXP(-H5-G5) -> 0.60454591 | K5: =( ( (J5*I5) + ( (1-J5)*C5 ) ) - C6 )^2 -> 2.744622e-16 | L5: =AVERAGE(G3:G5) -> 0.86090406 | M5: =AVERAGE(H3:H5) -> 0.03333463
A6: 17654 | B6: 59972 | C6: 2118 | D6: 1146 | E6: =IF(A6>A$554,1.16*D6,D6) -> 1146 | F6: =1 - ( (C7-E7)/C6 ) -> 0.56232295 | G6: =-LN(1-F6) -> 0.82627396 | H6: 0.032722227 | I6: =H6*B6/(H6+G6) -> 2284.5473 | J6: =1-EXP(-H6-G6) -> 0.57641293 | K6: =( ( (J6*I6) + ( (1-J6)*C6 ) ) - C7 )^2 -> 3.7122463e-16 | L6: =AVERAGE(G4:G6) -> 0.89243509 | M6: =AVERAGE(H4:H6) -> 0.033904344
A7: 17685 | B7: 60957 | C7: 2214 | D7: 1287 | E7: =IF(A7>A$554,1.16*D7,D7) -> 1287 | F7: =1 - ( (C8-E8)/C7 ) -> 0.56910569 | G7: =-LN(1-F7) -> 0.84189244 | H7: 0.031705059 | I7: =H7*B7/(H7+G7) -> 2212.2834 | J7: =1-EXP(-H7-G7) -> 0.58255292 | K7: =( ( (J7*I7) + ( (1-J7)*C7 ) ) - C8 )^2 -> 3.1382611e-16 | L7: =AVERAGE(G5:G7) -> 0.85539473 | M7: =AVERAGE(H5:H7) -> 0.031376688
A8: 17715 | B8: 61181 | C8: 2213 | D8: 1259 | E8: =IF(A8>A$554,1.16*D8,D8) -> 1259 | F8: =1 - ( (C9-E9)/C8 ) -> 0.62087664 | G8: =-LN(1-F8) -> 0.96989363 | H8: 0.040089725 | I8: =H8*B8/(H8+G8) -> 2428.4851 | J8: =1-EXP(-H8-G8) -> 0.63577496 | K8: =( ( (J8*I8) + ( (1-J8)*C8 ) ) - C9 )^2 -> 3.1181536e-16 | L8: =AVERAGE(G6:G8) -> 0.87935335 | M8: =AVERAGE(H6:H8) -> 0.034839004
A9: 17746 | B9: 60806 | C9: 2350 | D9: 1511 | E9: =IF(A9>A$554,1.16*D9,D9) -> 1511 | F9: =1 - ( (C10-E10)/C9 ) -> 0.55021277 | G9: =-LN(1-F9) -> 0.79898062 | H9: 0.030911511 | I9: =H9*B9/(H9+G9) -> 2264.8791 | J9: =1-EXP(-H9-G9) -> 0.56390368 | K9: =( ( (J9*I9) + ( (1-J9)*C9 ) ) - C10 )^2 -> 3.2546819e-16 | L9: =AVERAGE(G7:G9) -> 0.87025557 | M9: =AVERAGE(H7:H9) -> 0.034235432
A10: 17777 | B10: 60815 | C10: 2302 | D10: 1245 | E10: =IF(A10>A$554,1.16*D10,D10) -> 1245 | F10: =1 - ( (C11-E11)/C10 ) -> 0.5443093 | G10: =-LN(1-F10) -> 0.78594098 | H10: 0.0298453 | I10: =H10*B10/(H10+G10) -> 2224.8988 | J10: =1-EXP(-H10-G10) -> 0.55770857 | K10: =( ( (J10*I10) + ( (1-J10)*C10 ) ) - C11 )^2 -> 3.3735571e-16 | L10: =AVERAGE(G8:G10) -> 0.85160508 | M10: =AVERAGE(H8:H10) -> 0.033615512
A11: 17807 | B11: 60646 | C11: 2259 | D11: 1210 | E11: =IF(A11>A$554,1.16*D11,D11) -> 1210 | F11: =1 - ( (C12-E12)/C11 ) -> 0.54227534 | G11: =-LN(1-F11) -> 0.78148746 | H11: 0.030886249 | I11: =H11*B11/(H11+G11) -> 2305.7461 | J11: =1-EXP(-H11-G11) -> 0.55619665 | K11: =( ( (J11*I11) + ( (1-J11)*C11 ) ) - C12 )^2 -> 3.3658772e-16 | L11: =AVERAGE(G9:G11) -> 0.78880302 | M11: =AVERAGE(H9:H11) -> 0.030547687
A12: 17838 | B12: 60702 | C12: 2285 | D12: 1251 | E12: =IF(A12>A$554,1.16*D12,D12) -> 1251 | F12: =1 - ( (C13-E13)/C12 ) -> 0.56367615 | G12: =-LN(1-F12) -> 0.82937053 | H12: 0.036124862 | I12: =H12*B12/(H12+G12) -> 2533.6373 | J12: =1-EXP(-H12-G12) -> 0.57915698 | K12: =( ( (J12*I12) + ( (1-J12)*C12 ) ) - C13 )^2 -> 3.4336257e-16 | L12: =AVERAGE(G10:G12) -> 0.79893299 | M12: =AVERAGE(H10:H12) -> 0.03228547
A13: 17868 | B13: 61169 | C13: 2429 | D13: 1432 | E13: =IF(A13>A$554,1.16*D13,D13) -> 1432 | F13: =1 - ( (C14-E14)/C13 ) -> 0.55290243 | G13: =-LN(1-F13) -> 0.80497843 | H13: 0.03749407 | I13: =H13*B13/(H13+G13) -> 2722.3141 | J13: =1-EXP(-H13-G13) -> 0.56935556 | K13: =( ( (J13*I13) + ( (1-J13)*C13 ) ) - C14 )^2 -> 2.7207169e-16 | L13: =AVERAGE(G11:G13) -> 0.80527881 | M13: =AVERAGE(H11:H13) -> 0.03483506
A14: 17899 | B14: 60771 | C14: 2596 | D14: 1510 | E14: =IF(A14>A$554,1.16*D14,D14) -> 1510 | F14: =1 - ( (C15-E15)/C14 ) -> 0.52003082 | G14: =-LN(1-F14) -> 0.73403338 | H14: 0.038999821 | I14: =H14*B14/(H14+G14) -> 3065.9203 | J14: =1-EXP(-H14-G14) -> 0.53838922 | K14: =( ( (J14*I14) + ( (1-J14)*C14 ) ) - C15 )^2 -> 4.7427478e-16 | L14: =AVERAGE(G12:G14) -> 0.78946078 | M14: =AVERAGE(H12:H14) -> 0.037539584
A15: 17930 | B15: 61057 | C15: 2849 | D15: 1603 | E15: =IF(A15>A$554,1.16*D15,D15) -> 1603 | F15: =1 - ( (C16-E16)/C15 ) -> 0.50895051 | G15: =-LN(1-F15) -> 0.71121036 | H15: 0.039231188 | I15: =H15*B15/(H15+G15) -> 3191.9057 | J15: =1-EXP(-H15-G15) -> 0.52784197 | K15: =( ( (J15*I15) + ( (1-J15)*C15 ) ) - C16 )^2 -> 5.5299732e-16 | L15: =AVERAGE(G13:G15) -> 0.75007406 | M15: =AVERAGE(H13:H15) -> 0.038575026
... A787: 41426 | B787: 155835 | C787: 11777 | D787: 2692 | E787: =IF(A787>A$554,1.16*D787,D787) -> 3122.72 | F787: =1 - ( (C788-E788)/C787 ) -> 0.27477966 | G787: =-LN(1-F787) -> 0.32127975 | H787: 0.024106152 | I787: =H787*B787/(H787+G787) -> 10876.478 | J787: =1-EXP(-H787-G787) -> 0.29205289 | K787: =( ( (J787*I787) + ( (1-J787)*C787 ) ) - C788 )^2 -> 3.1878218e-14 | L787: =AVERAGE(G785:G787) -> 0.30993413 | M787: =AVERAGE(H785:H787) -> 0.024881159
A788: 41456 | B788: 155798 | C788: 11514 | D788: 2563 | E788: =IF(A788>A$554,1.16*D788,D788) -> 2973.08 | F788: =1 - ( (C789-E789)/C788 ) -> 0.2754108 | G788: =-LN(1-F788) -> 0.32215041 | H788: 0.020354718 | I788: =H788*B788/(H788+G788) -> 9258.9106 | J788: =1-EXP(-H788-G788) -> 0.29001052 | K788: 0 | L788: =AVERAGE(G786:G788) -> 0.31669337 | M788: =AVERAGE(H786:H788) -> 0.023220175
A789: 41487 | B789: 155486 | C789: 11316 | D789: 2563 | E789: =IF(A789>A$554,1.16*D789,D789) -> 2973.08 | F789: =NA() -> #N/A | G789: =-LN(1-F789) -> #N/A | H789: =NA() -> #N/A | I789: =H789*B789/(H789+G789) -> #N/A | J789: =1-EXP(-H789-G789) -> #N/A | K789: =( ( (J789*I789) + ( (1-J789)*C789 ) ) - C790 )^2 -> #N/A | L789: =AVERAGE(G787:G789) -> #N/A | M789: =AVERAGE(H787:H789) -> #N/A
J791: SUM | K791: =SUM(K2:K788) -> 1.2847417e-06

Sheet DFH
B1: Hires | C1: Job openings | D1: Layoffs | E1: Employment (CES) | F1: Labor force (CPS) | G1: U/L | H1: V/L | I1: Monthly flow of new vacancies/E | J1: Monthly flow of new vacancies/L | K1: Daily job filling rate | L1: Implied daily job filling rate (alpha=0.5) | M1: Layoff rate | N1: V/U | O1: V/U, 3m MA | P1: =K1&", 3m MA" -> Daily job filling rate, 3m MA | Q1: =L1&", 3m MA" -> Implied daily job filling rate (alpha=0.5), 3m MA | R1: =J1&", 3m MA" -> Monthly flow of new vacancies/L, 3m MA
A2: =DATE(2000,12,1) -> 36861 | B2: 5438 | C2: 5191 | D2: 1888 | E2: 132580 | F2: 143248 | G2: 0.039 | H2: =C2/F2 -> 0.036237853 | I2: =NA() -> #N/A | J2: =I2*E2/F2 -> #N/A | K2: =NA() -> #N/A | L2: =0.035772338*(H2/G2)^(-0.5) -> 0.037110636 | M2: =D2/E2 -> 0.014240459 | N2: =H2/G2 -> 0.92917572 | O2: =NA() -> #N/A | P2: =NA() -> #N/A | Q2: =NA() -> #N/A | R2: =NA() -> #N/A
A3: =DATE(YEAR(A2),MONTH(A2)+1,1) -> 36892 | B3: 5790 | C3: 5186 | D3: 2221 | E3: 132548 | F3: 143800 | G3: 0.042 | H3: =C3/F3 -> 0.036063978 | I3: 0.044272 | J3: =I3*E3/F3 -> 0.040807824 | K3: 0.042923 | L3: =0.035772338*(H3/G3)^(-0.5) -> 0.038604253 | M3: =D3/E3 -> 0.016756194 | N3: =H3/G3 -> 0.85866614 | O3: =NA() -> #N/A | P3: =NA() -> #N/A | Q3: =NA() -> #N/A | R3: =NA() -> #N/A
A4: =DATE(YEAR(A3),MONTH(A3)+1,1) -> 36923 | B4: 5396 | C4: 4702 | D4: 1748 | E4: 132617 | F4: 143701 | G4: 0.042 | H4: =C4/F4 -> 0.032720719 | I4: 0.037506 | J4: =I4*E4/F4 -> 0.034613073 | K4: 0.042281 | L4: =0.035772338*(H4/G4)^(-0.5) -> 0.040528502 | M4: =D4/E4 -> 0.013180814 | N4: =H4/G4 -> 0.77906473 | O4: =AVERAGE(N2:N4) -> 0.85563553 | P4: =AVERAGE(K2:K4) -> #N/A | Q4: =AVERAGE(L2:L4) -> 0.038747797 | R4: =AVERAGE(J2:J4) -> #N/A
A5: =DATE(YEAR(A4),MONTH(A4)+1,1) -> 36951 | B5: 5614 | C5: 4774 | D5: 2259 | E5: 132588 | F5: 143924 | G5: 0.043 | H5: =C5/F5 -> 0.033170284 | I5: 0.043467 | J5: =I5*E5/F5 -> 0.040043374 | K5: 0.045517 | L5: =0.035772338*(H5/G5)^(-0.5) -> 0.040729301 | M5: =D5/E5 -> 0.017037741 | N5: =H5/G5 -> 0.77140196 | O5: =AVERAGE(N3:N5) -> 0.80304428 | P5: =AVERAGE(K3:K5) -> 0.043573667 | Q5: =AVERAGE(L3:L5) -> 0.039954019 | R5: =AVERAGE(J3:J5) -> 0.03848809
A6: =DATE(YEAR(A5),MONTH(A5)+1,1) -> 36982 | B6: 5386 | C6: 4653 | D6: 1958 | E6: 132307 | F6: 143569 | G6: 0.044 | H6: =C6/F6 -> 0.032409503 | I6: 0.040297 | J6: =I6*E6/F6 -> 0.037135978 | K6: 0.044036 | L6: =0.035772338*(H6/G6)^(-0.5) -> 0.041680937 | M6: =D6/E6 -> 0.014798915 | N6: =H6/G6 -> 0.73657962 | O6: =AVERAGE(N4:N6) -> 0.76234877 | P6: =AVERAGE(K4:K6) -> 0.043944667 | Q6: =AVERAGE(L4:L6) -> 0.04097958 | R6: =AVERAGE(J4:J6) -> 0.037264142
A7: =DATE(YEAR(A6),MONTH(A6)+1,1) -> 37012 | B7: 5507 | C7: 4452 | D7: 2032 | E7: 132266 | F7: 143318 | G7: 0.043 | H7: =C7/F7 -> 0.031063788 | I7: 0.040618 | J7: =I7*E7/F7 -> 0.037485734 | K7: 0.046696 | L7: =0.035772338*(H7/G7)^(-0.5) -> 0.042087618 | M7: =D7/E7 -> 0.015362981 | N7: =H7/G7 -> 0.72241368 | O7: =AVERAGE(N5:N7) -> 0.74346509 | P7: =AVERAGE(K5:K7) -> 0.045416333 | Q7: =AVERAGE(L5:L7) -> 0.041499285 | R7: =AVERAGE(J5:J7) -> 0.038221695
A8: =DATE(YEAR(A7),MONTH(A7)+1,1) -> 37043 | B8: 5116 | C8: 4337 | D8: 2003 | E8: 132140 | F8: 143357 | G8: 0.045 | H8: =C8/F8 -> 0.030253144 | I8: 0.038327 | J8: =I8*E8/F8 -> 0.035328095 | K8: 0.044869 | L8: =0.035772338*(H8/G8)^(-0.5) -> 0.043628303 | M8: =D8/E8 -> 0.015158166 | N8: =H8/G8 -> 0.67229209 | O8: =AVERAGE(N6:N8) -> 0.71042847 | P8: =AVERAGE(K6:K8) -> 0.045200333 | Q8: =AVERAGE(L6:L8) -> 0.042465619 | R8: =AVERAGE(J6:J8) -> 0.036649936
A9: =DATE(YEAR(A8),MONTH(A8)+1,1) -> 37073 | B9: 5173 | C9: 4231 | D9: 1992 | E9: 132018 | F9: 143654 | G9: 0.046 | H9: =C9/F9 -> 0.029452713 | I9: 0.038847 | J9: =I9*E9/F9 -> 0.035700386 | K9: 0.046538 | L9: =0.035772338*(H9/G9)^(-0.5) -> 0.044705771 | M9: =D9/E9 -> 0.015088852 | N9: =H9/G9 -> 0.64027636 | O9: =AVERAGE(N7:N9) -> 0.67832738 | P9: =AVERAGE(K7:K9) -> 0.046034333 | Q9: =AVERAGE(L7:L9) -> 0.043473897 | R9: =AVERAGE(J7:J9) -> 0.036171405
A10: =DATE(YEAR(A9),MONTH(A9)+1,1) -> 37104 | B10: 5090 | C10: 4139 | D10: 1876 | E10: 131862 | F10: 143284 | G10: 0.049 | H10: =C10/F10 -> 0.028886687 | I10: 0.038333 | J10: =I10*E10/F10 -> 0.035277254 | K10: 0.046864 | L10: =0.035772338*(H10/G10)^(-0.5) -> 0.046590407 | M10: =D10/E10 -> 0.014226995 | N10: =H10/G10 -> 0.58952422 | O10: =AVERAGE(N8:N10) -> 0.63403089 | P10: =AVERAGE(K8:K10) -> 0.046090333 | Q10: =AVERAGE(L8:L10) -> 0.044974827 | R10: =AVERAGE(J8:J10) -> 0.035435245
A11: =DATE(YEAR(A10),MONTH(A10)+1,1) -> 37135 | B11: 4937 | C11: 4006 | D11: 2042 | E11: 131618 | F11: 143989 | G11: 0.05 | H11: =C11/F11 -> 0.02782157 | I11: 0.036956 | J11: =I11*E11/F11 -> 0.033780878 | K11: 0.046753 | L11: =0.035772338*(H11/G11)^(-0.5) -> 0.047955841 | M11: =D11/E11 -> 0.015514595 | N11: =H11/G11 -> 0.55643139 | O11: =AVERAGE(N9:N11) -> 0.59541066 | P11: =AVERAGE(K9:K11) -> 0.046718333 | Q11: =AVERAGE(L9:L11) -> 0.04641734 | R11: =AVERAGE(J9:J11) -> 0.034919506
A12: =DATE(YEAR(A11),MONTH(A11)+1,1) -> 37165 | B12: 5030 | C12: 3583 | D12: 2222 | E12: 131291 | F12: 144086 | G12: 0.053 | H12: =C12/F12 -> 0.024867093 | I12: 0.035549 | J12: =I12*E12/F12 -> 0.032392209 | K12: 0.051519 | L12: =0.035772338*(H12/G12)^(-0.5) -> 0.052224315 | M12: =D12/E12 -> 0.016924237 | N12: =H12/G12 -> 0.46919044 | O12: =AVERAGE(N10:N12) -> 0.53838202 | P12: =AVERAGE(K10:K12) -> 0.048378667 | Q12: =AVERAGE(L10:L12) -> 0.048923521 | R12: =AVERAGE(J10:J12) -> 0.03381678
A13: =DATE(YEAR(A12),MONTH(A12)+1,1) -> 37196 | B13: 4957 | C13: 3538 | D13: 2127 | E13: 130995 | F13: 144240 | G13: 0.055 | H13: =C13/F13 -> 0.024528564 | I13: 0.037915 | J13: =I13*E13/F13 -> 0.034433413 | K13: 0.053613 | L13: =0.035772338*(H13/G13)^(-0.5) -> 0.053566419 | M13: =D13/E13 -> 0.016237261 | N13: =H13/G13 -> 0.44597388 | O13: =AVERAGE(N11:N13) -> 0.4905319 | P13: =AVERAGE(K11:K13) -> 0.050628333 | Q13: =AVERAGE(L11:L13) -> 0.051248858 | R13: =AVERAGE(J11:J13) -> 0.0335355
A14: =DATE(YEAR(A13),MONTH(A13)+1,1) -> 37226 | B14: 4771 | C14: 3559 | D14: 1864 | E14: 130823 | F14: 144305 | G14: 0.057 | H14: =C14/F14 -> 0.02466304 | I14: 0.036996 | J14: =I14*E14/F14 -> 0.03353957 | K14: 0.051683 | L14: =0.035772338*(H14/G14)^(-0.5) -> 0.054382786 | M14: =D14/E14 -> 0.014248259 | N14: =H14/G14 -> 0.43268491 | O14: =AVERAGE(N12:N14) -> 0.44928308 | P14: =AVERAGE(K12:K14) -> 0.052271667 | Q14: =AVERAGE(L12:L14) -> 0.053391173 | R14: =AVERAGE(J12:J14) -> 0.033455064
A15: =DATE(YEAR(A14),MONTH(A14)+1,1) -> 37257 | B15: 4858 | C15: 3572 | D15: 1851 | E15: 130680 | F15: 143883 | G15: 0.057 | H15: =C15/F15 -> 0.024825726 | I15: 0.037641 | J15: =I15*E15/F15 -> 0.034186984 | K15: 0.052386 | L15: =0.035772338*(H15/G15)^(-0.5) -> 0.054204304 | M15: =D15/E15 -> 0.014164371 | N15: =H15/G15 -> 0.43553906 | O15: =AVERAGE(N13:N15) -> 0.43806595 | P15: =AVERAGE(K13:K15) -> 0.052560667 | Q15: =AVERAGE(L13:L15) -> 0.054051169 | R15: =AVERAGE(J13:J15) -> 0.034053322
... A152: =DATE(YEAR(A151),MONTH(A151)+1,1) -> 41426 | B152: 4201 | C152: 3936 | D152: 1537 | E152: 135876 | F152: 155835 | G152: 0.076 | H152: =C152/F152 -> 0.025257484 | I152: 0.031445 | J152: =I152*E152/F152 -> 0.027417594 | K152: 0.041181 | L152: =0.035772338*(H152/G152)^(-0.5) -> 0.062052471 | M152: =D152/E152 -> 0.011311784 | N152: =H152/G152 -> 0.33233531 | O152: =AVERAGE(N150:N152) -> 0.32965923 | P152: =AVERAGE(K150:K152) -> 0.043338 | Q152: =AVERAGE(L150:L152) -> 0.062305136 | R152: =AVERAGE(J150:J152) -> 0.028462383
J154: Avg (pre 2008) --> | K154: =AVERAGE(K3:K86) -> 0.05055194 | L154: =AVERAGE(L3:L86) -> 0.05055194
J155: Ratio --> | K155: --> | L155: =K154/L154 -> 1

