Workbook

Sheet BLS gross flows
A1: Data extracted on: October 28, 2013 (10:18:38 AM)
A4: Labor Force Statistics from the Current Population Survey
A5: Original Data Value
A7: Download:
A8: Series ID | B8: 17533 | C8: 17564 | D8: 17593 | E8: 17624 | F8: 17654 | G8: 17685 | H8: 17715 | I8: 17746 | J8: 17777 | K8: 17807 | L8: 17838 | M8: 17868 | N8: Annual 1948 | O8: 17899 | P8: 17930 | Q8: 17958 | R8: 17989 | S8: 18019 | T8: 18050 | U8: 18080 | V8: 18111 | W8: 18142 | X8: 18172 | Y8: 18203 | Z8: 18233 | AA8: Annual 1949 | AB8: 18264 | AC8: 18295 | AD8: 18323 | AE8: 18354 | AF8: 18384 | AG8: 18415 | AH8: 18445 | AI8: 18476 | AJ8: 18507 | AK8: 18537 | AL8: 18568 | AM8: 18598 | AN8: Annual 1950 | AO8: 18629 | AP8: 18660 | AQ8: 18688 | AR8: 18719 | AS8: 18749 | AT8: 18780 | AU8: 18810 | AV8: 18841 | AW8: 18872 | AX8: 18902 | AY8: 18933 | AZ8: 18963 | BA8: Annual 1951 | BB8: 18994 | BC8: 19025 | BD8: 19054 | BE8: 19085 | BF8: 19115 | BG8: 19146 | BH8: 19176 | BI8: 19207 | BJ8: 19238 | BK8: 19268 | BL8: 19299 | BM8: 19329 | BN8: Annual 1952 | BO8: 19360 | BP8: 19391 | BQ8: 19419 | BR8: 19450 | BS8: 19480 | BT8: 19511 | BU8: 19541 | BV8: 19572 | BW8: 19603 | BX8: 19633 | BY8: 19664 | BZ8: 19694 | CA8: Annual 1953 | CB8: 19725 | CC8: 19756 | CD8: 19784 | CE8: 19815 | CF8: 19845 | CG8: 19876 | CH8: 19906 | CI8: 19937 | CJ8: 19968 | CK8: 19998 | CL8: 20029 | CM8: 20059 | CN8: Annual 1954 | CO8: 20090 | CP8: 20121 | CQ8: 20149 | CR8: 20180 | CS8: 20210 | CT8: 20241 | CU8: 20271 | CV8: 20302 | CW8: 20333 | CX8: 20363 | CY8: 20394 | CZ8: 20424 | DA8: Annual 1955 | DB8: 20455 | DC8: 20486 | DD8: 20515 | DE8: 20546 | DF8: 20576 | DG8: 20607 | DH8: 20637 | DI8: 20668 | DJ8: 20699 | DK8: 20729 | DL8: 20760 | DM8: 20790 | DN8: Annual 1956 | DO8: 20821 | DP8: 20852 | DQ8: 20880 | DR8: 20911 | DS8: 20941 | DT8: 20972 | DU8: 21002 | DV8: 21033 | DW8: 21064 | DX8: 21094 | DY8: 21125 | DZ8: 21155 | EA8: Annual 1957 | EB8: 21186 | EC8: 21217 | ED8: 21245 | EE8: 21276 | EF8: 21306 | EG8: 21337 | EH8: 21367 | EI8: 21398 | EJ8: 21429 | EK8: 21459 | EL8: 21490 | EM8: 21520 | EN8: Annual 1958 | EO8: 21551 | EP8: 21582 | EQ8: 21610 | ER8: 21641 | ES8: 21671 | ET8: 21702 | EU8: 21732 | EV8: 21763 | EW8: 21794 | EX8: 21824 | EY8: 21855 | EZ8: 21885 | FA8: Annual 1959 | FB8: 21916 | FC8: 21947 | FD8: 21976 | FE8: 22007 | FF8: 22037 | FG8: 22068 | FH8: 22098 | FI8: 22129 | FJ8: 22160 | FK8: 22190 | FL8: 22221 | FM8: 22251 | FN8: Annual 1960 | FO8: 22282 | FP8: 22313 | FQ8: 22341 | FR8: 22372 | FS8: 22402 | FT8: 22433 | FU8: 22463 | FV8: 22494 | FW8: 22525 | FX8: 22555 | FY8: 22586 | FZ8: 22616 | GA8: Annual 1961 | GB8: 22647 | GC8: 22678 | GD8: 22706 | GE8: 22737 | GF8: 22767 | GG8: 22798 | GH8: 22828 | GI8: 22859 | GJ8: 22890 | GK8: 22920 | GL8: 22951 | GM8: 22981 | GN8: Annual 1962 | GO8: 23012 | GP8: 23043 | GQ8: 23071 | GR8: 23102 | GS8: 23132 | GT8: 23163 | GU8: 23193 | GV8: 23224 | GW8: 23255 | GX8: 23285 | GY8: 23316 | GZ8: 23346 | HA8: Annual 1963 | HB8: 23377 | HC8: 23408 | HD8: 23437 | HE8: 23468 | HF8: 23498 | HG8: 23529 | HH8: 23559 | HI8: 23590 | HJ8: 23621 | HK8: 23651 | HL8: 23682 | HM8: 23712 | HN8: Annual 1964 | HO8: 23743 | HP8: 23774 | HQ8: 23802 | HR8: 23833 | HS8: 23863 | HT8: 23894 | HU8: 23924 | HV8: 23955 | HW8: 23986 | HX8: 24016 | HY8: 24047 | HZ8: 24077 | IA8: Annual 1965 | IB8: 24108 | IC8: 24139 | ID8: 24167 | IE8: 24198 | IF8: 24228 | IG8: 24259 | IH8: 24289 | II8: 24320 | IJ8: 24351 | IK8: 24381 | IL8: 24412 | IM8: 24442 | IN8: Annual 1966 | IO8: 24473 | IP8: 24504 | IQ8: 24532 | IR8: 24563 | IS8: 24593 | IT8: 24624 | IU8: 24654 | IV8: 24685 | IW8: 24716 | IX8: 24746 | IY8: 24777 | IZ8: 24807 | JA8: Annual 1967 | JB8: 24838 | JC8: 24869 | JD8: 24898 | JE8: 24929 | JF8: 24959 | JG8: 24990 | JH8: 25020 | JI8: 25051 | JJ8: 25082 | JK8: 25112 | JL8: 25143 | JM8: 25173 | JN8: Annual 1968 | JO8: 25204 | JP8: 25235 | JQ8: 25263 | JR8: 25294 | JS8: 25324 | JT8: 25355 | JU8: 25385 | JV8: 25416 | JW8: 25447 | JX8: 25477 | JY8: 25508 | JZ8: 25538 | KA8: Annual 1969 | KB8: 25569 | KC8: 25600 | KD8: 25628 | KE8: 25659 | KF8: 25689 | KG8: 25720 | KH8: 25750 | KI8: 25781 | KJ8: 25812 | KK8: 25842 | KL8: 25873 | KM8: 25903 | KN8: Annual 1970 | KO8: 25934 | KP8: 25965 | KQ8: 25993 | KR8: 26024 | KS8: 26054 | KT8: 26085 | KU8: 26115 | KV8: 26146 | KW8: 26177 | KX8: 26207 | KY8: 26238 | KZ8: 26268 | LA8: Annual 1971 | LB8: 26299 | LC8: 26330 | LD8: 26359 | LE8: 26390 | LF8: 26420 | LG8: 26451 | LH8: 26481 | LI8: 26512 | LJ8: 26543 | LK8: 26573 | LL8: 26604 | LM8: 26634 | LN8: Annual 1972 | LO8: 26665 | LP8: 26696 | LQ8: 26724 | LR8: 26755 | LS8: 26785 | LT8: 26816 | LU8: 26846 | LV8: 26877 | LW8: 26908 | LX8: 26938 | LY8: 26969 | LZ8: 26999 | MA8: Annual 1973 | MB8: 27030 | MC8: 27061 | MD8: 27089 | ME8: 27120 | MF8: 27150 | MG8: 27181 | MH8: 27211 | MI8: 27242 | MJ8: 27273 | MK8: 27303 | ML8: 27334 | MM8: 27364 | MN8: Annual 1974 | MO8: 27395 | MP8: 27426 | MQ8: 27454 | MR8: 27485 | MS8: 27515 | MT8: 27546 | MU8: 27576 | MV8: 27607 | MW8: 27638 | MX8: 27668 | MY8: 27699 | MZ8: 27729 | NA8: Annual 1975 | NB8: 27760 | NC8: 27791 | ND8: 27820 | NE8: 27851 | NF8: 27881 | NG8: 27912 | NH8: 27942 | NI8: 27973 | NJ8: 28004 | NK8: 28034 | NL8: 28065 | NM8: 28095 | NN8: Annual 1976 | NO8: 28126 | NP8: 28157 | NQ8: 28185 | NR8: 28216 | NS8: 28246 | NT8: 28277 | NU8: 28307 | NV8: 28338 | NW8: 28369 | NX8: 28399 | NY8: 28430 | NZ8: 28460 | OA8: Annual 1977 | OB8: 28491 | OC8: 28522 | OD8: 28550 | OE8: 28581 | OF8: 28611 | OG8: 28642 | OH8: 28672 | OI8: 28703 | OJ8: 28734 | OK8: 28764 | OL8: 28795 | OM8: 28825 | ON8: Annual 1978 | OO8: 28856 | OP8: 28887 | OQ8: 28915 | OR8: 28946 | OS8: 28976 | OT8: 29007 | OU8: 29037 | OV8: 29068 | OW8: 29099 | OX8: 29129 | OY8: 29160 | OZ8: 29190 | PA8: Annual 1979 | PB8: 29221 | PC8: 29252 | PD8: 29281 | PE8: 29312 | PF8: 29342 | PG8: 29373 | PH8: 29403 | PI8: 29434 | PJ8: 29465 | PK8: 29495 | PL8: 29526 | PM8: 29556 | PN8: Annual 1980 | PO8: 29587 | PP8: 29618 | PQ8: 29646 | PR8: 29677 | PS8: 29707 | PT8: 29738 | PU8: 29768 | PV8: 29799 | PW8: 29830 | PX8: 29860 | PY8: 29891 | PZ8: 29921 | QA8: Annual 1981 | QB8: 29952 | QC8: 29983 | QD8: 30011 | QE8: 30042 | QF8: 30072 | QG8: 30103 | QH8: 30133 | QI8: 30164 | QJ8: 30195 | QK8: 30225 | QL8: 30256 | QM8: 30286 | QN8: Annual 1982 | QO8: 30317 | QP8: 30348 | QQ8: 30376 | QR8: 30407 | QS8: 30437 | QT8: 30468 | QU8: 30498 | QV8: 30529 | QW8: 30560 | QX8: 30590 | QY8: 30621 | QZ8: 30651 | RA8: Annual 1983 | RB8: 30682 | RC8: 30713 | RD8: 30742 | RE8: 30773 | RF8: 30803 | RG8: 30834 | RH8: 30864 | RI8: 30895 | RJ8: 30926 | RK8: 30956 | RL8: 30987 | RM8: 31017 | RN8: Annual 1984 | RO8: 31048 | RP8: 31079 | RQ8: 31107 | RR8: 31138 | RS8: 31168 | RT8: 31199 | RU8: 31229 | RV8: 31260 | RW8: 31291 | RX8: 31321 | RY8: 31352 | RZ8: 31382 | SA8: Annual 1985 | SB8: 31413 | SC8: 31444 | SD8: 31472 | SE8: 31503 | SF8: 31533 | SG8: 31564 | SH8: 31594 | SI8: 31625 | SJ8: 31656 | SK8: 31686 | SL8: 31717 | SM8: 31747 | SN8: Annual 1986 | SO8: 31778 | SP8: 31809 | SQ8: 31837 | SR8: 31868 | SS8: 31898 | ST8: 31929 | SU8: 31959 | SV8: 31990 | SW8: 32021 | SX8: 32051 | SY8: 32082 | SZ8: 32112 | TA8: Annual 1987 | TB8: 32143 | TC8: 32174 | TD8: 32203 | TE8: 32234 | TF8: 32264 | TG8: 32295 | TH8: 32325 | TI8: 32356 | TJ8: 32387 | TK8: 32417 | TL8: 32448 | TM8: 32478 | TN8: Annual 1988 | TO8: 32509 | TP8: 32540 | TQ8: 32568 | TR8: 32599 | TS8: 32629 | TT8: 32660 | TU8: 32690 | TV8: 32721 | TW8: 32752 | TX8: 32782 | TY8: 32813 | TZ8: 32843 | UA8: Annual 1989 | UB8: 32874 | UC8: 32905 | UD8: 32933 | UE8: 32964 | UF8: 32994 | UG8: 33025 | UH8: 33055 | UI8: 33086 | UJ8: 33117 | UK8: 33147 | UL8: 33178 | UM8: 33208 | UN8: Annual 1990 | UO8: 33239 | UP8: 33270 | UQ8: 33298 | UR8: 33329 | US8: 33359 | UT8: 33390 | UU8: 33420 | UV8: 33451 | UW8: 33482 | UX8: 33512 | UY8: 33543 | UZ8: 33573 | VA8: Annual 1991 | VB8: 33604 | VC8: 33635 | VD8: 33664 | VE8: 33695 | VF8: 33725 | VG8: 33756 | VH8: 33786 | VI8: 33817 | VJ8: 33848 | VK8: 33878 | VL8: 33909 | VM8: 33939 | VN8: Annual 1992 | VO8: 33970 | VP8: 34001 | VQ8: 34029 | VR8: 34060 | VS8: 34090 | VT8: 34121 | VU8: 34151 | VV8: 34182 | VW8: 34213 | VX8: 34243 | VY8: 34274 | VZ8: 34304 | WA8: Annual 1993 | WB8: 34335 | WC8: 34366 | WD8: 34394 | WE8: 34425 | WF8: 34455 | WG8: 34486 | WH8: 34516 | WI8: 34547 | WJ8: 34578 | WK8: 34608 | WL8: 34639 | WM8: 34669 | WN8: Annual 1994 | WO8: 34700 | WP8: 34731 | WQ8: 34759 | WR8: 34790 | WS8: 34820 | WT8: 34851 | WU8: 34881 | WV8: 34912 | WW8: 34943 | WX8: 34973 | WY8: 35004 | WZ8: 35034 | XA8: Annual 1995 | XB8: 35065 | XC8: 35096 | XD8: 35125 | XE8: 35156 | XF8: 35186 | XG8: 35217 | XH8: 35247 | XI8: 35278 | XJ8: 35309 | XK8: 35339 | XL8: 35370 | XM8: 35400 | XN8: Annual 1996 | XO8: 35431 | XP8: 35462 | XQ8: 35490 | XR8: 35521 | XS8: 35551 | XT8: 35582 | XU8: 35612 | XV8: 35643 | XW8: 35674 | XX8: 35704 | XY8: 35735 | XZ8: 35765 | YA8: Annual 1997 | YB8: 35796 | YC8: 35827 | YD8: 35855 | YE8: 35886 | YF8: 35916 | YG8: 35947 | YH8: 35977 | YI8: 36008 | YJ8: 36039 | YK8: 36069 | YL8: 36100 | YM8: 36130 | YN8: Annual 1998 | YO8: 36161 | YP8: 36192 | YQ8: 36220 | YR8: 36251 | YS8: 36281 | YT8: 36312 | YU8: 36342 | YV8: 36373 | YW8: 36404 | YX8: 36434 | YY8: 36465 | YZ8: 36495 | ZA8: Annual 1999 | ZB8: 36526 | ZC8: 36557 | ZD8: 36586 | ZE8: 36617 | ZF8: 36647 | ZG8: 36678 | ZH8: 36708 | ZI8: 36739 | ZJ8: 36770 | ZK8: 36800 | ZL8: 36831 | ZM8: 36861 | ZN8: Annual 2000 | ZO8: 36892 | ZP8: 36923 | ZQ8: 36951 | ZR8: 36982 | ZS8: 37012 | ZT8: 37043 | ZU8: 37073 | ZV8: 37104 | ZW8: 37135 | ZX8: 37165 | ZY8: 37196 | ZZ8: 37226 | AAA8: Annual 2001 | AAB8: 37257 | AAC8: 37288 | AAD8: 37316 | AAE8: 37347 | AAF8: 37377 | AAG8: 37408 | AAH8: 37438 | AAI8: 37469 | AAJ8: 37500 | AAK8: 37530 | AAL8: 37561 | AAM8: 37591 | AAN8: Annual 2002 | AAO8: 37622 | AAP8: 37653 | AAQ8: 37681 | AAR8: 37712 | AAS8: 37742 | AAT8: 37773 | AAU8: 37803 | AAV8: 37834 | AAW8: 37865 | AAX8: 37895 | AAY8: 37926 | AAZ8: 37956 | ABA8: Annual 2003 | ABB8: 37987 | ABC8: 38018 | ABD8: 38047 | ABE8: 38078 | ABF8: 38108 | ABG8: 38139 | ABH8: 38169 | ABI8: 38200 | ABJ8: 38231 | ABK8: 38261 | ABL8: 38292 | ABM8: 38322 | ABN8: Annual 2004 | ABO8: 38353 | ABP8: 38384 | ABQ8: 38412 | ABR8: 38443 | ABS8: 38473 | ABT8: 38504 | ABU8: 38534 | ABV8: 38565 | ABW8: 38596 | ABX8: 38626 | ABY8: 38657 | ABZ8: 38687 | ACA8: Annual 2005 | ACB8: 38718 | ACC8: 38749 | ACD8: 38777 | ACE8: 38808 | ACF8: 38838 | ACG8: 38869 | ACH8: 38899 | ACI8: 38930 | ACJ8: 38961 | ACK8: 38991 | ACL8: 39022 | ACM8: 39052 | ACN8: Annual 2006 | ACO8: 39083 | ACP8: 39114 | ACQ8: 39142 | ACR8: 39173 | ACS8: 39203 | ACT8: 39234 | ACU8: 39264 | ACV8: 39295 | ACW8: 39326 | ACX8: 39356 | ACY8: 39387 | ACZ8: 39417 | ADA8: Annual 2007 | ADB8: 39448 | ADC8: 39479 | ADD8: 39508 | ADE8: 39539 | ADF8: 39569 | ADG8: 39600 | ADH8: 39630 | ADI8: 39661 | ADJ8: 39692 | ADK8: 39722 | ADL8: 39753 | ADM8: 39783 | ADN8: Annual 2008 | ADO8: 39814 | ADP8: 39845 | ADQ8: 39873 | ADR8: 39904 | ADS8: 39934 | ADT8: 39965 | ADU8: 39995 | ADV8: 40026 | ADW8: 40057 | ADX8: 40087 | ADY8: 40118 | ADZ8: 40148 | AEA8: Annual 2009 | AEB8: 40179 | AEC8: 40210 | AED8: 40238 | AEE8: 40269 | AEF8: 40299 | AEG8: 40330 | AEH8: 40360 | AEI8: 40391 | AEJ8: 40422 | AEK8: 40452 | AEL8: 40483 | AEM8: 40513 | AEN8: Annual 2010 | AEO8: 40544 | AEP8: 40575 | AEQ8: 40603 | AER8: 40634 | AES8: 40664 | AET8: 40695 | AEU8: 40725 | AEV8: 40756 | AEW8: 40787 | AEX8: 40817 | AEY8: 40848 | AEZ8: 40878 | AFA8: Annual 2011 | AFB8: 40909 | AFC8: 40940 | AFD8: 40969 | AFE8: 41000 | AFF8: 41030 | AFG8: 41061 | AFH8: 41091 | AFI8: 41122 | AFJ8: 41153 | AFK8: 41183 | AFL8: 41214 | AFM8: 41244 | AFN8: Annual 2012 | AFO8: 41275 | AFP8: 41306 | AFQ8: 41334 | AFR8: 41365 | AFS8: 41395 | AFT8: 41426 | AFU8: 41456 | AFV8: 41487 | AFW8: 41518 | AFX8: 41548 | AFY8: 41579 | AFZ8: 41609 | AGA8: Annual 2013
A9: LNS12000000 | B9: 58061 | C9: 58196 | D9: 57671 | E9: 58291 | F9: 57854 | G9: 58743 | H9: 58968 | I9: 58456 | J9: 58513 | K9: 58387 | L9: 58417 | M9: 58740 | O9: 58175 | P9: 58208 | Q9: 58043 | R9: 57747 | S9: 57552 | T9: 57172 | U9: 57190 | V9: 57397 | W9: 57584 | X9: 57269 | Y9: 58009 | Z9: 57845 | AB9: 57635 | AC9: 57751 | AD9: 57728 | AE9: 58583 | AF9: 58649 | AG9: 59052 | AH9: 59001 | AI9: 59797 | AJ9: 59575 | AK9: 59803 | AL9: 59697 | AM9: 59429 | AO9: 59636 | AP9: 59661 | AQ9: 60401 | AR9: 59889 | AS9: 60188 | AT9: 59620 | AU9: 60156 | AV9: 59994 | AW9: 59713 | AX9: 60010 | AY9: 59836 | AZ9: 60497 | BB9: 60460 | BC9: 60462 | BD9: 59908 | BE9: 59909 | BF9: 60195 | BG9: 60219 | BH9: 59971 | BI9: 59790 | BJ9: 60521 | BK9: 60132 | BL9: 60748 | BM9: 60954 | BO9: 61600 | BP9: 61884 | BQ9: 62010 | BR9: 61444 | BS9: 61019 | BT9: 61456 | BU9: 61397 | BV9: 61151 | BW9: 60906 | BX9: 60893 | BY9: 60738 | BZ9: 59977 | CB9: 60024 | CC9: 60663 | CD9: 60186 | CE9: 60185 | CF9: 59908 | CG9: 59792 | CH9: 59643 | CI9: 59853 | CJ9: 60282 | CK9: 60270 | CL9: 60357 | CM9: 60116 | CO9: 60753 | CP9: 60727 | CQ9: 60964 | CR9: 61515 | CS9: 61634 | CT9: 61781 | CU9: 62513 | CV9: 62797 | CW9: 62950 | CX9: 62991 | CY9: 63257 | CZ9: 63684 | DB9: 63753 | DC9: 63518 | DD9: 63411 | DE9: 63614 | DF9: 63861 | DG9: 63820 | DH9: 63800 | DI9: 63972 | DJ9: 64079 | DK9: 63975 | DL9: 63796 | DM9: 63910 | DO9: 63632 | DP9: 64257 | DQ9: 64404 | DR9: 64047 | DS9: 63985 | DT9: 64196 | DU9: 64540 | DV9: 63959 | DW9: 64121 | DX9: 64046 | DY9: 63669 | DZ9: 63922 | EB9: 63220 | EC9: 62898 | ED9: 62731 | EE9: 62631 | EF9: 62874 | EG9: 62730 | EH9: 62745 | EI9: 63012 | EJ9: 63181 | EK9: 63475 | EL9: 63470 | EM9: 63549 | EO9: 63868 | EP9: 63684 | EQ9: 64267 | ER9: 64768 | ES9: 64699 | ET9: 64849 | EU9: 65011 | EV9: 64844 | EW9: 64770 | EX9: 64911 | EY9: 64530 | EZ9: 65341 | FB9: 65347 | FC9: 65620 | FD9: 64673 | FE9: 65959 | FF9: 66057 | FG9: 66168 | FH9: 65909 | FI9: 65895 | FJ9: 66267 | FK9: 65632 | FL9: 66109 | FM9: 65778 | FO9: 65776 | FP9: 65588 | FQ9: 65850 | FR9: 65374 | FS9: 65449 | FT9: 65993 | FU9: 65608 | FV9: 65852 | FW9: 65541 | FX9: 65919 | FY9: 66081 | FZ9: 65900 | GB9: 66108 | GC9: 66538 | GD9: 66493 | GE9: 66372 | GF9: 66688 | GG9: 66670 | GH9: 66483 | GI9: 66968 | GJ9: 67192 | GK9: 67114 | GL9: 66847 | GM9: 66947 | GO9: 67072 | GP9: 67024 | GQ9: 67351 | GR9: 67642 | GS9: 67615 | GT9: 67649 | GU9: 67905 | GV9: 67908 | GW9: 68174 | GX9: 68294 | GY9: 68267 | GZ9: 68213 | HB9: 68327 | HC9: 68751 | HD9: 68763 | HE9: 69356 | HF9: 69631 | HG9: 69218 | HH9: 69399 | HI9: 69463 | HJ9: 69578 | HK9: 69582 | HL9: 69735 | HM9: 69814 | HO9: 69997 | HP9: 70127 | HQ9: 70439 | HR9: 70633 | HS9: 71034 | HT9: 71025 | HU9: 71460 | HV9: 71362 | HW9: 71286 | HX9: 71695 | HY9: 71724 | HZ9: 72062 | IB9: 72198 | IC9: 72134 | ID9: 72188 | IE9: 72510 | IF9: 72497 | IG9: 72775 | IH9: 72860 | II9: 73146 | IJ9: 73258 | IK9: 73401 | IL9: 73840 | IM9: 73729 | IO9: 73671 | IP9: 73606 | IQ9: 73439 | IR9: 73882 | IS9: 73844 | IT9: 74278 | IU9: 74520 | IV9: 74767 | IW9: 74854 | IX9: 75051 | IY9: 75125 | IZ9: 75473 | JB9: 74700 | JC9: 75229 | JD9: 75379 | JE9: 75561 | JF9: 76107 | JG9: 76182 | JH9: 76087 | JI9: 76043 | JJ9: 76172 | JK9: 76224 | JL9: 76494 | JM9: 76778 | JO9: 76805 | JP9: 77327 | JQ9: 77367 | JR9: 77523 | JS9: 77412 | JT9: 77880 | JU9: 77959 | JV9: 78250 | JW9: 78250 | JX9: 78445 | JY9: 78541 | JZ9: 78740 | KB9: 78780 | KC9: 78698 | KD9: 78863 | KE9: 78930 | KF9: 78564 | KG9: 78413 | KH9: 78726 | KI9: 78624 | KJ9: 78498 | KK9: 78685 | KL9: 78650 | KM9: 78594 | KO9: 78864 | KP9: 78700 | KQ9: 78588 | KR9: 78987 | KS9: 79139 | KT9: 78757 | KU9: 79305 | KV9: 79539 | KW9: 79689 | KX9: 79918 | KY9: 80297 | KZ9: 80471 | LB9: 80959 | LC9: 81108 | LD9: 81573 | LE9: 81655 | LF9: 81887 | LG9: 82083 | LH9: 82230 | LI9: 82578 | LJ9: 82543 | LK9: 82616 | LL9: 82990 | LM9: 83400 | LO9: 83161 | LP9: 83912 | LQ9: 84452 | LR9: 84559 | LS9: 84648 | LT9: 85185 | LU9: 85299 | LV9: 85204 | LW9: 85488 | LX9: 85987 | LY9: 86320 | LZ9: 86401 | MB9: 86555 | MC9: 86754 | MD9: 86819 | ME9: 86669 | MF9: 86891 | MG9: 86941 | MH9: 87149 | MI9: 87037 | MJ9: 87051 | MK9: 86995 | ML9: 86626 | MM9: 86144 | MO9: 85627 | MP9: 85256 | MQ9: 85187 | MR9: 85189 | MS9: 85451 | MT9: 85355 | MU9: 85894 | MV9: 86234 | MW9: 86279 | MX9: 86370 | MY9: 86456 | MZ9: 86665 | NB9: 87400 | NC9: 87672 | ND9: 87985 | NE9: 88416 | NF9: 88794 | NG9: 88563 | NH9: 89093 | NI9: 89223 | NJ9: 89173 | NK9: 89274 | NL9: 89634 | NM9: 89803 | NO9: 89928 | NP9: 90342 | NQ9: 90808 | NR9: 91271 | NS9: 91754 | NT9: 91959 | NU9: 92084 | NV9: 92441 | NW9: 92702 | NX9: 93052 | NY9: 93761 | NZ9: 94105 | OB9: 94384 | OC9: 94519 | OD9: 94755 | OE9: 95394 | OF9: 95769 | OG9: 96343 | OH9: 96090 | OI9: 96431 | OJ9: 96670 | OK9: 97133 | OL9: 97485 | OM9: 97581 | OO9: 97948 | OP9: 98329 | OQ9: 98480 | OR9: 98103 | OS9: 98331 | OT9: 98679 | OU9: 99006 | OV9: 98776 | OW9: 99340 | OX9: 99404 | OY9: 99574 | OZ9: 99933 | PB9: 99879 | PC9: 99995 | PD9: 99713 | PE9: 99233 | PF9: 98945 | PG9: 98682 | PH9: 98796 | PI9: 98824 | PJ9: 99077 | PK9: 99317 | PL9: 99545 | PM9: 99634 | PO9: 99955 | PP9: 100191 | PQ9: 100571 | PR9: 101056 | PS9: 101048 | PT9: 100298 | PU9: 100693 | PV9: 100689 | PW9: 100064 | PX9: 100378 | PY9: 100207 | PZ9: 99645 | QB9: 99692 | QC9: 99762 | QD9: 99672 | QE9: 99576 | QF9: 100116 | QG9: 99543 | QH9: 99493 | QI9: 99633 | QJ9: 99504 | QK9: 99215 | QL9: 99112 | QM9: 99032 | QO9: 99161 | QP9: 99089 | QQ9: 99179 | QR9: 99560 | QS9: 99642 | QT9: 100633 | QU9: 101208 | QV9: 101608 | QW9: 102016 | QX9: 102039 | QY9: 102729 | QZ9: 102996 | RB9: 103201 | RC9: 103824 | RD9: 103967 | RE9: 104336 | RF9: 105193 | RG9: 105591 | RH9: 105435 | RI9: 105163 | RJ9: 105490 | RK9: 105638 | RL9: 105972 | RM9: 106223 | RO9: 106302 | RP9: 106555 | RQ9: 106989 | RR9: 106936 | RS9: 106932 | RT9: 106505 | RU9: 106807 | RV9: 107095 | RW9: 107657 | RX9: 107847 | RY9: 108007 | RZ9: 108216 | SB9: 108887 | SC9: 108480 | SD9: 108837 | SE9: 108952 | SF9: 109089 | SG9: 109576 | SH9: 109810 | SI9: 110015 | SJ9: 110085 | SK9: 110273 | SL9: 110475 | SM9: 110728 | SO9: 110953 | SP9: 111257 | SQ9: 111408 | SR9: 111794 | SS9: 112434 | ST9: 112246 | SU9: 112634 | SV9: 113057 | SW9: 112909 | SX9: 113282 | SY9: 113505 | SZ9: 113793 | TB9: 114016 | TC9: 114227 | TD9: 114037 | TE9: 114650 | TF9: 114292 | TG9: 114927 | TH9: 115060 | TI9: 115282 | TJ9: 115356 | TK9: 115638 | TL9: 116100 | TM9: 116104 | TO9: 116708 | TP9: 116776 | TQ9: 117022 | TR9: 117097 | TS9: 117099 | TT9: 117418 | TU9: 117472 | TV9: 117655 | TW9: 117354 | TX9: 117581 | TY9: 117912 | TZ9: 117830 | UB9: 119081 | UC9: 119059 | UD9: 119203 | UE9: 118852 | UF9: 119151 | UG9: 118983 | UH9: 118810 | UI9: 118802 | UJ9: 118524 | UK9: 118536 | UL9: 118306 | UM9: 118241 | UO9: 117940 | UP9: 117755 | UQ9: 117652 | UR9: 118109 | US9: 117440 | UT9: 117639 | UU9: 117568 | UV9: 117484 | UW9: 117928 | UX9: 117800 | UY9: 117770 | UZ9: 117466 | VB9: 117978 | VC9: 117753 | VD9: 118144 | VE9: 118426 | VF9: 118375 | VG9: 118419 | VH9: 118713 | VI9: 118826 | VJ9: 118720 | VK9: 118628 | VL9: 118876 | VM9: 118997 | VO9: 119075 | VP9: 119275 | VQ9: 119542 | VR9: 119474 | VS9: 120115 | VT9: 120290 | VU9: 120467 | VV9: 120856 | VW9: 120554 | VX9: 120823 | VY9: 121169 | VZ9: 121464 | WB9: 121966 | WC9: 122086 | WD9: 121930 | WE9: 122290 | WF9: 122864 | WG9: 122634 | WH9: 122706 | WI9: 123342 | WJ9: 123687 | WK9: 124112 | WL9: 124516 | WM9: 124721 | WO9: 124663 | WP9: 124928 | WQ9: 124955 | WR9: 124945 | WS9: 124421 | WT9: 124522 | WU9: 124816 | WV9: 124852 | WW9: 125133 | WX9: 125388 | WY9: 125188 | WZ9: 125088 | XB9: 125125 | XC9: 125639 | XD9: 125862 | XE9: 125994 | XF9: 126244 | XG9: 126602 | XH9: 126947 | XI9: 127172 | XJ9: 127536 | XK9: 127890 | XL9: 127771 | XM9: 127860 | XO9: 128298 | XP9: 128298 | XQ9: 128891 | XR9: 129143 | XS9: 129464 | XT9: 129412 | XU9: 129822 | XV9: 130010 | XW9: 130019 | XX9: 130179 | XY9: 130653 | XZ9: 130679 | YB9: 130726 | YC9: 130807 | YD9: 130814 | YE9: 131209 | YF9: 131325 | YG9: 131244 | YH9: 131329 | YI9: 131390 | YJ9: 131986 | YK9: 131999 | YL9: 132280 | YM9: 132602 | YO9: 133027 | YP9: 132856 | YQ9: 132947 | YR9: 132955 | YS9: 133311 | YT9: 133378 | YU9: 133414 | YV9: 133591 | YW9: 133707 | YX9: 133993 | YY9: 134309 | YZ9: 134523 | ZB9: 136559(1) | ZC9: 136598 | ZD9: 136701 | ZE9: 137270 | ZF9: 136630 | ZG9: 136940 | ZH9: 136531 | ZI9: 136662 | ZJ9: 136893 | ZK9: 137088 | ZL9: 137322 | ZM9: 137614 | ZO9: 137778 | ZP9: 137612 | ZQ9: 137783 | ZR9: 137299 | ZS9: 137092 | ZT9: 136873 | ZU9: 137071 | ZV9: 136241 | ZW9: 136846 | ZX9: 136392 | ZY9: 136238 | ZZ9: 136047 | AAB9: 135701 | AAC9: 136438 | AAD9: 136177 | AAE9: 136126 | AAF9: 136539 | AAG9: 136415 | AAH9: 136413 | AAI9: 136705 | AAJ9: 137302 | AAK9: 137008 | AAL9: 136521 | AAM9: 136426 | AAO9: 137417(1) | AAP9: 137482 | AAQ9: 137434 | AAR9: 137633 | AAS9: 137544 | AAT9: 137790 | AAU9: 137474 | AAV9: 137549 | AAW9: 137609 | AAX9: 137984 | AAY9: 138424 | AAZ9: 138411 | ABB9: 138472(1) | ABC9: 138542 | ABD9: 138453 | ABE9: 138680 | ABF9: 138852 | ABG9: 139174 | ABH9: 139556 | ABI9: 139573 | ABJ9: 139487 | ABK9: 139732 | ABL9: 140231 | ABM9: 140125 | ABO9: 140245(1) | ABP9: 140385 | ABQ9: 140654 | ABR9: 141254 | ABS9: 141609 | ABT9: 141714 | ABU9: 142026 | ABV9: 142434 | ABW9: 142401 | ABX9: 142548 | ABY9: 142499 | ABZ9: 142752 | ACB9: 143150(1) | ACC9: 143457 | ACD9: 143741 | ACE9: 143761 | ACF9: 144089 | ACG9: 144353 | ACH9: 144202 | ACI9: 144625 | ACJ9: 144815 | ACK9: 145314 | ACL9: 145534 | ACM9: 145970 | ACO9: 146028(1) | ACP9: 146057 | ACQ9: 146320 | ACR9: 145586 | ACS9: 145903 | ACT9: 146063 | ACU9: 145905 | ACV9: 145682 | ACW9: 146244 | ACX9: 145946 | ACY9: 146595 | ACZ9: 146273 | ADB9: 146378(1) | ADC9: 146156 | ADD9: 146086 | ADE9: 146132 | ADF9: 145908 | ADG9: 145737 | ADH9: 145532 | ADI9: 145203 | ADJ9: 145076 | ADK9: 144802 | ADL9: 144100 | ADM9: 143369 | ADO9: 142153(1) | ADP9: 141644 | ADQ9: 140721 | ADR9: 140652 | ADS9: 140250 | ADT9: 140005 | ADU9: 139898 | ADV9: 139481 | ADW9: 138810 | ADX9: 138421 | ADY9: 138665 | ADZ9: 138025 | AEB9: 138439(1) | AEC9: 138624 | AED9: 138767 | AEE9: 139296 | AEF9: 139255 | AEG9: 139148 | AEH9: 139167 | AEI9: 139405 | AEJ9: 139388 | AEK9: 139097 | AEL9: 139046 | AEM9: 139295 | AEO9: 139253(1) | AEP9: 139471 | AEQ9: 139643 | AER9: 139606 | AES9: 139681 | AET9: 139405 | AEU9: 139509 | AEV9: 139870 | AEW9: 140164 | AEX9: 140314 | AEY9: 140771 | AEZ9: 140896 | AFB9: 141608(1) | AFC9: 142019 | AFD9: 142020 | AFE9: 141934 | AFF9: 142302 | AFG9: 142448 | AFH9: 142250 | AFI9: 142164 | AFJ9: 142974 | AFK9: 143328 | AFL9: 143277 | AFM9: 143305 | AFO9: 143322(1) | AFP9: 143492 | AFQ9: 143286 | AFR9: 143579 | AFS9: 143898 | AFT9: 144058 | AFU9: 144285 | AFV9: 144170 | AFW9: 144303
A10: LNS17000000 | UC10: 113650 | UD10: 113910 | UE10: 113817 | UF10: 114028 | UG10: 113970 | UH10: 113702 | UI10: 113809 | UJ10: 113676 | UK10: 113367 | UL10: 113166 | UM10: 113229 | UO10: 113007 | UP10: 112786 | UQ10: 112522 | UR10: 112720 | US10: 112657 | UT10: 112342 | UU10: 112517 | UV10: 112404 | UW10: 112548 | UX10: 112804 | UY10: 112846 | UZ10: 112766 | VB10: 112354 | VC10: 112941 | VD10: 113012 | VE10: 113342 | VF10: 113225 | VG10: 113310 | VH10: 113440 | VI10: 113661 | VJ10: 113569 | VK10: 113468 | VL10: 113572 | VM10: 113726 | VO10: 113968 | VP10: 113917 | VQ10: 114269 | VR10: 114401 | VS10: 114531 | VT10: 115236 | VU10: 115319 | VV10: 115536 | VW10: 115549 | VX10: 115671 | VY10: 115909 | VZ10: 116040 | WB10: 116484 | WC10: 116518 | WD10: 116623 | WE10: 116882 | WF10: 117303 | WG10: 117629 | WH10: 117389 | WI10: 117700 | WJ10: 118344 | WK10: 118833 | WL10: 119002 | WM10: 119098 | WO10: 119303 | WP10: 119850 | WQ10: 119777 | WR10: 119671 | WS10: 119596 | WT10: 119107 | WU10: 119431 | WV10: 119491 | WW10: 119646 | WX10: 119880 | WY10: 120119 | WZ10: 120269 | XB10: 120022 | XC10: 120194 | XD10: 120616 | XE10: 120930 | XF10: 120990 | XG10: 121245 | XH10: 121504 | XI10: 121885 | XJ10: 122245 | XK10: 122621 | XL10: 122794 | XM10: 123041 | XO10: 122620 | XP10: 123094 | XQ10: 123292 | XR10: 123816 | XS10: 124156 | XT10: 124226 | XU10: 124551 | XV10: 124942 | XW10: 124955 | XX10: 125004 | XY10: 125254 | XZ10: 125186 | YB10: 125499 | YC10: 125579 | YD10: 125574 | YE10: 125746 | YF10: 126116 | YG10: 126025 | YH10: 125954 | YI10: 125738 | YJ10: 126022 | YK10: 126522 | YL10: 126659 | YM10: 126880 | YO10: 127216 | YP10: 127525 | YQ10: 127503 | YR10: 127485 | YS10: 127556 | YT10: 127897 | YU10: 127876 | YV10: 127976 | YW10: 128243 | YX10: 128418 | YY10: 128693 | YZ10: 128956 | ZB10: 129298 | ZC10: 131110 | ZD10: 131134 | ZE10: 131601 | ZF10: 131570 | ZG10: 131306 | ZH10: 131248 | ZI10: 131097 | ZJ10: 131097 | ZK10: 131395 | ZL10: 131664 | ZM10: 132007 | ZO10: 131941 | ZP10: 131858 | ZQ10: 131973 | ZR10: 131739 | ZS10: 131305 | ZT10: 131227 | ZU10: 130991 | ZV10: 130580 | ZW10: 130558 | ZX10: 130909 | ZY10: 130534 | ZZ10: 130347 | AAB10: 129970 | AAC10: 130289 | AAD10: 130541 | AAE10: 130344 | AAF10: 130487 | AAG10: 130541 | AAH10: 130737 | AAI10: 130755 | AAJ10: 131393 | AAK10: 131300 | AAL10: 130895 | AAM10: 130887 | AAO10: 130692 | AAP10: 131799 | AAQ10: 131711 | AAR10: 131826 | AAS10: 131944 | AAT10: 131772 | AAU10: 131796 | AAV10: 131630 | AAW10: 131702 | AAX10: 132061 | AAY10: 132308 | AAZ10: 132489 | ABB10: 132603 | ABC10: 132898 | ABD10: 132753 | ABE10: 132799 | ABF10: 132961 | ABG10: 133433 | ABH10: 133431 | ABI10: 133730 | ABJ10: 133638 | ABK10: 133561 | ABL10: 134094 | ABM10: 134242 | ABO10: 134291 | ABP10: 134480 | ABQ10: 134785 | ABR10: 135077 | ABS10: 135600 | ABT10: 135897 | ABU10: 135916 | ABV10: 136360 | ABW10: 136621 | ABX10: 136599 | ABY10: 136768 | ABZ10: 136650 | ACB10: 137122 | ACC10: 137643 | ACD10: 137695 | ACE10: 137608 | ACF10: 137853 | ACG10: 138172 | ACH10: 138186 | ACI10: 138364 | ACJ10: 138687 | ACK10: 139140 | ACL10: 139289 | ACM10: 139554 | ACO10: 139748 | ACP10: 139839 | ACQ10: 140142 | ACR10: 140032 | ACS10: 139889 | ACT10: 140072 | ACU10: 140199 | ACV10: 139756 | ACW10: 140179 | ACX10: 140126 | ACY10: 140427 | ACZ10: 140546 | ADB10: 140343 | ADC10: 140482 | ADD10: 140171 | ADE10: 140262 | ADF10: 140237 | ADG10: 139857 | ADH10: 139696 | ADI10: 139465 | ADJ10: 139097 | ADK10: 139089 | ADL10: 138406 | ADM10: 137761 | ADO10: 136270 | ADP10: 135729 | ADQ10: 135187 | ADR10: 134538 | ADS10: 134507 | ADT10: 134041 | ADU10: 133928 | ADV10: 133544 | ADW10: 133000 | ADX10: 132679 | ADY10: 132706 | ADZ10: 132405 | AEB10: 132169 | AEC10: 132517 | AED10: 132543 | AEE10: 132985 | AEF10: 133096 | AEG10: 133448 | AEH10: 133191 | AEI10: 133200 | AEJ10: 133602 | AEK10: 133137 | AEL10: 132916 | AEM10: 133123 | AEO10: 133221 | AEP10: 133533 | AEQ10: 133769 | AER10: 133768 | AES10: 133626 | AET10: 133627 | AEU10: 133401 | AEV10: 133901 | AEW10: 133978 | AEX10: 134231 | AEY10: 134584 | AEZ10: 134779 | AFB10: 134862 | AFC10: 136101 | AFD10: 136131 | AFE10: 136027 | AFF10: 136289 | AFG10: 136461 | AFH10: 136308 | AFI10: 136017 | AFJ10: 136776 | AFK10: 137261 | AFL10: 137457 | AFM10: 137376 | AFO10: 137431 | AFP10: 137400 | AFQ10: 137362 | AFR10: 137312 | AFS10: 137769 | AFT10: 137757 | AFU10: 138155 | AFV10: 138185 | AFW10: 138304
A11: LNS17100000 | UC11: 2152 | UD11: 1964 | UE11: 1801 | UF11: 1931 | UG11: 1945 | UH11: 1818 | UI11: 1940 | UJ11: 1764 | UK11: 2029 | UL11: 1975 | UM11: 1963 | UO11: 2016 | UP11: 2043 | UQ11: 2091 | UR11: 2341 | US11: 1979 | UT11: 2199 | UU11: 2057 | UV11: 2148 | UW11: 2247 | UX11: 2110 | UY11: 2123 | UZ11: 1936 | VB11: 2425 | VC11: 2044 | VD11: 2117 | VE11: 2181 | VF11: 2161 | VG11: 2217 | VH11: 2301 | VI11: 2188 | VJ11: 2241 | VK11: 2264 | VL11: 2252 | VM11: 2247 | VO11: 2180 | VP11: 2102 | VQ11: 2181 | VR11: 2139 | VS11: 2217 | VT11: 2119 | VU11: 2243 | VV11: 2109 | VW11: 2023 | VX11: 2115 | VY11: 2163 | VZ11: 2212 | WB11: 2171 | WC11: 2208 | WD11: 2194 | WE11: 2199 | WF11: 2249 | WG11: 2039 | WH11: 2141 | WI11: 2212 | WJ11: 2166 | WK11: 2013 | WL11: 2111 | WM11: 2235 | WO11: 2062 | WP11: 2085 | WQ11: 2044 | WR11: 2009 | WS11: 2035 | WT11: 2075 | WU11: 2060 | WV11: 2182 | WW11: 2062 | WX11: 2158 | WY11: 1969 | WZ11: 1899 | XB11: 2035 | XC11: 2044 | XD11: 2022 | XE11: 1963 | XF11: 1994 | XG11: 2039 | XH11: 2007 | XI11: 2123 | XJ11: 1976 | XK11: 2034 | XL11: 1947 | XM11: 1935 | XO11: 2187 | XP11: 2074 | XQ11: 2056 | XR11: 1976 | XS11: 2051 | XT11: 1990 | XU11: 2097 | XV11: 1811 | XW11: 1836 | XX11: 1953 | XY11: 1900 | XZ11: 1997 | YB11: 1896 | YC11: 1954 | YD11: 1876 | YE11: 2060 | YF11: 1759 | YG11: 1892 | YH11: 1883 | YI11: 1941 | YJ11: 1942 | YK11: 1918 | YL11: 1941 | YM11: 1882 | YO11: 1864 | YP11: 1873 | YQ11: 2039 | YR11: 1658 | YS11: 1867 | YT11: 1827 | YU11: 1848 | YV11: 1944 | YW11: 1871 | YX11: 1827 | YY11: 1993 | YZ11: 1944 | ZB11: 2005 | ZC11: 1784 | ZD11: 1893 | ZE11: 1940 | ZF11: 1660 | ZG11: 1850 | ZH11: 1887 | ZI11: 1831 | ZJ11: 1875 | ZK11: 1885 | ZL11: 1709 | ZM11: 1699 | ZO11: 1784 | ZP11: 1831 | ZQ11: 1892 | ZR11: 1859 | ZS11: 2034 | ZT11: 1910 | ZU11: 1956 | ZV11: 1914 | ZW11: 2045 | ZX11: 1933 | ZY11: 2121 | ZZ11: 2109 | AAB11: 2109 | AAC11: 2332 | AAD11: 2195 | AAE11: 2085 | AAF11: 2130 | AAG11: 1997 | AAH11: 2022 | AAI11: 2184 | AAJ11: 2178 | AAK11: 2041 | AAL11: 1959 | AAM11: 1977 | AAO11: 2176 | AAP11: 1966 | AAQ11: 1998 | AAR11: 2086 | AAS11: 2048 | AAT11: 2114 | AAU11: 2127 | AAV11: 2127 | AAW11: 2051 | AAX11: 2064 | AAY11: 2120 | AAZ11: 2247 | ABB11: 2058 | ABC11: 1984 | ABD11: 1925 | ABE11: 2147 | ABF11: 2088 | ABG11: 2032 | ABH11: 2151 | ABI11: 1996 | ABJ11: 2138 | ABK11: 2132 | ABL11: 2154 | ABM11: 2080 | ABO11: 2040 | ABP11: 2052 | ABQ11: 2060 | ABR11: 2060 | ABS11: 1979 | ABT11: 1978 | ABU11: 1944 | ABV11: 2119 | ABW11: 1852 | ABX11: 1954 | ABY11: 2052 | ABZ11: 1968 | ACB11: 2033 | ACC11: 1824 | ACD11: 1952 | ACE11: 1977 | ACF11: 1997 | ACG11: 2022 | ACH11: 2012 | ACI11: 2075 | ACJ11: 2081 | ACK11: 1881 | ACL11: 1932 | ACM11: 2077 | ACO11: 1945 | ACP11: 2125 | ACQ11: 2088 | ACR11: 1851 | ACS11: 1981 | ACT11: 1753 | ACU11: 1900 | ACV11: 1975 | ACW11: 1910 | ACX11: 1907 | ACY11: 1956 | ACZ11: 1951 | ADB11: 2034 | ADC11: 1965 | ADD11: 1996 | ADE11: 2122 | ADF11: 1900 | ADG11: 2016 | ADH11: 2052 | ADI11: 2087 | ADJ11: 2293 | ADK11: 2139 | ADL11: 2098 | ADM11: 2080 | ADO11: 2235 | ADP11: 2299 | ADQ11: 2212 | ADR11: 2496 | ADS11: 2251 | ADT11: 2622 | ADU11: 2577 | ADV11: 2399 | ADW11: 2581 | ADX11: 2314 | ADY11: 2585 | ADZ11: 2354 | AEB11: 2534 | AEC11: 2487 | AED11: 2600 | AEE11: 2755 | AEF11: 2676 | AEG11: 2391 | AEH11: 2505 | AEI11: 2468 | AEJ11: 2358 | AEK11: 2440 | AEL11: 2444 | AEM11: 2613 | AEO11: 2393 | AEP11: 2320 | AEQ11: 2344 | AER11: 2256 | AES11: 2360 | AET11: 2422 | AEU11: 2375 | AEV11: 2400 | AEW11: 2396 | AEX11: 2448 | AEY11: 2483 | AEZ11: 2503 | AFB11: 2407 | AFC11: 2355 | AFD11: 2324 | AFE11: 2271 | AFF11: 2263 | AFG11: 2284 | AFH11: 2280 | AFI11: 2291 | AFJ11: 2392 | AFK11: 2253 | AFL11: 2157 | AFM11: 2175 | AFO11: 2249 | AFP11: 2311 | AFQ11: 2153 | AFR11: 2260 | AFS11: 2251 | AFT11: 2330 | AFU11: 2337 | AFV11: 2243 | AFW11: 2137
A12: LNS17200000 | UC12: 3204 | UD12: 3244 | UE12: 3148 | UF12: 3119 | UG12: 2986 | UH12: 3193 | UI12: 2961 | UJ12: 2975 | UK12: 3032 | UL12: 3092 | UM12: 2962 | UO12: 2836 | UP12: 2857 | UQ12: 2982 | UR12: 2972 | US12: 2736 | UT12: 2993 | UU12: 2891 | UV12: 2868 | UW12: 3047 | UX12: 2806 | UY12: 2722 | UZ12: 2661 | VB12: 3133 | VC12: 2708 | VD12: 2921 | VE12: 2836 | VF12: 2912 | VG12: 2800 | VH12: 2933 | VI12: 2848 | VJ12: 2767 | VK12: 2814 | VL12: 2964 | VM12: 2880 | VO12: 2870 | VP12: 3167 | VQ12: 2989 | VR12: 2871 | VS12: 3271 | VT12: 2842 | VU12: 2825 | VV12: 3099 | VW12: 2891 | VX12: 2971 | VY12: 3011 | VZ12: 3093 | WB12: 3228 | WC12: 3260 | WD12: 3012 | WE12: 3102 | WF12: 3179 | WG12: 2855 | WH12: 3061 | WI12: 3308 | WJ12: 3071 | WK12: 3125 | WL12: 3274 | WM12: 3262 | WO12: 3214 | WP12: 2919 | WQ12: 3043 | WR12: 3150 | WS12: 2675 | WT12: 3215 | WU12: 3211 | WV12: 3039 | WW12: 3297 | WX12: 3215 | WY12: 3012 | WZ12: 2777 | XB12: 2989 | XC12: 3329 | XD12: 3111 | XE12: 2996 | XF12: 3131 | XG12: 3194 | XH12: 3310 | XI12: 3063 | XJ12: 3149 | XK12: 3080 | XL12: 2923 | XM12: 2741 | XO12: 3094 | XP12: 3059 | XQ12: 3450 | XR12: 3215 | XS12: 3172 | XT12: 3075 | XU12: 3096 | XV12: 3142 | XW12: 3074 | XX12: 3113 | XY12: 3381 | XZ12: 3402 | YB12: 3226 | YC12: 3202 | YD12: 3272 | YE12: 3288 | YF12: 3331 | YG12: 3196 | YH12: 3391 | YI12: 3576 | YJ12: 3871 | YK12: 3413 | YL12: 3539 | YM12: 3683 | YO12: 3621 | YP12: 3393 | YQ12: 3349 | YR12: 3736 | YS12: 3779 | YT12: 3556 | YU12: 3610 | YV12: 3572 | YW12: 3497 | YX12: 3644 | YY12: 3547 | YZ12: 3561 | ZB12: 3629 | ZC12: 3640 | ZD12: 3585 | ZE12: 3611 | ZF12: 3265 | ZG12: 3660 | ZH12: 3276 | ZI12: 3639 | ZJ12: 3775 | ZK12: 3691 | ZL12: 3831 | ZM12: 3768 | ZO12: 3972 | ZP12: 3843 | ZQ12: 3840 | ZR12: 3594 | ZS12: 3677 | ZT12: 3655 | ZU12: 4003 | ZV12: 3663 | ZW12: 4124 | ZX12: 3416 | ZY12: 3528 | ZZ12: 3505 | AAB12: 3558 | AAC12: 3766 | AAD12: 3360 | AAE12: 3637 | AAF12: 3852 | AAG12: 3765 | AAH12: 3562 | AAI12: 3718 | AAJ12: 3611 | AAK12: 3604 | AAL12: 3620 | AAM12: 3445 | AAO12: 3902 | AAP12: 3623 | AAQ12: 3623 | AAR12: 3639 | AAS12: 3478 | AAT12: 3776 | AAU12: 3487 | AAV12: 3698 | AAW12: 3757 | AAX12: 3800 | AAY12: 3886 | AAZ12: 3584 | ABB12: 3769 | ABC12: 3549 | ABD12: 3704 | ABE12: 3656 | ABF12: 3722 | ABG12: 3630 | ABH12: 3903 | ABI12: 3713 | ABJ12: 3608 | ABK12: 3937 | ABL12: 3876 | ABM12: 3726 | ABO12: 3865 | ABP12: 3757 | ABQ12: 3741 | ABR12: 4034 | ABS12: 3943 | ABT12: 3755 | ABU12: 4062 | ABV12: 3849 | ABW12: 3845 | ABX12: 3882 | ABY12: 3625 | ABZ12: 4067 | ACB12: 3968 | ACC12: 3942 | ACD12: 4015 | ACE12: 4064 | ACF12: 4122 | ACG12: 4089 | ACH12: 3881 | ACI12: 4108 | ACJ12: 3933 | ACK12: 4163 | ACL12: 4225 | ACM12: 4295 | ACO12: 4146 | ACP12: 4044 | ACQ12: 4018 | ACR12: 3609 | ACS12: 3966 | ACT12: 4095 | ACU12: 3745 | ACV12: 3888 | ACW12: 4052 | ACX12: 3818 | ACY12: 4122 | ACZ12: 3668 | ADB12: 3964 | ADC12: 3645 | ADD12: 3830 | ADE12: 3695 | ADF12: 3715 | ADG12: 3765 | ADH12: 3733 | ADI12: 3564 | ADJ12: 3608 | ADK12: 3517 | ADL12: 3481 | ADM12: 3441 | ADO12: 3637 | ADP12: 3525 | ADQ12: 3294 | ADR12: 3571 | ADS12: 3412 | ADT12: 3281 | ADU12: 3368 | ADV12: 3425 | ADW12: 3155 | ADX12: 3360 | ADY12: 3296 | ADZ12: 3228 | AEB12: 3725 | AEC12: 3555 | AED12: 3542 | AEE12: 3489 | AEF12: 3413 | AEG12: 3281 | AEH12: 3437 | AEI12: 3638 | AEJ12: 3387 | AEK12: 3414 | AEL12: 3608 | AEM12: 3525 | AEO12: 3612 | AEP12: 3598 | AEQ12: 3481 | AER12: 3528 | AES12: 3612 | AET12: 3307 | AEU12: 3710 | AEV12: 3502 | AEW12: 3752 | AEX12: 3571 | AEY12: 3650 | AEZ12: 3516 | AFB12: 3462 | AFC12: 3544 | AFD12: 3490 | AFE12: 3565 | AFF12: 3693 | AFG12: 3634 | AFH12: 3629 | AFI12: 3802 | AFJ12: 3746 | AFK12: 3715 | AFL12: 3628 | AFM12: 3684 | AFO12: 3566 | AFP12: 3716 | AFQ12: 3724 | AFR12: 3912 | AFS12: 3806 | AFT12: 3907 | AFU12: 3774 | AFV12: 3711 | AFW12: 3790
A13: LNS17300000 | UC13: 53 | UD13: 85 | UE13: 87 | UF13: 73 | UG13: 81 | UH13: 97 | UI13: 92 | UJ13: 110 | UK13: 108 | UL13: 73 | UM13: 87 | UO13: 81 | UP13: 69 | UQ13: 56 | UR13: 76 | US13: 68 | UT13: 105 | UU13: 103 | UV13: 63 | UW13: 85 | UX13: 80 | UY13: 80 | UZ13: 103 | VB13: 66 | VC13: 60 | VD13: 94 | VE13: 68 | VF13: 77 | VG13: 93 | VH13: 39 | VI13: 129 | VJ13: 143 | VK13: 83 | VL13: 88 | VM13: 144 | VO13: 57 | VP13: 89 | VQ13: 104 | VR13: 63 | VS13: 95 | VT13: 94 | VU13: 81 | VV13: 112 | VW13: 90 | VX13: 66 | VY13: 86 | VZ13: 119 | WB13: 83 | WC13: 101 | WD13: 101 | WE13: 107 | WF13: 133 | WG13: 110 | WH13: 115 | WI13: 122 | WJ13: 107 | WK13: 142 | WL13: 129 | WM13: 126 | WO13: 84 | WP13: 74 | WQ13: 92 | WR13: 115 | WS13: 114 | WT13: 125 | WU13: 114 | WV13: 140 | WW13: 129 | WX13: 135 | WY13: 87 | WZ13: 144 | XB13: 78 | XC13: 72 | XD13: 113 | XE13: 105 | XF13: 128 | XG13: 124 | XH13: 127 | XI13: 100 | XJ13: 165 | XK13: 155 | XL13: 107 | XM13: 144 | XO13: 397 | XP13: 72 | XQ13: 92 | XR13: 136 | XS13: 86 | XT13: 121 | XU13: 78 | XV13: 115 | XW13: 154 | XX13: 110 | XY13: 118 | XZ13: 94 | YB13: 105 | YC13: 73 | YD13: 93 | YE13: 116 | YF13: 119 | YG13: 131 | YH13: 101 | YI13: 136 | YJ13: 150 | YK13: 146 | YL13: 142 | YM13: 157 | YO13: 326 | YP13: 65 | YQ13: 56 | YR13: 75 | YS13: 108 | YT13: 98 | YU13: 80 | YV13: 99 | YW13: 96 | YX13: 103 | YY13: 76 | YZ13: 63 | ZB13: 1627 | ZC13: 65 | ZD13: 89 | ZE13: 118 | ZF13: 135 | ZG13: 124 | ZH13: 121 | ZI13: 95 | ZJ13: 145 | ZK13: 117 | ZL13: 118 | ZM13: 140 | ZO13: 81 | ZP13: 79 | ZQ13: 78 | ZR13: 107 | ZS13: 76 | ZT13: 81 | ZU13: 121 | ZV13: 85 | ZW13: 119 | ZX13: 134 | ZY13: 55 | ZZ13: 85 | AAB13: 64 | AAC13: 52 | AAD13: 81 | AAE13: 61 | AAF13: 70 | AAG13: 111 | AAH13: 92 | AAI13: 48 | AAJ13: 119 | AAK13: 63 | AAL13: 47 | AAM13: 117 | AAO13: 647 | AAP13: 93 | AAQ13: 103 | AAR13: 81 | AAS13: 74 | AAT13: 128 | AAU13: 64 | AAV13: 93 | AAW13: 100 | AAX13: 59 | AAY13: 109 | AAZ13: 91 | ABB13: 42 | ABC13: 111 | ABD13: 71 | ABE13: 78 | ABF13: 81 | ABG13: 79 | ABH13: 71 | ABI13: 135 | ABJ13: 104 | ABK13: 101 | ABL13: 107 | ABM13: 77 | ABO13: 48 | ABP13: 96 | ABQ13: 67 | ABR13: 83 | ABS13: 88 | ABT13: 83 | ABU13: 104 | ABV13: 105 | ABW13: 84 | ABX13: 114 | ABY13: 54 | ABZ13: 67 | ACB13: 27 | ACC13: 48 | ACD13: 79 | ACE13: 113 | ACF13: 117 | ACG13: 69 | ACH13: 123 | ACI13: 78 | ACJ13: 114 | ACK13: 130 | ACL13: 88 | ACM13: 45 | ACO13: 189 | ACP13: 48 | ACQ13: 72 | ACR13: 93 | ACS13: 67 | ACT13: 143 | ACU13: 61 | ACV13: 64 | ACW13: 102 | ACX13: 96 | ACY13: 89 | ACZ13: 109 | ADB13: 37 | ADC13: 64 | ADD13: 88 | ADE13: 53 | ADF13: 56 | ADG13: 99 | ADH13: 50 | ADI13: 87 | ADJ13: 79 | ADK13: 58 | ADL13: 117 | ADM13: 87 | ADO13: 12 | ADP13: 91 | ADQ13: 28 | ADR13: 47 | ADS13: 80 | ADT13: 62 | ADU13: 25 | ADV13: 113 | ADW13: 75 | ADX13: 68 | ADY13: 78 | ADZ13: 38 | AEB13: 10 | AEC13: 66 | AED13: 82 | AEE13: 67 | AEF13: 69 | AEG13: 28 | AEH13: 34 | AEI13: 98 | AEJ13: 41 | AEK13: 106 | AEL13: 78 | AEM13: 33 | AEO13: 27 | AEP13: 20 | AEQ13: 48 | AER13: 53 | AES13: 82 | AET13: 49 | AEU13: 23 | AEV13: 68 | AEW13: 38 | AEX13: 64 | AEY13: 54 | AEZ13: 98 | AFB13: 877 | AFC13: 18 | AFD13: 75 | AFE13: 71 | AFF13: 58 | AFG13: 69 | AFH13: 34 | AFI13: 55 | AFJ13: 59 | AFK13: 99 | AFL13: 34 | AFM13: 69 | AFO13: 76 | AFP13: 65 | AFQ13: 47 | AFR13: 95 | AFS13: 71 | AFT13: 64 | AFU13: 19 | AFV13: 31 | AFW13: 72
A14: LNS13000000 | B14: 2034 | C14: 2328 | D14: 2399 | E14: 2386 | F14: 2118 | G14: 2214 | H14: 2213 | I14: 2350 | J14: 2302 | K14: 2259 | L14: 2285 | M14: 2429 | O14: 2596 | P14: 2849 | Q14: 3030 | R14: 3260 | S14: 3707 | T14: 3776 | U14: 4111 | V14: 4193 | W14: 4049 | X14: 4916 | Y14: 3996 | Z14: 4063 | AB14: 4026 | AC14: 3936 | AD14: 3876 | AE14: 3575 | AF14: 3434 | AG14: 3367 | AH14: 3120 | AI14: 2799 | AJ14: 2774 | AK14: 2625 | AL14: 2589 | AM14: 2639 | AO14: 2305 | AP14: 2117 | AQ14: 2125 | AR14: 1919 | AS14: 1856 | AT14: 1995 | AU14: 1950 | AV14: 1933 | AW14: 2067 | AX14: 2194 | AY14: 2178 | AZ14: 1960 | BB14: 1972 | BC14: 1957 | BD14: 1813 | BE14: 1811 | BF14: 1863 | BG14: 1884 | BH14: 1991 | BI14: 2087 | BJ14: 1936 | BK14: 1839 | BL14: 1743 | BM14: 1667 | BO14: 1839 | BP14: 1636 | BQ14: 1647 | BR14: 1723 | BS14: 1596 | BT14: 1607 | BU14: 1660 | BV14: 1665 | BW14: 1821 | BX14: 1974 | BY14: 2211 | BZ14: 2818 | CB14: 3077 | CC14: 3331 | CD14: 3607 | CE14: 3749 | CF14: 3767 | CG14: 3551 | CH14: 3659 | CI14: 3854 | CJ14: 3927 | CK14: 3666 | CL14: 3402 | CM14: 3196 | CO14: 3157 | CP14: 2969 | CQ14: 2918 | CR14: 3049 | CS14: 2747 | CT14: 2701 | CU14: 2632 | CV14: 2784 | CW14: 2678 | CX14: 2830 | CY14: 2780 | CZ14: 2761 | DB14: 2666 | DC14: 2606 | DD14: 2764 | DE14: 2650 | DF14: 2861 | DG14: 2882 | DH14: 2952 | DI14: 2701 | DJ14: 2635 | DK14: 2571 | DL14: 2861 | DM14: 2790 | DO14: 2796 | DP14: 2622 | DQ14: 2509 | DR14: 2600 | DS14: 2710 | DT14: 2856 | DU14: 2796 | DV14: 2747 | DW14: 2943 | DX14: 3020 | DY14: 3454 | DZ14: 3476 | EB14: 3875 | EC14: 4303 | ED14: 4492 | EE14: 5016 | EF14: 5021 | EG14: 4944 | EH14: 5079 | EI14: 5025 | EJ14: 4821 | EK14: 4570 | EL14: 4188 | EM14: 4191 | EO14: 4068 | EP14: 3965 | EQ14: 3801 | ER14: 3571 | ES14: 3479 | ET14: 3429 | EU14: 3528 | EV14: 3588 | EW14: 3775 | EX14: 3910 | EY14: 4003 | EZ14: 3653 | FB14: 3615 | FC14: 3329 | FD14: 3726 | FE14: 3620 | FF14: 3569 | FG14: 3766 | FH14: 3836 | FI14: 3946 | FJ14: 3884 | FK14: 4252 | FL14: 4330 | FM14: 4617 | FO14: 4671 | FP14: 4832 | FQ14: 4853 | FR14: 4893 | FS14: 5003 | FT14: 4885 | FU14: 4928 | FV14: 4682 | FW14: 4676 | FX14: 4573 | FY14: 4295 | FZ14: 4177 | GB14: 4081 | GC14: 3871 | GD14: 3921 | GE14: 3906 | GF14: 3863 | GG14: 3844 | GH14: 3819 | GI14: 4013 | GJ14: 3961 | GK14: 3803 | GL14: 4024 | GM14: 3907 | GO14: 4074 | GP14: 4238 | GQ14: 4072 | GR14: 4055 | GS14: 4217 | GT14: 3977 | GU14: 4051 | GV14: 3878 | GW14: 3957 | GX14: 3987 | GY14: 4151 | GZ14: 3975 | HB14: 4029 | HC14: 3932 | HD14: 3950 | HE14: 3918 | HF14: 3764 | HG14: 3814 | HH14: 3608 | HI14: 3655 | HJ14: 3712 | HK14: 3726 | HL14: 3551 | HM14: 3651 | HO14: 3572 | HP14: 3730 | HQ14: 3510 | HR14: 3595 | HS14: 3432 | HT14: 3387 | HU14: 3301 | HV14: 3254 | HW14: 3216 | HX14: 3143 | HY14: 3073 | HZ14: 3031 | IB14: 2988 | IC14: 2820 | ID14: 2887 | IE14: 2828 | IF14: 2950 | IG14: 2872 | IH14: 2876 | II14: 2900 | IJ14: 2798 | IK14: 2798 | IL14: 2770 | IM14: 2912 | IO14: 2968 | IP14: 2915 | IQ14: 2889 | IR14: 2895 | IS14: 2929 | IT14: 2992 | IU14: 2944 | IV14: 2945 | IW14: 2958 | IX14: 3143 | IY14: 3066 | IZ14: 3018 | JB14: 2878 | JC14: 3001 | JD14: 2877 | JE14: 2709 | JF14: 2740 | JG14: 2938 | JH14: 2883 | JI14: 2768 | JJ14: 2686 | JK14: 2689 | JL14: 2715 | JM14: 2685 | JO14: 2718 | JP14: 2692 | JQ14: 2712 | JR14: 2758 | JS14: 2713 | JT14: 2816 | JU14: 2868 | JV14: 2856 | JW14: 3040 | JX14: 3049 | JY14: 2856 | JZ14: 2884 | KB14: 3201 | KC14: 3453 | KD14: 3635 | KE14: 3797 | KF14: 3919 | KG14: 4071 | KH14: 4175 | KI14: 4256 | KJ14: 4456 | KK14: 4591 | KL14: 4898 | KM14: 5076 | KO14: 4986 | KP14: 4903 | KQ14: 4987 | KR14: 4959 | KS14: 4996 | KT14: 4949 | KU14: 5035 | KV14: 5134 | KW14: 5042 | KX14: 4954 | KY14: 5161 | KZ14: 5154 | LB14: 5019 | LC14: 4928 | LD14: 5038 | LE14: 4959 | LF14: 4922 | LG14: 4923 | LH14: 4913 | LI14: 4939 | LJ14: 4849 | LK14: 4875 | LL14: 4602 | LM14: 4543 | LO14: 4326 | LP14: 4452 | LQ14: 4394 | LR14: 4459 | LS14: 4329 | LT14: 4363 | LU14: 4305 | LV14: 4305 | LW14: 4350 | LX14: 4144 | LY14: 4396 | LZ14: 4489 | MB14: 4644 | MC14: 4731 | MD14: 4634 | ME14: 4618 | MF14: 4705 | MG14: 4927 | MH14: 5063 | MI14: 5022 | MJ14: 5437 | MK14: 5523 | ML14: 6140 | MM14: 6636 | MO14: 7501 | MP14: 7520 | MQ14: 7978 | MR14: 8210 | MS14: 8433 | MT14: 8220 | MU14: 8127 | MV14: 7928 | MW14: 7923 | MX14: 7897 | MY14: 7794 | MZ14: 7744 | NB14: 7534 | NC14: 7326 | ND14: 7230 | NE14: 7330 | NF14: 7053 | NG14: 7322 | NH14: 7490 | NI14: 7518 | NJ14: 7380 | NK14: 7430 | NL14: 7620 | NM14: 7545 | NO14: 7280 | NP14: 7443 | NQ14: 7307 | NR14: 7059 | NS14: 6911 | NT14: 7134 | NU14: 6829 | NV14: 6925 | NW14: 6751 | NX14: 6763 | NY14: 6815 | NZ14: 6386 | OB14: 6489 | OC14: 6318 | OD14: 6337 | OE14: 6180 | OF14: 6127 | OG14: 6028 | OH14: 6309 | OI14: 6080 | OJ14: 6125 | OK14: 5947 | OL14: 6077 | OM14: 6228 | OO14: 6109 | OP14: 6173 | OQ14: 6109 | OR14: 6069 | OS14: 5840 | OT14: 5959 | OU14: 5996 | OV14: 6320 | OW14: 6190 | OX14: 6296 | OY14: 6238 | OZ14: 6325 | PB14: 6683 | PC14: 6702 | PD14: 6729 | PE14: 7358 | PF14: 7984 | PG14: 8098 | PH14: 8363 | PI14: 8281 | PJ14: 8021 | PK14: 8088 | PL14: 8023 | PM14: 7718 | PO14: 8071 | PP14: 8051 | PQ14: 7982 | PR14: 7869 | PS14: 8174 | PT14: 8098 | PU14: 7863 | PV14: 8036 | PW14: 8230 | PX14: 8646 | PY14: 9029 | PZ14: 9267 | QB14: 9397 | QC14: 9705 | QD14: 9895 | QE14: 10244 | QF14: 10335 | QG14: 10538 | QH14: 10849 | QI14: 10881 | QJ14: 11217 | QK14: 11529 | QL14: 11938 | QM14: 12051 | QO14: 11534 | QP14: 11545 | QQ14: 11408 | QR14: 11268 | QS14: 11154 | QT14: 11246 | QU14: 10548 | QV14: 10623 | QW14: 10282 | QX14: 9887 | QY14: 9499 | QZ14: 9331 | RB14: 9008 | RC14: 8791 | RD14: 8746 | RE14: 8762 | RF14: 8456 | RG14: 8226 | RH14: 8537 | RI14: 8519 | RJ14: 8367 | RK14: 8381 | RL14: 8198 | RM14: 8358 | RO14: 8423 | RP14: 8321 | RQ14: 8339 | RR14: 8395 | RS14: 8302 | RT14: 8460 | RU14: 8513 | RV14: 8196 | RW14: 8248 | RX14: 8298 | RY14: 8128 | RZ14: 8138 | SB14: 7795 | SC14: 8402 | SD14: 8383 | SE14: 8364 | SF14: 8439 | SG14: 8508 | SH14: 8319 | SI14: 8135 | SJ14: 8310 | SK14: 8243 | SL14: 8159 | SM14: 7883 | SO14: 7892 | SP14: 7865 | SQ14: 7862 | SR14: 7542 | SS14: 7574 | ST14: 7398 | SU14: 7268 | SV14: 7261 | SW14: 7102 | SX14: 7227 | SY14: 7035 | SZ14: 6936 | TB14: 6953 | TC14: 6929 | TD14: 6876 | TE14: 6601 | TF14: 6779 | TG14: 6546 | TH14: 6605 | TI14: 6843 | TJ14: 6604 | TK14: 6568 | TL14: 6537 | TM14: 6518 | TO14: 6682 | TP14: 6359 | TQ14: 6205 | TR14: 6468 | TS14: 6375 | TT14: 6577 | TU14: 6495 | TV14: 6511 | TW14: 6590 | TX14: 6630 | TY14: 6725 | TZ14: 6667 | UB14: 6752 | UC14: 6651 | UD14: 6598 | UE14: 6797 | UF14: 6742 | UG14: 6590 | UH14: 6922 | UI14: 7188 | UJ14: 7368 | UK14: 7459 | UL14: 7764 | UM14: 7901 | UO14: 8015 | UP14: 8265 | UQ14: 8586 | UR14: 8439 | US14: 8736 | UT14: 8692 | UU14: 8586 | UV14: 8666 | UW14: 8722 | UX14: 8842 | UY14: 8931 | UZ14: 9198 | VB14: 9283 | VC14: 9454 | VD14: 9460 | VE14: 9415 | VF14: 9744 | VG14: 10040 | VH14: 9850 | VI14: 9787 | VJ14: 9781 | VK14: 9398 | VL14: 9565 | VM14: 9557 | VO14: 9325 | VP14: 9183 | VQ14: 9056 | VR14: 9110 | VS14: 9149 | VT14: 9121 | VU14: 8930 | VV14: 8763 | VW14: 8714 | VX14: 8750 | VY14: 8542 | VZ14: 8477 | WB14: 8630 | WC14: 8583 | WD14: 8470 | WE14: 8331 | WF14: 7915 | WG14: 7927 | WH14: 7946 | WI14: 7933 | WJ14: 7734 | WK14: 7632 | WL14: 7375 | WM14: 7230 | WO14: 7375 | WP14: 7187 | WQ14: 7153 | WR14: 7645 | WS14: 7430 | WT14: 7427 | WU14: 7527 | WV14: 7484 | WW14: 7478 | WX14: 7328 | WY14: 7426 | WZ14: 7423 | XB14: 7491 | XC14: 7313 | XD14: 7318 | XE14: 7415 | XF14: 7423 | XG14: 7095 | XH14: 7337 | XI14: 6882 | XJ14: 6979 | XK14: 7031 | XL14: 7236 | XM14: 7253 | XO14: 7158 | XP14: 7102 | XQ14: 7000 | XR14: 6873 | XS14: 6655 | XT14: 6799 | XU14: 6655 | XV14: 6608 | XW14: 6656 | XX14: 6454 | XY14: 6308 | XZ14: 6476 | YB14: 6368 | YC14: 6306 | YD14: 6422 | YE14: 5941 | YF14: 6047 | YG14: 6212 | YH14: 6259 | YI14: 6179 | YJ14: 6300 | YK14: 6280 | YL14: 6100 | YM14: 6032 | YO14: 5976 | YP14: 6111 | YQ14: 5783 | YR14: 6004 | YS14: 5796 | YT14: 5951 | YU14: 6025 | YV14: 5838 | YW14: 5915 | YX14: 5778 | YY14: 5716 | YZ14: 5653 | ZB14: 5708 | ZC14: 5858 | ZD14: 5733 | ZE14: 5481 | ZF14: 5758 | ZG14: 5651 | ZH14: 5747 | ZI14: 5853 | ZJ14: 5625 | ZK14: 5534 | ZL14: 5639 | ZM14: 5634 | ZO14: 6023 | ZP14: 6089 | ZQ14: 6141 | ZR14: 6271 | ZS14: 6226 | ZT14: 6484 | ZU14: 6583 | ZV14: 7042 | ZW14: 7142 | ZX14: 7694 | ZY14: 8003 | ZZ14: 8258 | AAB14: 8182 | AAC14: 8215 | AAD14: 8304 | AAE14: 8599 | AAF14: 8399 | AAG14: 8393 | AAH14: 8390 | AAI14: 8304 | AAJ14: 8251 | AAK14: 8307 | AAL14: 8520 | AAM14: 8640 | AAO14: 8520 | AAP14: 8618 | AAQ14: 8588 | AAR14: 8842 | AAS14: 8957 | AAT14: 9266 | AAU14: 9011 | AAV14: 8896 | AAW14: 8921 | AAX14: 8732 | AAY14: 8576 | AAZ14: 8317 | ABB14: 8370 | ABC14: 8167 | ABD14: 8491 | ABE14: 8170 | ABF14: 8212 | ABG14: 8286 | ABH14: 8136 | ABI14: 7990 | ABJ14: 7927 | ABK14: 8061 | ABL14: 7932 | ABM14: 7934 | ABO14: 7784 | ABP14: 7980 | ABQ14: 7737 | ABR14: 7672 | ABS14: 7651 | ABT14: 7524 | ABU14: 7406 | ABV14: 7345 | ABW14: 7553 | ABX14: 7453 | ABY14: 7566 | ABZ14: 7279 | ACB14: 7064 | ACC14: 7184 | ACD14: 7072 | ACE14: 7120 | ACF14: 6980 | ACG14: 7001 | ACH14: 7175 | ACI14: 7091 | ACJ14: 6847 | ACK14: 6727 | ACL14: 6872 | ACM14: 6762 | ACO14: 7116 | ACP14: 6927 | ACQ14: 6731 | ACR14: 6850 | ACS14: 6766 | ACT14: 6979 | ACU14: 7149 | ACV14: 7067 | ACW14: 7170 | ACX14: 7237 | ACY14: 7240 | ACZ14: 7645 | ADB14: 7685 | ADC14: 7497 | ADD14: 7822 | ADE14: 7637 | ADF14: 8395 | ADG14: 8575 | ADH14: 8937 | ADI14: 9438 | ADJ14: 9494 | ADK14: 10074 | ADL14: 10538 | ADM14: 11286 | ADO14: 12079 | ADP14: 12881 | ADQ14: 13421 | ADR14: 13826 | ADS14: 14492 | ADT14: 14705 | ADU14: 14607 | ADV14: 14819 | ADW14: 15005 | ADX14: 15382 | ADY14: 15223 | ADZ14: 15095 | AEB14: 15016 | AEC14: 15078 | AED14: 15192 | AEE14: 15281 | AEF14: 14856 | AEG14: 14475 | AEH14: 14542 | AEI14: 14673 | AEJ14: 14577 | AEK14: 14584 | AEL14: 15094 | AEM14: 14354 | AEO14: 13992 | AEP14: 13798 | AEQ14: 13716 | AER14: 13872 | AES14: 13871 | AET14: 13964 | AEU14: 13817 | AEV14: 13837 | AEW14: 13910 | AEX14: 13696 | AEY14: 13325 | AEZ14: 13049 | AFB14: 12748 | AFC14: 12806 | AFD14: 12686 | AFE14: 12518 | AFF14: 12695 | AFG14: 12701 | AFH14: 12745 | AFI14: 12483 | AFJ14: 12082 | AFK14: 12248 | AFL14: 12042 | AFM14: 12206 | AFO14: 12332 | AFP14: 12032 | AFQ14: 11742 | AFR14: 11659 | AFS14: 11760 | AFT14: 11777 | AFU14: 11514 | AFV14: 11316 | AFW14: 11255
A15: LNS17400000 | UC15: 1823 | UD15: 1764 | UE15: 1873 | UF15: 1676 | UG15: 1771 | UH15: 1941 | UI15: 1877 | UJ15: 1752 | UK15: 1902 | UL15: 2034 | UM15: 1874 | UO15: 1978 | UP15: 2084 | UQ15: 2130 | UR15: 1956 | US15: 2077 | UT15: 1909 | UU15: 1947 | UV15: 2043 | UW15: 1959 | UX15: 2019 | UY15: 1935 | UZ15: 1975 | VB15: 2150 | VC15: 2035 | VD15: 1773 | VE15: 1915 | VF15: 2028 | VG15: 2057 | VH15: 1940 | VI15: 1950 | VJ15: 2087 | VK15: 1923 | VL15: 1994 | VM15: 2019 | VO15: 1818 | VP15: 1903 | VQ15: 1930 | VR15: 1894 | VS15: 1895 | VT15: 1872 | VU15: 1925 | VV15: 1807 | VW15: 1852 | VX15: 1852 | VY15: 1807 | VZ15: 1932 | WB15: 1884 | WC15: 1898 | WD15: 1852 | WE15: 1898 | WF15: 1776 | WG15: 1875 | WH15: 1910 | WI15: 1848 | WJ15: 1783 | WK15: 1606 | WL15: 1791 | WM15: 1867 | WO15: 1969 | WP15: 1700 | WQ15: 1829 | WR15: 1873 | WS15: 1784 | WT15: 1871 | WU15: 1820 | WV15: 1910 | WW15: 1895 | WX15: 1857 | WY15: 1798 | WZ15: 1657 | XB15: 1867 | XC15: 1677 | XD15: 1752 | XE15: 1750 | XF15: 1787 | XG15: 1754 | XH15: 1765 | XI15: 1634 | XJ15: 1792 | XK15: 1666 | XL15: 1849 | XM15: 1604 | XO15: 1863 | XP15: 1789 | XQ15: 1650 | XR15: 1724 | XS15: 1639 | XT15: 1865 | XU15: 1685 | XV15: 1578 | XW15: 1667 | XX15: 1691 | XY15: 1596 | XZ15: 1880 | YB15: 1685 | YC15: 1750 | YD15: 1781 | YE15: 1586 | YF15: 1656 | YG15: 1661 | YH15: 1739 | YI15: 1684 | YJ15: 1758 | YK15: 1684 | YL15: 1643 | YM15: 1751 | YO15: 1576 | YP15: 1736 | YQ15: 1591 | YR15: 1682 | YS15: 1685 | YT15: 1662 | YU15: 1611 | YV15: 1603 | YW15: 1527 | YX15: 1613 | YY15: 1613 | YZ15: 1620 | ZB15: 1614 | ZC15: 1678 | ZD15: 1646 | ZE15: 1532 | ZF15: 1688 | ZG15: 1597 | ZH15: 1751 | ZI15: 1718 | ZJ15: 1643 | ZK15: 1549 | ZL15: 1444 | ZM15: 1472 | ZO15: 1758 | ZP15: 1729 | ZQ15: 1782 | ZR15: 1827 | ZS15: 1810 | ZT15: 1877 | ZU15: 1833 | ZV15: 1946 | ZW15: 1823 | ZX15: 2025 | ZY15: 2109 | ZZ15: 1986 | AAB15: 2130 | AAC15: 1950 | AAD15: 1884 | AAE15: 2008 | AAF15: 1797 | AAG15: 1989 | AAH15: 1935 | AAI15: 1934 | AAJ15: 1878 | AAK15: 2004 | AAL15: 2050 | AAM15: 1911 | AAO15: 2008 | AAP15: 1886 | AAQ15: 1959 | AAR15: 1978 | AAS15: 2000 | AAT15: 1949 | AAU15: 1882 | AAV15: 2041 | AAW15: 1931 | AAX15: 1733 | AAY15: 1832 | AAZ15: 1922 | ABB15: 1729 | ABC15: 1806 | ABD15: 1857 | ABE15: 1787 | ABF15: 1851 | ABG15: 1777 | ABH15: 1823 | ABI15: 1858 | ABJ15: 1907 | ABK15: 1890 | ABL15: 1801 | ABM15: 1848 | ABO15: 1814 | ABP15: 1853 | ABQ15: 1730 | ABR15: 1692 | ABS15: 1738 | ABT15: 1822 | ABU15: 1783 | ABV15: 1769 | ABW15: 1853 | ABX15: 1736 | ABY15: 1685 | ABZ15: 1732 | ACB15: 1595 | ACC15: 1692 | ACD15: 1728 | ACE15: 1882 | ACF15: 1754 | ACG15: 1752 | ACH15: 1900 | ACI15: 1725 | ACJ15: 1761 | ACK15: 1749 | ACL15: 1814 | ACM15: 1820 | ACO15: 1917 | ACP15: 1833 | ACQ15: 1701 | ACR15: 1763 | ACS15: 1712 | ACT15: 1774 | ACU15: 1843 | ACV15: 1714 | ACW15: 1795 | ACX15: 1818 | ACY15: 1725 | ACZ15: 1866 | ADB15: 1780 | ADC15: 1817 | ADD15: 2005 | ADE15: 1915 | ADF15: 2054 | ADG15: 1996 | ADH15: 1967 | ADI15: 2288 | ADJ15: 2140 | ADK15: 2259 | ADL15: 2506 | ADM15: 2519 | ADO15: 2764 | ADP15: 2827 | ADQ15: 2651 | ADR15: 2483 | ADS15: 2650 | ADT15: 2558 | ADU15: 2471 | ADV15: 2566 | ADW15: 2625 | ADX15: 2521 | ADY15: 2283 | ADZ15: 2379 | AEB15: 2240 | AEC15: 2329 | AED15: 2316 | AEE15: 2277 | AEF15: 2347 | AEG15: 2183 | AEH15: 2319 | AEI15: 2411 | AEJ15: 2229 | AEK15: 2245 | AEL15: 2575 | AEM15: 2207 | AEO15: 2163 | AEP15: 2024 | AEQ15: 2124 | AER15: 2276 | AES15: 2207 | AET15: 2156 | AEU15: 2135 | AEV15: 2043 | AEW15: 2384 | AEX15: 2170 | AEY15: 2104 | AEZ15: 2053 | AFB15: 1983 | AFC15: 1943 | AFD15: 2091 | AFE15: 2004 | AFF15: 1950 | AFG15: 2068 | AFH15: 2160 | AFI15: 2130 | AFJ15: 1897 | AFK15: 2017 | AFL15: 1908 | AFM15: 2123 | AFO15: 2104 | AFP15: 1884 | AFQ15: 1902 | AFR15: 2008 | AFS15: 1961 | AFT15: 2114 | AFU15: 1957 | AFV15: 2007 | AFW15: 1887
A16: LNS17500000 | UC16: 3238 | UD16: 3219 | UE16: 3402 | UF16: 3551 | UG16: 3402 | UH16: 3379 | UI16: 3625 | UJ16: 4045 | UK16: 3924 | UL16: 4027 | UM16: 4310 | UO16: 4302 | UP16: 4446 | UQ16: 4662 | UR16: 4751 | US16: 4846 | UT16: 4924 | UU16: 4969 | UV16: 4825 | UW16: 4829 | UX16: 4936 | UY16: 5123 | UZ16: 5321 | VB16: 5155 | VC16: 5696 | VD16: 5713 | VE16: 5538 | VF16: 5620 | VG16: 5899 | VH16: 5894 | VI16: 5939 | VJ16: 5741 | VK16: 5607 | VL16: 5536 | VM16: 5504 | VO16: 5628 | VP16: 5376 | VQ16: 5269 | VR16: 5265 | VS16: 5360 | VT16: 5451 | VU16: 5152 | VV16: 5131 | VW16: 5021 | VX16: 4969 | VY16: 4895 | VZ16: 4644 | WB16: 4641 | WC16: 4638 | WD16: 4477 | WE16: 4361 | WF16: 4181 | WG16: 3913 | WH16: 3952 | WI16: 3955 | WJ16: 3994 | WK16: 3997 | WL16: 3700 | WM16: 3431 | WO16: 3483 | WP16: 3603 | WQ16: 3566 | WR16: 3609 | WS16: 3775 | WT16: 3658 | WU16: 3705 | WV16: 3650 | WW16: 3636 | WX16: 3508 | WY16: 3663 | WZ16: 3808 | XB16: 3704 | XC16: 3687 | XD16: 3601 | XE16: 3713 | XF16: 3666 | XG16: 3544 | XH16: 3486 | XI16: 3541 | XJ16: 3264 | XK16: 3479 | XL16: 3466 | XM16: 3707 | XO16: 3418 | XP16: 3474 | XQ16: 3475 | XR16: 3379 | XS16: 3228 | XT16: 3126 | XU16: 3162 | XV16: 3165 | XW16: 3237 | XX16: 3115 | XY16: 3041 | XZ16: 2831 | YB16: 3026 | YC16: 2807 | YD16: 2842 | YE16: 2778 | YF16: 2748 | YG16: 2823 | YH16: 2854 | YI16: 2856 | YJ16: 2788 | YK16: 2870 | YL16: 2742 | YM16: 2641 | YO16: 2674 | YP16: 2660 | YQ16: 2599 | YR16: 2684 | YS16: 2607 | YT16: 2653 | YU16: 2741 | YV16: 2666 | YW16: 2673 | YX16: 2630 | YY16: 2380 | YZ16: 2370 | ZB16: 2391 | ZC16: 2527 | ZD16: 2513 | ZE16: 2393 | ZF16: 2440 | ZG16: 2415 | ZH16: 2473 | ZI16: 2492 | ZJ16: 2479 | ZK16: 2466 | ZL16: 2578 | ZM16: 2643 | ZO16: 2591 | ZP16: 2754 | ZQ16: 2717 | ZR16: 2745 | ZS16: 2773 | ZT16: 2877 | ZU16: 3071 | ZV16: 3214 | ZW16: 3446 | ZX16: 3646 | ZY16: 3948 | ZZ16: 4213 | AAB16: 4350 | AAC16: 4240 | AAD16: 4364 | AAE16: 4567 | AAF16: 4653 | AAG16: 4614 | AAH16: 4395 | AAI16: 4491 | AAJ16: 4411 | AAK16: 4429 | AAL16: 4527 | AAM16: 4764 | AAO16: 4475 | AAP16: 4756 | AAQ16: 4604 | AAR16: 4722 | AAS16: 4895 | AAT16: 5012 | AAU16: 5132 | AAV16: 4866 | AAW16: 4932 | AAX16: 4856 | AAY16: 4765 | AAZ16: 4435 | ABB16: 4579 | ABC16: 4436 | ABD16: 4370 | ABE16: 4464 | ABF16: 4314 | ABG16: 4381 | ABH16: 4287 | ABI16: 4164 | ABJ16: 3966 | ABK16: 4053 | ABL16: 4125 | ABM16: 4053 | ABO16: 4158 | ABP16: 4083 | ABQ16: 4065 | ABR16: 3959 | ABS16: 3915 | ABT16: 3852 | ABU16: 3762 | ABV16: 3565 | ABW16: 3712 | ABX16: 3780 | ABY16: 3686 | ABZ16: 3593 | ACB16: 3440 | ACC16: 3566 | ACD16: 3485 | ACE16: 3362 | ACF16: 3376 | ACG16: 3222 | ACH16: 3276 | ACI16: 3360 | ACJ16: 3325 | ACK16: 3226 | ACL16: 3305 | ACM16: 3194 | ACO16: 3272 | ACP16: 3248 | ACQ16: 3207 | ACR16: 3377 | ACS16: 3308 | ACT16: 3414 | ACU16: 3495 | ACV16: 3580 | ACW16: 3549 | ACX16: 3624 | ACY16: 3582 | ACZ16: 3792 | ADB16: 4016 | ADC16: 3845 | ADD16: 3787 | ADE16: 3794 | ADF16: 4070 | ADG16: 4558 | ADH16: 4781 | ADI16: 4930 | ADJ16: 5052 | ADK16: 5355 | ADL16: 5885 | ADM16: 6217 | ADO16: 6796 | ADP16: 7455 | ADQ16: 8178 | ADR16: 8501 | ADS16: 8984 | ADT16: 9315 | ADU16: 9346 | ADV16: 9329 | ADW16: 9578 | ADX16: 9911 | ADY16: 10010 | ADZ16: 9923 | AEB16: 9699 | AEC16: 9742 | AED16: 9639 | AEE16: 9696 | AEF16: 9593 | AEG16: 9421 | AEH16: 9113 | AEI16: 9190 | AEJ16: 9360 | AEK16: 9269 | AEL16: 9324 | AEM16: 9311 | AEO16: 8892 | AEP16: 8775 | AEQ16: 8676 | AER16: 8617 | AES16: 8696 | AET16: 8658 | AEU16: 8630 | AEV16: 8671 | AEW16: 8462 | AEX16: 8778 | AEY16: 8442 | AEZ16: 8087 | AFB16: 7793 | AFC16: 7753 | AFD16: 7737 | AFE16: 7744 | AFF16: 7644 | AFG16: 7742 | AFH16: 7721 | AFI16: 7519 | AFJ16: 7306 | AFK16: 7125 | AFL16: 7199 | AFM16: 7131 | AFO16: 7393 | AFP16: 7257 | AFQ16: 7133 | AFR16: 7012 | AFS16: 6990 | AFT16: 6947 | AFU16: 6814 | AFV16: 6611 | AFW16: 6753
